2024-10-06 21:29:12 - ERROR - Необработанная ошибка: [WinError 2] Не удается найти указанный файл: 'D:\\PythonProjects\\FaceRecognizerServer\\files/pictures/logo2.jpg'
Traceback (most recent call last):
  File "D:\anaconda3\Lib\site-packages\flask\app.py", line 1820, in full_dispatch_request
    rv = self.dispatch_request()
         ^^^^^^^^^^^^^^^^^^^^^^^
  File "D:\anaconda3\Lib\site-packages\flask\app.py", line 1796, in dispatch_request
    return self.ensure_sync(self.view_functions[rule.endpoint])(**view_args)
           ^^^^^^^^^^^^^^^^^^^^^^^^^^^^^^^^^^^^^^^^^^^^^^^^^^^^^^^^^^^^^^^^^
  File "D:\PythonProjects\FaceRecognizerServer\main.py", line 85, in loadPict
    return send_file(filename, mimetype=f'image/{parts[1]}')
           ^^^^^^^^^^^^^^^^^^^^^^^^^^^^^^^^^^^^^^^^^^^^^^^^^
  File "D:\anaconda3\Lib\site-packages\flask\helpers.py", line 537, in send_file
    return werkzeug.utils.send_file(  # type: ignore[return-value]
           ^^^^^^^^^^^^^^^^^^^^^^^^^^^^^^^^^^^^^^^^^^^^^^^^^^^^^^^
  File "D:\anaconda3\Lib\site-packages\werkzeug\utils.py", line 440, in send_file
    stat = os.stat(path)
           ^^^^^^^^^^^^^
FileNotFoundError: [WinError 2] Не удается найти указанный файл: 'D:\\PythonProjects\\FaceRecognizerServer\\files/pictures/logo2.jpg'


2024-10-06 21:29:25 - ERROR - Необработанная ошибка: [WinError 2] Не удается найти указанный файл: 'D:\\PythonProjects\\FaceRecognizerServer\\files/pictures/logo2.jpg'
Traceback (most recent call last):
  File "D:\anaconda3\Lib\site-packages\flask\app.py", line 1820, in full_dispatch_request
    rv = self.dispatch_request()
         ^^^^^^^^^^^^^^^^^^^^^^^
  File "D:\anaconda3\Lib\site-packages\flask\app.py", line 1796, in dispatch_request
    return self.ensure_sync(self.view_functions[rule.endpoint])(**view_args)
           ^^^^^^^^^^^^^^^^^^^^^^^^^^^^^^^^^^^^^^^^^^^^^^^^^^^^^^^^^^^^^^^^^
  File "D:\PythonProjects\FaceRecognizerServer\main.py", line 85, in loadPict
    return send_file(filename, mimetype=f'image/{parts[1]}')
           ^^^^^^^^^^^^^^^^^^^^^^^^^^^^^^^^^^^^^^^^^^^^^^^^^
  File "D:\anaconda3\Lib\site-packages\flask\helpers.py", line 537, in send_file
    return werkzeug.utils.send_file(  # type: ignore[return-value]
           ^^^^^^^^^^^^^^^^^^^^^^^^^^^^^^^^^^^^^^^^^^^^^^^^^^^^^^^
  File "D:\anaconda3\Lib\site-packages\werkzeug\utils.py", line 440, in send_file
    stat = os.stat(path)
           ^^^^^^^^^^^^^
FileNotFoundError: [WinError 2] Не удается найти указанный файл: 'D:\\PythonProjects\\FaceRecognizerServer\\files/pictures/logo2.jpg'


2024-10-06 21:32:04 - ERROR - Необработанная ошибка: [WinError 2] Не удается найти указанный файл: 'D:\\PythonProjects\\FaceRecognizerServer\\files/pictures/logo2.jpg'
Traceback (most recent call last):
  File "D:\anaconda3\Lib\site-packages\flask\app.py", line 1820, in full_dispatch_request
    rv = self.dispatch_request()
         ^^^^^^^^^^^^^^^^^^^^^^^
  File "D:\anaconda3\Lib\site-packages\flask\app.py", line 1796, in dispatch_request
    return self.ensure_sync(self.view_functions[rule.endpoint])(**view_args)
           ^^^^^^^^^^^^^^^^^^^^^^^^^^^^^^^^^^^^^^^^^^^^^^^^^^^^^^^^^^^^^^^^^
  File "D:\PythonProjects\FaceRecognizerServer\main.py", line 85, in loadPict
    return send_file(filename, mimetype=f'image/{parts[1]}')
           ^^^^^^^^^^^^^^^^^^^^^^^^^^^^^^^^^^^^^^^^^^^^^^^^^
  File "D:\anaconda3\Lib\site-packages\flask\helpers.py", line 537, in send_file
    return werkzeug.utils.send_file(  # type: ignore[return-value]
           ^^^^^^^^^^^^^^^^^^^^^^^^^^^^^^^^^^^^^^^^^^^^^^^^^^^^^^^
  File "D:\anaconda3\Lib\site-packages\werkzeug\utils.py", line 440, in send_file
    stat = os.stat(path)
           ^^^^^^^^^^^^^
FileNotFoundError: [WinError 2] Не удается найти указанный файл: 'D:\\PythonProjects\\FaceRecognizerServer\\files/pictures/logo2.jpg'


2024-10-06 21:32:04 - ERROR - Необработанная ошибка: 500 Internal Server Error: The server encountered an internal error and was unable to complete your request. Either the server is overloaded or there is an error in the application.
Traceback (most recent call last):
  File "D:\anaconda3\Lib\site-packages\flask\app.py", line 1820, in full_dispatch_request
    rv = self.dispatch_request()
         ^^^^^^^^^^^^^^^^^^^^^^^
  File "D:\anaconda3\Lib\site-packages\flask\app.py", line 1796, in dispatch_request
    return self.ensure_sync(self.view_functions[rule.endpoint])(**view_args)
           ^^^^^^^^^^^^^^^^^^^^^^^^^^^^^^^^^^^^^^^^^^^^^^^^^^^^^^^^^^^^^^^^^
  File "D:\PythonProjects\FaceRecognizerServer\main.py", line 85, in loadPict
    return send_file(filename, mimetype=f'image/{parts[1]}')
           ^^^^^^^^^^^^^^^^^^^^^^^^^^^^^^^^^^^^^^^^^^^^^^^^^
  File "D:\anaconda3\Lib\site-packages\flask\helpers.py", line 537, in send_file
    return werkzeug.utils.send_file(  # type: ignore[return-value]
           ^^^^^^^^^^^^^^^^^^^^^^^^^^^^^^^^^^^^^^^^^^^^^^^^^^^^^^^
  File "D:\anaconda3\Lib\site-packages\werkzeug\utils.py", line 440, in send_file
    stat = os.stat(path)
           ^^^^^^^^^^^^^
FileNotFoundError: [WinError 2] Не удается найти указанный файл: 'D:\\PythonProjects\\FaceRecognizerServer\\files/pictures/logo2.jpg'

During handling of the above exception, another exception occurred:

Traceback (most recent call last):
  File "D:\anaconda3\Lib\site-packages\flask\app.py", line 2525, in wsgi_app
    response = self.full_dispatch_request()
               ^^^^^^^^^^^^^^^^^^^^^^^^^^^^
  File "D:\anaconda3\Lib\site-packages\flask\app.py", line 1822, in full_dispatch_request
    rv = self.handle_user_exception(e)
         ^^^^^^^^^^^^^^^^^^^^^^^^^^^^^
  File "D:\anaconda3\Lib\site-packages\flask_restful\__init__.py", line 298, in error_router
    return original_handler(e)
           ^^^^^^^^^^^^^^^^^^^
  File "D:\anaconda3\Lib\site-packages\flask_cors\extension.py", line 176, in wrapped_function
    return cors_after_request(app.make_response(f(*args, **kwargs)))
                                                ^^^^^^^^^^^^^^^^^^
  File "D:\anaconda3\Lib\site-packages\flask\app.py", line 1673, in handle_user_exception
    return self.ensure_sync(handler)(e)
           ^^^^^^^^^^^^^^^^^^^^^^^^^^^^
  File "D:\PythonProjects\FaceRecognizerServer\main.py", line 50, in handle_exception
    return page_not_found()
           ^^^^^^^^^^^^^^^^
TypeError: page_not_found() missing 1 required positional argument: 'e'


2024-10-06 21:32:19 - ERROR - Необработанная ошибка: [WinError 2] Не удается найти указанный файл: 'D:\\PythonProjects\\FaceRecognizerServer\\files/pictures/logo2.jpg'
Traceback (most recent call last):
  File "D:\anaconda3\Lib\site-packages\flask\app.py", line 1820, in full_dispatch_request
    rv = self.dispatch_request()
         ^^^^^^^^^^^^^^^^^^^^^^^
  File "D:\anaconda3\Lib\site-packages\flask\app.py", line 1796, in dispatch_request
    return self.ensure_sync(self.view_functions[rule.endpoint])(**view_args)
           ^^^^^^^^^^^^^^^^^^^^^^^^^^^^^^^^^^^^^^^^^^^^^^^^^^^^^^^^^^^^^^^^^
  File "D:\PythonProjects\FaceRecognizerServer\main.py", line 85, in loadPict
    return send_file(filename, mimetype=f'image/{parts[1]}')
           ^^^^^^^^^^^^^^^^^^^^^^^^^^^^^^^^^^^^^^^^^^^^^^^^^
  File "D:\anaconda3\Lib\site-packages\flask\helpers.py", line 537, in send_file
    return werkzeug.utils.send_file(  # type: ignore[return-value]
           ^^^^^^^^^^^^^^^^^^^^^^^^^^^^^^^^^^^^^^^^^^^^^^^^^^^^^^^
  File "D:\anaconda3\Lib\site-packages\werkzeug\utils.py", line 440, in send_file
    stat = os.stat(path)
           ^^^^^^^^^^^^^
FileNotFoundError: [WinError 2] Не удается найти указанный файл: 'D:\\PythonProjects\\FaceRecognizerServer\\files/pictures/logo2.jpg'


2024-10-06 21:33:34 - ERROR - Произошла ошибка: [WinError 2] Не удается найти указанный файл: 'D:\\PythonProjects\\FaceRecognizerServer\\files/pictures/logo3.jpg'


