2025-01-26 17:21:18 - ERROR - Необработанная ошибка: (pg8000.exceptions.InterfaceError) Can't create a connection to host localhost and port 5432 (timeout is None and source_address is None).
(Background on this error at: https://sqlalche.me/e/20/rvf5)
Traceback (most recent call last):
  File "/Users/chronos_386/PycharmProjects/FaceRecognizerServer/.venv/lib/python3.8/site-packages/pg8000/core.py", line 206, in _make_socket
    sock = socket.create_connection((host, port), timeout, source_address)
  File "/Library/Frameworks/Python.framework/Versions/3.8/lib/python3.8/socket.py", line 808, in create_connection
    raise err
  File "/Library/Frameworks/Python.framework/Versions/3.8/lib/python3.8/socket.py", line 796, in create_connection
    sock.connect(sa)
ConnectionRefusedError: [Errno 61] Connection refused

The above exception was the direct cause of the following exception:

Traceback (most recent call last):
  File "/Users/chronos_386/PycharmProjects/FaceRecognizerServer/.venv/lib/python3.8/site-packages/sqlalchemy/engine/base.py", line 146, in __init__
    self._dbapi_connection = engine.raw_connection()
  File "/Users/chronos_386/PycharmProjects/FaceRecognizerServer/.venv/lib/python3.8/site-packages/sqlalchemy/engine/base.py", line 3302, in raw_connection
    return self.pool.connect()
  File "/Users/chronos_386/PycharmProjects/FaceRecognizerServer/.venv/lib/python3.8/site-packages/sqlalchemy/pool/base.py", line 449, in connect
    return _ConnectionFairy._checkout(self)
  File "/Users/chronos_386/PycharmProjects/FaceRecognizerServer/.venv/lib/python3.8/site-packages/sqlalchemy/pool/base.py", line 1263, in _checkout
    fairy = _ConnectionRecord.checkout(pool)
  File "/Users/chronos_386/PycharmProjects/FaceRecognizerServer/.venv/lib/python3.8/site-packages/sqlalchemy/pool/base.py", line 712, in checkout
    rec = pool._do_get()
  File "/Users/chronos_386/PycharmProjects/FaceRecognizerServer/.venv/lib/python3.8/site-packages/sqlalchemy/pool/impl.py", line 180, in _do_get
    self._dec_overflow()
  File "/Users/chronos_386/PycharmProjects/FaceRecognizerServer/.venv/lib/python3.8/site-packages/sqlalchemy/util/langhelpers.py", line 146, in __exit__
    raise exc_value.with_traceback(exc_tb)
  File "/Users/chronos_386/PycharmProjects/FaceRecognizerServer/.venv/lib/python3.8/site-packages/sqlalchemy/pool/impl.py", line 177, in _do_get
    return self._create_connection()
  File "/Users/chronos_386/PycharmProjects/FaceRecognizerServer/.venv/lib/python3.8/site-packages/sqlalchemy/pool/base.py", line 390, in _create_connection
    return _ConnectionRecord(self)
  File "/Users/chronos_386/PycharmProjects/FaceRecognizerServer/.venv/lib/python3.8/site-packages/sqlalchemy/pool/base.py", line 674, in __init__
    self.__connect()
  File "/Users/chronos_386/PycharmProjects/FaceRecognizerServer/.venv/lib/python3.8/site-packages/sqlalchemy/pool/base.py", line 901, in __connect
    pool.logger.debug("Error on connect(): %s", e)
  File "/Users/chronos_386/PycharmProjects/FaceRecognizerServer/.venv/lib/python3.8/site-packages/sqlalchemy/util/langhelpers.py", line 146, in __exit__
    raise exc_value.with_traceback(exc_tb)
  File "/Users/chronos_386/PycharmProjects/FaceRecognizerServer/.venv/lib/python3.8/site-packages/sqlalchemy/pool/base.py", line 896, in __connect
    self.dbapi_connection = connection = pool._invoke_creator(self)
  File "/Users/chronos_386/PycharmProjects/FaceRecognizerServer/.venv/lib/python3.8/site-packages/sqlalchemy/engine/create.py", line 643, in connect
    return dialect.connect(*cargs, **cparams)
  File "/Users/chronos_386/PycharmProjects/FaceRecognizerServer/.venv/lib/python3.8/site-packages/sqlalchemy/engine/default.py", line 621, in connect
    return self.loaded_dbapi.connect(*cargs, **cparams)
  File "/Users/chronos_386/PycharmProjects/FaceRecognizerServer/.venv/lib/python3.8/site-packages/pg8000/__init__.py", line 111, in connect
    return Connection(
  File "/Users/chronos_386/PycharmProjects/FaceRecognizerServer/.venv/lib/python3.8/site-packages/pg8000/legacy.py", line 443, in __init__
    super().__init__(*args, **kwargs)
  File "/Users/chronos_386/PycharmProjects/FaceRecognizerServer/.venv/lib/python3.8/site-packages/pg8000/core.py", line 320, in __init__
    self.channel_binding, self._usock = _make_socket(
  File "/Users/chronos_386/PycharmProjects/FaceRecognizerServer/.venv/lib/python3.8/site-packages/pg8000/core.py", line 208, in _make_socket
    raise InterfaceError(
pg8000.exceptions.InterfaceError: Can't create a connection to host localhost and port 5432 (timeout is None and source_address is None).

The above exception was the direct cause of the following exception:

Traceback (most recent call last):
  File "/Users/chronos_386/PycharmProjects/FaceRecognizerServer/.venv/lib/python3.8/site-packages/flask/app.py", line 880, in full_dispatch_request
    rv = self.dispatch_request()
  File "/Users/chronos_386/PycharmProjects/FaceRecognizerServer/.venv/lib/python3.8/site-packages/flask/app.py", line 865, in dispatch_request
    return self.ensure_sync(self.view_functions[rule.endpoint])(**view_args)  # type: ignore[no-any-return]
  File "/Users/chronos_386/PycharmProjects/FaceRecognizerServer/.venv/lib/python3.8/site-packages/flask_restful/__init__.py", line 489, in wrapper
    resp = resource(*args, **kwargs)
  File "/Users/chronos_386/PycharmProjects/FaceRecognizerServer/.venv/lib/python3.8/site-packages/flask/views.py", line 110, in view
    return current_app.ensure_sync(self.dispatch_request)(**kwargs)  # type: ignore[no-any-return]
  File "/Users/chronos_386/PycharmProjects/FaceRecognizerServer/.venv/lib/python3.8/site-packages/flask_restful/__init__.py", line 604, in dispatch_request
    resp = meth(*args, **kwargs)
  File "/Users/chronos_386/PycharmProjects/FaceRecognizerServer/source_code/resources/schedule_device_res.py", line 12, in post
    student_id, json_model, code = self.api_connector.getStudentScheduleByPhoto(file)
  File "/Users/chronos_386/PycharmProjects/FaceRecognizerServer/source_code/api_connection/api_connector.py", line 674, in getStudentScheduleByPhoto
    student, code = self.__handleGetStudentByPhoto(photo)
  File "/Users/chronos_386/PycharmProjects/FaceRecognizerServer/source_code/api_connection/api_connector.py", line 89, in __handleGetStudentByPhoto
    emb: List[FaceEmbeddingsDB] = self.db_class.getAllEmbeddings()
  File "/Users/chronos_386/PycharmProjects/FaceRecognizerServer/source_code/db_connection/db_class.py", line 176, in getAllEmbeddings
    embeddings: List[Type[FaceEmbeddingsDB]] = self.session.query(FaceEmbeddingsDB).all()
  File "/Users/chronos_386/PycharmProjects/FaceRecognizerServer/.venv/lib/python3.8/site-packages/sqlalchemy/orm/query.py", line 2673, in all
    return self._iter().all()  # type: ignore
  File "/Users/chronos_386/PycharmProjects/FaceRecognizerServer/.venv/lib/python3.8/site-packages/sqlalchemy/orm/query.py", line 2827, in _iter
    result: Union[ScalarResult[_T], Result[_T]] = self.session.execute(
  File "/Users/chronos_386/PycharmProjects/FaceRecognizerServer/.venv/lib/python3.8/site-packages/sqlalchemy/orm/session.py", line 2362, in execute
    return self._execute_internal(
  File "/Users/chronos_386/PycharmProjects/FaceRecognizerServer/.venv/lib/python3.8/site-packages/sqlalchemy/orm/session.py", line 2237, in _execute_internal
    conn = self._connection_for_bind(bind)
  File "/Users/chronos_386/PycharmProjects/FaceRecognizerServer/.venv/lib/python3.8/site-packages/sqlalchemy/orm/session.py", line 2106, in _connection_for_bind
    return trans._connection_for_bind(engine, execution_options)
  File "<string>", line 2, in _connection_for_bind
  File "/Users/chronos_386/PycharmProjects/FaceRecognizerServer/.venv/lib/python3.8/site-packages/sqlalchemy/orm/state_changes.py", line 139, in _go
    ret_value = fn(self, *arg, **kw)
  File "/Users/chronos_386/PycharmProjects/FaceRecognizerServer/.venv/lib/python3.8/site-packages/sqlalchemy/orm/session.py", line 1189, in _connection_for_bind
    conn = bind.connect()
  File "/Users/chronos_386/PycharmProjects/FaceRecognizerServer/.venv/lib/python3.8/site-packages/sqlalchemy/engine/base.py", line 3278, in connect
    return self._connection_cls(self)
  File "/Users/chronos_386/PycharmProjects/FaceRecognizerServer/.venv/lib/python3.8/site-packages/sqlalchemy/engine/base.py", line 148, in __init__
    Connection._handle_dbapi_exception_noconnection(
  File "/Users/chronos_386/PycharmProjects/FaceRecognizerServer/.venv/lib/python3.8/site-packages/sqlalchemy/engine/base.py", line 2442, in _handle_dbapi_exception_noconnection
    raise sqlalchemy_exception.with_traceback(exc_info[2]) from e
  File "/Users/chronos_386/PycharmProjects/FaceRecognizerServer/.venv/lib/python3.8/site-packages/sqlalchemy/engine/base.py", line 146, in __init__
    self._dbapi_connection = engine.raw_connection()
  File "/Users/chronos_386/PycharmProjects/FaceRecognizerServer/.venv/lib/python3.8/site-packages/sqlalchemy/engine/base.py", line 3302, in raw_connection
    return self.pool.connect()
  File "/Users/chronos_386/PycharmProjects/FaceRecognizerServer/.venv/lib/python3.8/site-packages/sqlalchemy/pool/base.py", line 449, in connect
    return _ConnectionFairy._checkout(self)
  File "/Users/chronos_386/PycharmProjects/FaceRecognizerServer/.venv/lib/python3.8/site-packages/sqlalchemy/pool/base.py", line 1263, in _checkout
    fairy = _ConnectionRecord.checkout(pool)
  File "/Users/chronos_386/PycharmProjects/FaceRecognizerServer/.venv/lib/python3.8/site-packages/sqlalchemy/pool/base.py", line 712, in checkout
    rec = pool._do_get()
  File "/Users/chronos_386/PycharmProjects/FaceRecognizerServer/.venv/lib/python3.8/site-packages/sqlalchemy/pool/impl.py", line 180, in _do_get
    self._dec_overflow()
  File "/Users/chronos_386/PycharmProjects/FaceRecognizerServer/.venv/lib/python3.8/site-packages/sqlalchemy/util/langhelpers.py", line 146, in __exit__
    raise exc_value.with_traceback(exc_tb)
  File "/Users/chronos_386/PycharmProjects/FaceRecognizerServer/.venv/lib/python3.8/site-packages/sqlalchemy/pool/impl.py", line 177, in _do_get
    return self._create_connection()
  File "/Users/chronos_386/PycharmProjects/FaceRecognizerServer/.venv/lib/python3.8/site-packages/sqlalchemy/pool/base.py", line 390, in _create_connection
    return _ConnectionRecord(self)
  File "/Users/chronos_386/PycharmProjects/FaceRecognizerServer/.venv/lib/python3.8/site-packages/sqlalchemy/pool/base.py", line 674, in __init__
    self.__connect()
  File "/Users/chronos_386/PycharmProjects/FaceRecognizerServer/.venv/lib/python3.8/site-packages/sqlalchemy/pool/base.py", line 901, in __connect
    pool.logger.debug("Error on connect(): %s", e)
  File "/Users/chronos_386/PycharmProjects/FaceRecognizerServer/.venv/lib/python3.8/site-packages/sqlalchemy/util/langhelpers.py", line 146, in __exit__
    raise exc_value.with_traceback(exc_tb)
  File "/Users/chronos_386/PycharmProjects/FaceRecognizerServer/.venv/lib/python3.8/site-packages/sqlalchemy/pool/base.py", line 896, in __connect
    self.dbapi_connection = connection = pool._invoke_creator(self)
  File "/Users/chronos_386/PycharmProjects/FaceRecognizerServer/.venv/lib/python3.8/site-packages/sqlalchemy/engine/create.py", line 643, in connect
    return dialect.connect(*cargs, **cparams)
  File "/Users/chronos_386/PycharmProjects/FaceRecognizerServer/.venv/lib/python3.8/site-packages/sqlalchemy/engine/default.py", line 621, in connect
    return self.loaded_dbapi.connect(*cargs, **cparams)
  File "/Users/chronos_386/PycharmProjects/FaceRecognizerServer/.venv/lib/python3.8/site-packages/pg8000/__init__.py", line 111, in connect
    return Connection(
  File "/Users/chronos_386/PycharmProjects/FaceRecognizerServer/.venv/lib/python3.8/site-packages/pg8000/legacy.py", line 443, in __init__
    super().__init__(*args, **kwargs)
  File "/Users/chronos_386/PycharmProjects/FaceRecognizerServer/.venv/lib/python3.8/site-packages/pg8000/core.py", line 320, in __init__
    self.channel_binding, self._usock = _make_socket(
  File "/Users/chronos_386/PycharmProjects/FaceRecognizerServer/.venv/lib/python3.8/site-packages/pg8000/core.py", line 208, in _make_socket
    raise InterfaceError(
sqlalchemy.exc.InterfaceError: (pg8000.exceptions.InterfaceError) Can't create a connection to host localhost and port 5432 (timeout is None and source_address is None).
(Background on this error at: https://sqlalche.me/e/20/rvf5)


2025-01-26 17:21:18 - ERROR - Необработанная ошибка: (pg8000.exceptions.InterfaceError) Can't create a connection to host localhost and port 5432 (timeout is None and source_address is None).
(Background on this error at: https://sqlalche.me/e/20/rvf5)
Traceback (most recent call last):
  File "/Users/chronos_386/PycharmProjects/FaceRecognizerServer/.venv/lib/python3.8/site-packages/pg8000/core.py", line 206, in _make_socket
    sock = socket.create_connection((host, port), timeout, source_address)
  File "/Library/Frameworks/Python.framework/Versions/3.8/lib/python3.8/socket.py", line 808, in create_connection
    raise err
  File "/Library/Frameworks/Python.framework/Versions/3.8/lib/python3.8/socket.py", line 796, in create_connection
    sock.connect(sa)
ConnectionRefusedError: [Errno 61] Connection refused

The above exception was the direct cause of the following exception:

Traceback (most recent call last):
  File "/Users/chronos_386/PycharmProjects/FaceRecognizerServer/.venv/lib/python3.8/site-packages/sqlalchemy/engine/base.py", line 146, in __init__
    self._dbapi_connection = engine.raw_connection()
  File "/Users/chronos_386/PycharmProjects/FaceRecognizerServer/.venv/lib/python3.8/site-packages/sqlalchemy/engine/base.py", line 3302, in raw_connection
    return self.pool.connect()
  File "/Users/chronos_386/PycharmProjects/FaceRecognizerServer/.venv/lib/python3.8/site-packages/sqlalchemy/pool/base.py", line 449, in connect
    return _ConnectionFairy._checkout(self)
  File "/Users/chronos_386/PycharmProjects/FaceRecognizerServer/.venv/lib/python3.8/site-packages/sqlalchemy/pool/base.py", line 1263, in _checkout
    fairy = _ConnectionRecord.checkout(pool)
  File "/Users/chronos_386/PycharmProjects/FaceRecognizerServer/.venv/lib/python3.8/site-packages/sqlalchemy/pool/base.py", line 712, in checkout
    rec = pool._do_get()
  File "/Users/chronos_386/PycharmProjects/FaceRecognizerServer/.venv/lib/python3.8/site-packages/sqlalchemy/pool/impl.py", line 180, in _do_get
    self._dec_overflow()
  File "/Users/chronos_386/PycharmProjects/FaceRecognizerServer/.venv/lib/python3.8/site-packages/sqlalchemy/util/langhelpers.py", line 146, in __exit__
    raise exc_value.with_traceback(exc_tb)
  File "/Users/chronos_386/PycharmProjects/FaceRecognizerServer/.venv/lib/python3.8/site-packages/sqlalchemy/pool/impl.py", line 177, in _do_get
    return self._create_connection()
  File "/Users/chronos_386/PycharmProjects/FaceRecognizerServer/.venv/lib/python3.8/site-packages/sqlalchemy/pool/base.py", line 390, in _create_connection
    return _ConnectionRecord(self)
  File "/Users/chronos_386/PycharmProjects/FaceRecognizerServer/.venv/lib/python3.8/site-packages/sqlalchemy/pool/base.py", line 674, in __init__
    self.__connect()
  File "/Users/chronos_386/PycharmProjects/FaceRecognizerServer/.venv/lib/python3.8/site-packages/sqlalchemy/pool/base.py", line 901, in __connect
    pool.logger.debug("Error on connect(): %s", e)
  File "/Users/chronos_386/PycharmProjects/FaceRecognizerServer/.venv/lib/python3.8/site-packages/sqlalchemy/util/langhelpers.py", line 146, in __exit__
    raise exc_value.with_traceback(exc_tb)
  File "/Users/chronos_386/PycharmProjects/FaceRecognizerServer/.venv/lib/python3.8/site-packages/sqlalchemy/pool/base.py", line 896, in __connect
    self.dbapi_connection = connection = pool._invoke_creator(self)
  File "/Users/chronos_386/PycharmProjects/FaceRecognizerServer/.venv/lib/python3.8/site-packages/sqlalchemy/engine/create.py", line 643, in connect
    return dialect.connect(*cargs, **cparams)
  File "/Users/chronos_386/PycharmProjects/FaceRecognizerServer/.venv/lib/python3.8/site-packages/sqlalchemy/engine/default.py", line 621, in connect
    return self.loaded_dbapi.connect(*cargs, **cparams)
  File "/Users/chronos_386/PycharmProjects/FaceRecognizerServer/.venv/lib/python3.8/site-packages/pg8000/__init__.py", line 111, in connect
    return Connection(
  File "/Users/chronos_386/PycharmProjects/FaceRecognizerServer/.venv/lib/python3.8/site-packages/pg8000/legacy.py", line 443, in __init__
    super().__init__(*args, **kwargs)
  File "/Users/chronos_386/PycharmProjects/FaceRecognizerServer/.venv/lib/python3.8/site-packages/pg8000/core.py", line 320, in __init__
    self.channel_binding, self._usock = _make_socket(
  File "/Users/chronos_386/PycharmProjects/FaceRecognizerServer/.venv/lib/python3.8/site-packages/pg8000/core.py", line 208, in _make_socket
    raise InterfaceError(
pg8000.exceptions.InterfaceError: Can't create a connection to host localhost and port 5432 (timeout is None and source_address is None).

The above exception was the direct cause of the following exception:

Traceback (most recent call last):
  File "/Users/chronos_386/PycharmProjects/FaceRecognizerServer/.venv/lib/python3.8/site-packages/flask/app.py", line 880, in full_dispatch_request
    rv = self.dispatch_request()
  File "/Users/chronos_386/PycharmProjects/FaceRecognizerServer/.venv/lib/python3.8/site-packages/flask/app.py", line 865, in dispatch_request
    return self.ensure_sync(self.view_functions[rule.endpoint])(**view_args)  # type: ignore[no-any-return]
  File "/Users/chronos_386/PycharmProjects/FaceRecognizerServer/.venv/lib/python3.8/site-packages/flask_restful/__init__.py", line 489, in wrapper
    resp = resource(*args, **kwargs)
  File "/Users/chronos_386/PycharmProjects/FaceRecognizerServer/.venv/lib/python3.8/site-packages/flask/views.py", line 110, in view
    return current_app.ensure_sync(self.dispatch_request)(**kwargs)  # type: ignore[no-any-return]
  File "/Users/chronos_386/PycharmProjects/FaceRecognizerServer/.venv/lib/python3.8/site-packages/flask_restful/__init__.py", line 604, in dispatch_request
    resp = meth(*args, **kwargs)
  File "/Users/chronos_386/PycharmProjects/FaceRecognizerServer/source_code/resources/schedule_device_res.py", line 12, in post
    student_id, json_model, code = self.api_connector.getStudentScheduleByPhoto(file)
  File "/Users/chronos_386/PycharmProjects/FaceRecognizerServer/source_code/api_connection/api_connector.py", line 674, in getStudentScheduleByPhoto
    student, code = self.__handleGetStudentByPhoto(photo)
  File "/Users/chronos_386/PycharmProjects/FaceRecognizerServer/source_code/api_connection/api_connector.py", line 89, in __handleGetStudentByPhoto
    emb: List[FaceEmbeddingsDB] = self.db_class.getAllEmbeddings()
  File "/Users/chronos_386/PycharmProjects/FaceRecognizerServer/source_code/db_connection/db_class.py", line 176, in getAllEmbeddings
    embeddings: List[Type[FaceEmbeddingsDB]] = self.session.query(FaceEmbeddingsDB).all()
  File "/Users/chronos_386/PycharmProjects/FaceRecognizerServer/.venv/lib/python3.8/site-packages/sqlalchemy/orm/query.py", line 2673, in all
    return self._iter().all()  # type: ignore
  File "/Users/chronos_386/PycharmProjects/FaceRecognizerServer/.venv/lib/python3.8/site-packages/sqlalchemy/orm/query.py", line 2827, in _iter
    result: Union[ScalarResult[_T], Result[_T]] = self.session.execute(
  File "/Users/chronos_386/PycharmProjects/FaceRecognizerServer/.venv/lib/python3.8/site-packages/sqlalchemy/orm/session.py", line 2362, in execute
    return self._execute_internal(
  File "/Users/chronos_386/PycharmProjects/FaceRecognizerServer/.venv/lib/python3.8/site-packages/sqlalchemy/orm/session.py", line 2237, in _execute_internal
    conn = self._connection_for_bind(bind)
  File "/Users/chronos_386/PycharmProjects/FaceRecognizerServer/.venv/lib/python3.8/site-packages/sqlalchemy/orm/session.py", line 2106, in _connection_for_bind
    return trans._connection_for_bind(engine, execution_options)
  File "<string>", line 2, in _connection_for_bind
  File "/Users/chronos_386/PycharmProjects/FaceRecognizerServer/.venv/lib/python3.8/site-packages/sqlalchemy/orm/state_changes.py", line 139, in _go
    ret_value = fn(self, *arg, **kw)
  File "/Users/chronos_386/PycharmProjects/FaceRecognizerServer/.venv/lib/python3.8/site-packages/sqlalchemy/orm/session.py", line 1189, in _connection_for_bind
    conn = bind.connect()
  File "/Users/chronos_386/PycharmProjects/FaceRecognizerServer/.venv/lib/python3.8/site-packages/sqlalchemy/engine/base.py", line 3278, in connect
    return self._connection_cls(self)
  File "/Users/chronos_386/PycharmProjects/FaceRecognizerServer/.venv/lib/python3.8/site-packages/sqlalchemy/engine/base.py", line 148, in __init__
    Connection._handle_dbapi_exception_noconnection(
  File "/Users/chronos_386/PycharmProjects/FaceRecognizerServer/.venv/lib/python3.8/site-packages/sqlalchemy/engine/base.py", line 2442, in _handle_dbapi_exception_noconnection
    raise sqlalchemy_exception.with_traceback(exc_info[2]) from e
  File "/Users/chronos_386/PycharmProjects/FaceRecognizerServer/.venv/lib/python3.8/site-packages/sqlalchemy/engine/base.py", line 146, in __init__
    self._dbapi_connection = engine.raw_connection()
  File "/Users/chronos_386/PycharmProjects/FaceRecognizerServer/.venv/lib/python3.8/site-packages/sqlalchemy/engine/base.py", line 3302, in raw_connection
    return self.pool.connect()
  File "/Users/chronos_386/PycharmProjects/FaceRecognizerServer/.venv/lib/python3.8/site-packages/sqlalchemy/pool/base.py", line 449, in connect
    return _ConnectionFairy._checkout(self)
  File "/Users/chronos_386/PycharmProjects/FaceRecognizerServer/.venv/lib/python3.8/site-packages/sqlalchemy/pool/base.py", line 1263, in _checkout
    fairy = _ConnectionRecord.checkout(pool)
  File "/Users/chronos_386/PycharmProjects/FaceRecognizerServer/.venv/lib/python3.8/site-packages/sqlalchemy/pool/base.py", line 712, in checkout
    rec = pool._do_get()
  File "/Users/chronos_386/PycharmProjects/FaceRecognizerServer/.venv/lib/python3.8/site-packages/sqlalchemy/pool/impl.py", line 180, in _do_get
    self._dec_overflow()
  File "/Users/chronos_386/PycharmProjects/FaceRecognizerServer/.venv/lib/python3.8/site-packages/sqlalchemy/util/langhelpers.py", line 146, in __exit__
    raise exc_value.with_traceback(exc_tb)
  File "/Users/chronos_386/PycharmProjects/FaceRecognizerServer/.venv/lib/python3.8/site-packages/sqlalchemy/pool/impl.py", line 177, in _do_get
    return self._create_connection()
  File "/Users/chronos_386/PycharmProjects/FaceRecognizerServer/.venv/lib/python3.8/site-packages/sqlalchemy/pool/base.py", line 390, in _create_connection
    return _ConnectionRecord(self)
  File "/Users/chronos_386/PycharmProjects/FaceRecognizerServer/.venv/lib/python3.8/site-packages/sqlalchemy/pool/base.py", line 674, in __init__
    self.__connect()
  File "/Users/chronos_386/PycharmProjects/FaceRecognizerServer/.venv/lib/python3.8/site-packages/sqlalchemy/pool/base.py", line 901, in __connect
    pool.logger.debug("Error on connect(): %s", e)
  File "/Users/chronos_386/PycharmProjects/FaceRecognizerServer/.venv/lib/python3.8/site-packages/sqlalchemy/util/langhelpers.py", line 146, in __exit__
    raise exc_value.with_traceback(exc_tb)
  File "/Users/chronos_386/PycharmProjects/FaceRecognizerServer/.venv/lib/python3.8/site-packages/sqlalchemy/pool/base.py", line 896, in __connect
    self.dbapi_connection = connection = pool._invoke_creator(self)
  File "/Users/chronos_386/PycharmProjects/FaceRecognizerServer/.venv/lib/python3.8/site-packages/sqlalchemy/engine/create.py", line 643, in connect
    return dialect.connect(*cargs, **cparams)
  File "/Users/chronos_386/PycharmProjects/FaceRecognizerServer/.venv/lib/python3.8/site-packages/sqlalchemy/engine/default.py", line 621, in connect
    return self.loaded_dbapi.connect(*cargs, **cparams)
  File "/Users/chronos_386/PycharmProjects/FaceRecognizerServer/.venv/lib/python3.8/site-packages/pg8000/__init__.py", line 111, in connect
    return Connection(
  File "/Users/chronos_386/PycharmProjects/FaceRecognizerServer/.venv/lib/python3.8/site-packages/pg8000/legacy.py", line 443, in __init__
    super().__init__(*args, **kwargs)
  File "/Users/chronos_386/PycharmProjects/FaceRecognizerServer/.venv/lib/python3.8/site-packages/pg8000/core.py", line 320, in __init__
    self.channel_binding, self._usock = _make_socket(
  File "/Users/chronos_386/PycharmProjects/FaceRecognizerServer/.venv/lib/python3.8/site-packages/pg8000/core.py", line 208, in _make_socket
    raise InterfaceError(
sqlalchemy.exc.InterfaceError: (pg8000.exceptions.InterfaceError) Can't create a connection to host localhost and port 5432 (timeout is None and source_address is None).
(Background on this error at: https://sqlalche.me/e/20/rvf5)


2025-01-26 17:21:18 - ERROR - Необработанная ошибка: (pg8000.exceptions.InterfaceError) Can't create a connection to host localhost and port 5432 (timeout is None and source_address is None).
(Background on this error at: https://sqlalche.me/e/20/rvf5)
Traceback (most recent call last):
  File "/Users/chronos_386/PycharmProjects/FaceRecognizerServer/.venv/lib/python3.8/site-packages/pg8000/core.py", line 206, in _make_socket
    sock = socket.create_connection((host, port), timeout, source_address)
  File "/Library/Frameworks/Python.framework/Versions/3.8/lib/python3.8/socket.py", line 808, in create_connection
    raise err
  File "/Library/Frameworks/Python.framework/Versions/3.8/lib/python3.8/socket.py", line 796, in create_connection
    sock.connect(sa)
ConnectionRefusedError: [Errno 61] Connection refused

The above exception was the direct cause of the following exception:

Traceback (most recent call last):
  File "/Users/chronos_386/PycharmProjects/FaceRecognizerServer/.venv/lib/python3.8/site-packages/sqlalchemy/engine/base.py", line 146, in __init__
    self._dbapi_connection = engine.raw_connection()
  File "/Users/chronos_386/PycharmProjects/FaceRecognizerServer/.venv/lib/python3.8/site-packages/sqlalchemy/engine/base.py", line 3302, in raw_connection
    return self.pool.connect()
  File "/Users/chronos_386/PycharmProjects/FaceRecognizerServer/.venv/lib/python3.8/site-packages/sqlalchemy/pool/base.py", line 449, in connect
    return _ConnectionFairy._checkout(self)
  File "/Users/chronos_386/PycharmProjects/FaceRecognizerServer/.venv/lib/python3.8/site-packages/sqlalchemy/pool/base.py", line 1263, in _checkout
    fairy = _ConnectionRecord.checkout(pool)
  File "/Users/chronos_386/PycharmProjects/FaceRecognizerServer/.venv/lib/python3.8/site-packages/sqlalchemy/pool/base.py", line 712, in checkout
    rec = pool._do_get()
  File "/Users/chronos_386/PycharmProjects/FaceRecognizerServer/.venv/lib/python3.8/site-packages/sqlalchemy/pool/impl.py", line 180, in _do_get
    self._dec_overflow()
  File "/Users/chronos_386/PycharmProjects/FaceRecognizerServer/.venv/lib/python3.8/site-packages/sqlalchemy/util/langhelpers.py", line 146, in __exit__
    raise exc_value.with_traceback(exc_tb)
  File "/Users/chronos_386/PycharmProjects/FaceRecognizerServer/.venv/lib/python3.8/site-packages/sqlalchemy/pool/impl.py", line 177, in _do_get
    return self._create_connection()
  File "/Users/chronos_386/PycharmProjects/FaceRecognizerServer/.venv/lib/python3.8/site-packages/sqlalchemy/pool/base.py", line 390, in _create_connection
    return _ConnectionRecord(self)
  File "/Users/chronos_386/PycharmProjects/FaceRecognizerServer/.venv/lib/python3.8/site-packages/sqlalchemy/pool/base.py", line 674, in __init__
    self.__connect()
  File "/Users/chronos_386/PycharmProjects/FaceRecognizerServer/.venv/lib/python3.8/site-packages/sqlalchemy/pool/base.py", line 901, in __connect
    pool.logger.debug("Error on connect(): %s", e)
  File "/Users/chronos_386/PycharmProjects/FaceRecognizerServer/.venv/lib/python3.8/site-packages/sqlalchemy/util/langhelpers.py", line 146, in __exit__
    raise exc_value.with_traceback(exc_tb)
  File "/Users/chronos_386/PycharmProjects/FaceRecognizerServer/.venv/lib/python3.8/site-packages/sqlalchemy/pool/base.py", line 896, in __connect
    self.dbapi_connection = connection = pool._invoke_creator(self)
  File "/Users/chronos_386/PycharmProjects/FaceRecognizerServer/.venv/lib/python3.8/site-packages/sqlalchemy/engine/create.py", line 643, in connect
    return dialect.connect(*cargs, **cparams)
  File "/Users/chronos_386/PycharmProjects/FaceRecognizerServer/.venv/lib/python3.8/site-packages/sqlalchemy/engine/default.py", line 621, in connect
    return self.loaded_dbapi.connect(*cargs, **cparams)
  File "/Users/chronos_386/PycharmProjects/FaceRecognizerServer/.venv/lib/python3.8/site-packages/pg8000/__init__.py", line 111, in connect
    return Connection(
  File "/Users/chronos_386/PycharmProjects/FaceRecognizerServer/.venv/lib/python3.8/site-packages/pg8000/legacy.py", line 443, in __init__
    super().__init__(*args, **kwargs)
  File "/Users/chronos_386/PycharmProjects/FaceRecognizerServer/.venv/lib/python3.8/site-packages/pg8000/core.py", line 320, in __init__
    self.channel_binding, self._usock = _make_socket(
  File "/Users/chronos_386/PycharmProjects/FaceRecognizerServer/.venv/lib/python3.8/site-packages/pg8000/core.py", line 208, in _make_socket
    raise InterfaceError(
pg8000.exceptions.InterfaceError: Can't create a connection to host localhost and port 5432 (timeout is None and source_address is None).

The above exception was the direct cause of the following exception:

Traceback (most recent call last):
  File "/Users/chronos_386/PycharmProjects/FaceRecognizerServer/.venv/lib/python3.8/site-packages/flask/app.py", line 880, in full_dispatch_request
    rv = self.dispatch_request()
  File "/Users/chronos_386/PycharmProjects/FaceRecognizerServer/.venv/lib/python3.8/site-packages/flask/app.py", line 865, in dispatch_request
    return self.ensure_sync(self.view_functions[rule.endpoint])(**view_args)  # type: ignore[no-any-return]
  File "/Users/chronos_386/PycharmProjects/FaceRecognizerServer/.venv/lib/python3.8/site-packages/flask_restful/__init__.py", line 489, in wrapper
    resp = resource(*args, **kwargs)
  File "/Users/chronos_386/PycharmProjects/FaceRecognizerServer/.venv/lib/python3.8/site-packages/flask/views.py", line 110, in view
    return current_app.ensure_sync(self.dispatch_request)(**kwargs)  # type: ignore[no-any-return]
  File "/Users/chronos_386/PycharmProjects/FaceRecognizerServer/.venv/lib/python3.8/site-packages/flask_restful/__init__.py", line 604, in dispatch_request
    resp = meth(*args, **kwargs)
  File "/Users/chronos_386/PycharmProjects/FaceRecognizerServer/source_code/resources/schedule_device_res.py", line 12, in post
    student_id, json_model, code = self.api_connector.getStudentScheduleByPhoto(file)
  File "/Users/chronos_386/PycharmProjects/FaceRecognizerServer/source_code/api_connection/api_connector.py", line 674, in getStudentScheduleByPhoto
    student, code = self.__handleGetStudentByPhoto(photo)
  File "/Users/chronos_386/PycharmProjects/FaceRecognizerServer/source_code/api_connection/api_connector.py", line 89, in __handleGetStudentByPhoto
    emb: List[FaceEmbeddingsDB] = self.db_class.getAllEmbeddings()
  File "/Users/chronos_386/PycharmProjects/FaceRecognizerServer/source_code/db_connection/db_class.py", line 176, in getAllEmbeddings
    embeddings: List[Type[FaceEmbeddingsDB]] = self.session.query(FaceEmbeddingsDB).all()
  File "/Users/chronos_386/PycharmProjects/FaceRecognizerServer/.venv/lib/python3.8/site-packages/sqlalchemy/orm/query.py", line 2673, in all
    return self._iter().all()  # type: ignore
  File "/Users/chronos_386/PycharmProjects/FaceRecognizerServer/.venv/lib/python3.8/site-packages/sqlalchemy/orm/query.py", line 2827, in _iter
    result: Union[ScalarResult[_T], Result[_T]] = self.session.execute(
  File "/Users/chronos_386/PycharmProjects/FaceRecognizerServer/.venv/lib/python3.8/site-packages/sqlalchemy/orm/session.py", line 2362, in execute
    return self._execute_internal(
  File "/Users/chronos_386/PycharmProjects/FaceRecognizerServer/.venv/lib/python3.8/site-packages/sqlalchemy/orm/session.py", line 2237, in _execute_internal
    conn = self._connection_for_bind(bind)
  File "/Users/chronos_386/PycharmProjects/FaceRecognizerServer/.venv/lib/python3.8/site-packages/sqlalchemy/orm/session.py", line 2106, in _connection_for_bind
    return trans._connection_for_bind(engine, execution_options)
  File "<string>", line 2, in _connection_for_bind
  File "/Users/chronos_386/PycharmProjects/FaceRecognizerServer/.venv/lib/python3.8/site-packages/sqlalchemy/orm/state_changes.py", line 139, in _go
    ret_value = fn(self, *arg, **kw)
  File "/Users/chronos_386/PycharmProjects/FaceRecognizerServer/.venv/lib/python3.8/site-packages/sqlalchemy/orm/session.py", line 1189, in _connection_for_bind
    conn = bind.connect()
  File "/Users/chronos_386/PycharmProjects/FaceRecognizerServer/.venv/lib/python3.8/site-packages/sqlalchemy/engine/base.py", line 3278, in connect
    return self._connection_cls(self)
  File "/Users/chronos_386/PycharmProjects/FaceRecognizerServer/.venv/lib/python3.8/site-packages/sqlalchemy/engine/base.py", line 148, in __init__
    Connection._handle_dbapi_exception_noconnection(
  File "/Users/chronos_386/PycharmProjects/FaceRecognizerServer/.venv/lib/python3.8/site-packages/sqlalchemy/engine/base.py", line 2442, in _handle_dbapi_exception_noconnection
    raise sqlalchemy_exception.with_traceback(exc_info[2]) from e
  File "/Users/chronos_386/PycharmProjects/FaceRecognizerServer/.venv/lib/python3.8/site-packages/sqlalchemy/engine/base.py", line 146, in __init__
    self._dbapi_connection = engine.raw_connection()
  File "/Users/chronos_386/PycharmProjects/FaceRecognizerServer/.venv/lib/python3.8/site-packages/sqlalchemy/engine/base.py", line 3302, in raw_connection
    return self.pool.connect()
  File "/Users/chronos_386/PycharmProjects/FaceRecognizerServer/.venv/lib/python3.8/site-packages/sqlalchemy/pool/base.py", line 449, in connect
    return _ConnectionFairy._checkout(self)
  File "/Users/chronos_386/PycharmProjects/FaceRecognizerServer/.venv/lib/python3.8/site-packages/sqlalchemy/pool/base.py", line 1263, in _checkout
    fairy = _ConnectionRecord.checkout(pool)
  File "/Users/chronos_386/PycharmProjects/FaceRecognizerServer/.venv/lib/python3.8/site-packages/sqlalchemy/pool/base.py", line 712, in checkout
    rec = pool._do_get()
  File "/Users/chronos_386/PycharmProjects/FaceRecognizerServer/.venv/lib/python3.8/site-packages/sqlalchemy/pool/impl.py", line 180, in _do_get
    self._dec_overflow()
  File "/Users/chronos_386/PycharmProjects/FaceRecognizerServer/.venv/lib/python3.8/site-packages/sqlalchemy/util/langhelpers.py", line 146, in __exit__
    raise exc_value.with_traceback(exc_tb)
  File "/Users/chronos_386/PycharmProjects/FaceRecognizerServer/.venv/lib/python3.8/site-packages/sqlalchemy/pool/impl.py", line 177, in _do_get
    return self._create_connection()
  File "/Users/chronos_386/PycharmProjects/FaceRecognizerServer/.venv/lib/python3.8/site-packages/sqlalchemy/pool/base.py", line 390, in _create_connection
    return _ConnectionRecord(self)
  File "/Users/chronos_386/PycharmProjects/FaceRecognizerServer/.venv/lib/python3.8/site-packages/sqlalchemy/pool/base.py", line 674, in __init__
    self.__connect()
  File "/Users/chronos_386/PycharmProjects/FaceRecognizerServer/.venv/lib/python3.8/site-packages/sqlalchemy/pool/base.py", line 901, in __connect
    pool.logger.debug("Error on connect(): %s", e)
  File "/Users/chronos_386/PycharmProjects/FaceRecognizerServer/.venv/lib/python3.8/site-packages/sqlalchemy/util/langhelpers.py", line 146, in __exit__
    raise exc_value.with_traceback(exc_tb)
  File "/Users/chronos_386/PycharmProjects/FaceRecognizerServer/.venv/lib/python3.8/site-packages/sqlalchemy/pool/base.py", line 896, in __connect
    self.dbapi_connection = connection = pool._invoke_creator(self)
  File "/Users/chronos_386/PycharmProjects/FaceRecognizerServer/.venv/lib/python3.8/site-packages/sqlalchemy/engine/create.py", line 643, in connect
    return dialect.connect(*cargs, **cparams)
  File "/Users/chronos_386/PycharmProjects/FaceRecognizerServer/.venv/lib/python3.8/site-packages/sqlalchemy/engine/default.py", line 621, in connect
    return self.loaded_dbapi.connect(*cargs, **cparams)
  File "/Users/chronos_386/PycharmProjects/FaceRecognizerServer/.venv/lib/python3.8/site-packages/pg8000/__init__.py", line 111, in connect
    return Connection(
  File "/Users/chronos_386/PycharmProjects/FaceRecognizerServer/.venv/lib/python3.8/site-packages/pg8000/legacy.py", line 443, in __init__
    super().__init__(*args, **kwargs)
  File "/Users/chronos_386/PycharmProjects/FaceRecognizerServer/.venv/lib/python3.8/site-packages/pg8000/core.py", line 320, in __init__
    self.channel_binding, self._usock = _make_socket(
  File "/Users/chronos_386/PycharmProjects/FaceRecognizerServer/.venv/lib/python3.8/site-packages/pg8000/core.py", line 208, in _make_socket
    raise InterfaceError(
sqlalchemy.exc.InterfaceError: (pg8000.exceptions.InterfaceError) Can't create a connection to host localhost and port 5432 (timeout is None and source_address is None).
(Background on this error at: https://sqlalche.me/e/20/rvf5)


2025-01-26 17:21:22 - ERROR - Необработанная ошибка: (pg8000.exceptions.InterfaceError) Can't create a connection to host localhost and port 5432 (timeout is None and source_address is None).
(Background on this error at: https://sqlalche.me/e/20/rvf5)
Traceback (most recent call last):
  File "/Users/chronos_386/PycharmProjects/FaceRecognizerServer/.venv/lib/python3.8/site-packages/pg8000/core.py", line 206, in _make_socket
    sock = socket.create_connection((host, port), timeout, source_address)
  File "/Library/Frameworks/Python.framework/Versions/3.8/lib/python3.8/socket.py", line 808, in create_connection
    raise err
  File "/Library/Frameworks/Python.framework/Versions/3.8/lib/python3.8/socket.py", line 796, in create_connection
    sock.connect(sa)
ConnectionRefusedError: [Errno 61] Connection refused

The above exception was the direct cause of the following exception:

Traceback (most recent call last):
  File "/Users/chronos_386/PycharmProjects/FaceRecognizerServer/.venv/lib/python3.8/site-packages/sqlalchemy/engine/base.py", line 146, in __init__
    self._dbapi_connection = engine.raw_connection()
  File "/Users/chronos_386/PycharmProjects/FaceRecognizerServer/.venv/lib/python3.8/site-packages/sqlalchemy/engine/base.py", line 3302, in raw_connection
    return self.pool.connect()
  File "/Users/chronos_386/PycharmProjects/FaceRecognizerServer/.venv/lib/python3.8/site-packages/sqlalchemy/pool/base.py", line 449, in connect
    return _ConnectionFairy._checkout(self)
  File "/Users/chronos_386/PycharmProjects/FaceRecognizerServer/.venv/lib/python3.8/site-packages/sqlalchemy/pool/base.py", line 1263, in _checkout
    fairy = _ConnectionRecord.checkout(pool)
  File "/Users/chronos_386/PycharmProjects/FaceRecognizerServer/.venv/lib/python3.8/site-packages/sqlalchemy/pool/base.py", line 712, in checkout
    rec = pool._do_get()
  File "/Users/chronos_386/PycharmProjects/FaceRecognizerServer/.venv/lib/python3.8/site-packages/sqlalchemy/pool/impl.py", line 180, in _do_get
    self._dec_overflow()
  File "/Users/chronos_386/PycharmProjects/FaceRecognizerServer/.venv/lib/python3.8/site-packages/sqlalchemy/util/langhelpers.py", line 146, in __exit__
    raise exc_value.with_traceback(exc_tb)
  File "/Users/chronos_386/PycharmProjects/FaceRecognizerServer/.venv/lib/python3.8/site-packages/sqlalchemy/pool/impl.py", line 177, in _do_get
    return self._create_connection()
  File "/Users/chronos_386/PycharmProjects/FaceRecognizerServer/.venv/lib/python3.8/site-packages/sqlalchemy/pool/base.py", line 390, in _create_connection
    return _ConnectionRecord(self)
  File "/Users/chronos_386/PycharmProjects/FaceRecognizerServer/.venv/lib/python3.8/site-packages/sqlalchemy/pool/base.py", line 674, in __init__
    self.__connect()
  File "/Users/chronos_386/PycharmProjects/FaceRecognizerServer/.venv/lib/python3.8/site-packages/sqlalchemy/pool/base.py", line 901, in __connect
    pool.logger.debug("Error on connect(): %s", e)
  File "/Users/chronos_386/PycharmProjects/FaceRecognizerServer/.venv/lib/python3.8/site-packages/sqlalchemy/util/langhelpers.py", line 146, in __exit__
    raise exc_value.with_traceback(exc_tb)
  File "/Users/chronos_386/PycharmProjects/FaceRecognizerServer/.venv/lib/python3.8/site-packages/sqlalchemy/pool/base.py", line 896, in __connect
    self.dbapi_connection = connection = pool._invoke_creator(self)
  File "/Users/chronos_386/PycharmProjects/FaceRecognizerServer/.venv/lib/python3.8/site-packages/sqlalchemy/engine/create.py", line 643, in connect
    return dialect.connect(*cargs, **cparams)
  File "/Users/chronos_386/PycharmProjects/FaceRecognizerServer/.venv/lib/python3.8/site-packages/sqlalchemy/engine/default.py", line 621, in connect
    return self.loaded_dbapi.connect(*cargs, **cparams)
  File "/Users/chronos_386/PycharmProjects/FaceRecognizerServer/.venv/lib/python3.8/site-packages/pg8000/__init__.py", line 111, in connect
    return Connection(
  File "/Users/chronos_386/PycharmProjects/FaceRecognizerServer/.venv/lib/python3.8/site-packages/pg8000/legacy.py", line 443, in __init__
    super().__init__(*args, **kwargs)
  File "/Users/chronos_386/PycharmProjects/FaceRecognizerServer/.venv/lib/python3.8/site-packages/pg8000/core.py", line 320, in __init__
    self.channel_binding, self._usock = _make_socket(
  File "/Users/chronos_386/PycharmProjects/FaceRecognizerServer/.venv/lib/python3.8/site-packages/pg8000/core.py", line 208, in _make_socket
    raise InterfaceError(
pg8000.exceptions.InterfaceError: Can't create a connection to host localhost and port 5432 (timeout is None and source_address is None).

The above exception was the direct cause of the following exception:

Traceback (most recent call last):
  File "/Users/chronos_386/PycharmProjects/FaceRecognizerServer/.venv/lib/python3.8/site-packages/flask/app.py", line 880, in full_dispatch_request
    rv = self.dispatch_request()
  File "/Users/chronos_386/PycharmProjects/FaceRecognizerServer/.venv/lib/python3.8/site-packages/flask/app.py", line 865, in dispatch_request
    return self.ensure_sync(self.view_functions[rule.endpoint])(**view_args)  # type: ignore[no-any-return]
  File "/Users/chronos_386/PycharmProjects/FaceRecognizerServer/.venv/lib/python3.8/site-packages/flask_restful/__init__.py", line 489, in wrapper
    resp = resource(*args, **kwargs)
  File "/Users/chronos_386/PycharmProjects/FaceRecognizerServer/.venv/lib/python3.8/site-packages/flask/views.py", line 110, in view
    return current_app.ensure_sync(self.dispatch_request)(**kwargs)  # type: ignore[no-any-return]
  File "/Users/chronos_386/PycharmProjects/FaceRecognizerServer/.venv/lib/python3.8/site-packages/flask_restful/__init__.py", line 604, in dispatch_request
    resp = meth(*args, **kwargs)
  File "/Users/chronos_386/PycharmProjects/FaceRecognizerServer/source_code/resources/schedule_device_res.py", line 12, in post
    student_id, json_model, code = self.api_connector.getStudentScheduleByPhoto(file)
  File "/Users/chronos_386/PycharmProjects/FaceRecognizerServer/source_code/api_connection/api_connector.py", line 674, in getStudentScheduleByPhoto
    student, code = self.__handleGetStudentByPhoto(photo)
  File "/Users/chronos_386/PycharmProjects/FaceRecognizerServer/source_code/api_connection/api_connector.py", line 89, in __handleGetStudentByPhoto
    emb: List[FaceEmbeddingsDB] = self.db_class.getAllEmbeddings()
  File "/Users/chronos_386/PycharmProjects/FaceRecognizerServer/source_code/db_connection/db_class.py", line 176, in getAllEmbeddings
    embeddings: List[Type[FaceEmbeddingsDB]] = self.session.query(FaceEmbeddingsDB).all()
  File "/Users/chronos_386/PycharmProjects/FaceRecognizerServer/.venv/lib/python3.8/site-packages/sqlalchemy/orm/query.py", line 2673, in all
    return self._iter().all()  # type: ignore
  File "/Users/chronos_386/PycharmProjects/FaceRecognizerServer/.venv/lib/python3.8/site-packages/sqlalchemy/orm/query.py", line 2827, in _iter
    result: Union[ScalarResult[_T], Result[_T]] = self.session.execute(
  File "/Users/chronos_386/PycharmProjects/FaceRecognizerServer/.venv/lib/python3.8/site-packages/sqlalchemy/orm/session.py", line 2362, in execute
    return self._execute_internal(
  File "/Users/chronos_386/PycharmProjects/FaceRecognizerServer/.venv/lib/python3.8/site-packages/sqlalchemy/orm/session.py", line 2237, in _execute_internal
    conn = self._connection_for_bind(bind)
  File "/Users/chronos_386/PycharmProjects/FaceRecognizerServer/.venv/lib/python3.8/site-packages/sqlalchemy/orm/session.py", line 2106, in _connection_for_bind
    return trans._connection_for_bind(engine, execution_options)
  File "<string>", line 2, in _connection_for_bind
  File "/Users/chronos_386/PycharmProjects/FaceRecognizerServer/.venv/lib/python3.8/site-packages/sqlalchemy/orm/state_changes.py", line 139, in _go
    ret_value = fn(self, *arg, **kw)
  File "/Users/chronos_386/PycharmProjects/FaceRecognizerServer/.venv/lib/python3.8/site-packages/sqlalchemy/orm/session.py", line 1189, in _connection_for_bind
    conn = bind.connect()
  File "/Users/chronos_386/PycharmProjects/FaceRecognizerServer/.venv/lib/python3.8/site-packages/sqlalchemy/engine/base.py", line 3278, in connect
    return self._connection_cls(self)
  File "/Users/chronos_386/PycharmProjects/FaceRecognizerServer/.venv/lib/python3.8/site-packages/sqlalchemy/engine/base.py", line 148, in __init__
    Connection._handle_dbapi_exception_noconnection(
  File "/Users/chronos_386/PycharmProjects/FaceRecognizerServer/.venv/lib/python3.8/site-packages/sqlalchemy/engine/base.py", line 2442, in _handle_dbapi_exception_noconnection
    raise sqlalchemy_exception.with_traceback(exc_info[2]) from e
  File "/Users/chronos_386/PycharmProjects/FaceRecognizerServer/.venv/lib/python3.8/site-packages/sqlalchemy/engine/base.py", line 146, in __init__
    self._dbapi_connection = engine.raw_connection()
  File "/Users/chronos_386/PycharmProjects/FaceRecognizerServer/.venv/lib/python3.8/site-packages/sqlalchemy/engine/base.py", line 3302, in raw_connection
    return self.pool.connect()
  File "/Users/chronos_386/PycharmProjects/FaceRecognizerServer/.venv/lib/python3.8/site-packages/sqlalchemy/pool/base.py", line 449, in connect
    return _ConnectionFairy._checkout(self)
  File "/Users/chronos_386/PycharmProjects/FaceRecognizerServer/.venv/lib/python3.8/site-packages/sqlalchemy/pool/base.py", line 1263, in _checkout
    fairy = _ConnectionRecord.checkout(pool)
  File "/Users/chronos_386/PycharmProjects/FaceRecognizerServer/.venv/lib/python3.8/site-packages/sqlalchemy/pool/base.py", line 712, in checkout
    rec = pool._do_get()
  File "/Users/chronos_386/PycharmProjects/FaceRecognizerServer/.venv/lib/python3.8/site-packages/sqlalchemy/pool/impl.py", line 180, in _do_get
    self._dec_overflow()
  File "/Users/chronos_386/PycharmProjects/FaceRecognizerServer/.venv/lib/python3.8/site-packages/sqlalchemy/util/langhelpers.py", line 146, in __exit__
    raise exc_value.with_traceback(exc_tb)
  File "/Users/chronos_386/PycharmProjects/FaceRecognizerServer/.venv/lib/python3.8/site-packages/sqlalchemy/pool/impl.py", line 177, in _do_get
    return self._create_connection()
  File "/Users/chronos_386/PycharmProjects/FaceRecognizerServer/.venv/lib/python3.8/site-packages/sqlalchemy/pool/base.py", line 390, in _create_connection
    return _ConnectionRecord(self)
  File "/Users/chronos_386/PycharmProjects/FaceRecognizerServer/.venv/lib/python3.8/site-packages/sqlalchemy/pool/base.py", line 674, in __init__
    self.__connect()
  File "/Users/chronos_386/PycharmProjects/FaceRecognizerServer/.venv/lib/python3.8/site-packages/sqlalchemy/pool/base.py", line 901, in __connect
    pool.logger.debug("Error on connect(): %s", e)
  File "/Users/chronos_386/PycharmProjects/FaceRecognizerServer/.venv/lib/python3.8/site-packages/sqlalchemy/util/langhelpers.py", line 146, in __exit__
    raise exc_value.with_traceback(exc_tb)
  File "/Users/chronos_386/PycharmProjects/FaceRecognizerServer/.venv/lib/python3.8/site-packages/sqlalchemy/pool/base.py", line 896, in __connect
    self.dbapi_connection = connection = pool._invoke_creator(self)
  File "/Users/chronos_386/PycharmProjects/FaceRecognizerServer/.venv/lib/python3.8/site-packages/sqlalchemy/engine/create.py", line 643, in connect
    return dialect.connect(*cargs, **cparams)
  File "/Users/chronos_386/PycharmProjects/FaceRecognizerServer/.venv/lib/python3.8/site-packages/sqlalchemy/engine/default.py", line 621, in connect
    return self.loaded_dbapi.connect(*cargs, **cparams)
  File "/Users/chronos_386/PycharmProjects/FaceRecognizerServer/.venv/lib/python3.8/site-packages/pg8000/__init__.py", line 111, in connect
    return Connection(
  File "/Users/chronos_386/PycharmProjects/FaceRecognizerServer/.venv/lib/python3.8/site-packages/pg8000/legacy.py", line 443, in __init__
    super().__init__(*args, **kwargs)
  File "/Users/chronos_386/PycharmProjects/FaceRecognizerServer/.venv/lib/python3.8/site-packages/pg8000/core.py", line 320, in __init__
    self.channel_binding, self._usock = _make_socket(
  File "/Users/chronos_386/PycharmProjects/FaceRecognizerServer/.venv/lib/python3.8/site-packages/pg8000/core.py", line 208, in _make_socket
    raise InterfaceError(
sqlalchemy.exc.InterfaceError: (pg8000.exceptions.InterfaceError) Can't create a connection to host localhost and port 5432 (timeout is None and source_address is None).
(Background on this error at: https://sqlalche.me/e/20/rvf5)


2025-01-26 17:21:51 - ERROR - Необработанная ошибка: (pg8000.exceptions.InterfaceError) Can't create a connection to host localhost and port 5432 (timeout is None and source_address is None).
(Background on this error at: https://sqlalche.me/e/20/rvf5)
Traceback (most recent call last):
  File "/Users/chronos_386/PycharmProjects/FaceRecognizerServer/.venv/lib/python3.8/site-packages/pg8000/core.py", line 206, in _make_socket
    sock = socket.create_connection((host, port), timeout, source_address)
  File "/Library/Frameworks/Python.framework/Versions/3.8/lib/python3.8/socket.py", line 808, in create_connection
    raise err
  File "/Library/Frameworks/Python.framework/Versions/3.8/lib/python3.8/socket.py", line 796, in create_connection
    sock.connect(sa)
ConnectionRefusedError: [Errno 61] Connection refused

The above exception was the direct cause of the following exception:

Traceback (most recent call last):
  File "/Users/chronos_386/PycharmProjects/FaceRecognizerServer/.venv/lib/python3.8/site-packages/sqlalchemy/engine/base.py", line 146, in __init__
    self._dbapi_connection = engine.raw_connection()
  File "/Users/chronos_386/PycharmProjects/FaceRecognizerServer/.venv/lib/python3.8/site-packages/sqlalchemy/engine/base.py", line 3302, in raw_connection
    return self.pool.connect()
  File "/Users/chronos_386/PycharmProjects/FaceRecognizerServer/.venv/lib/python3.8/site-packages/sqlalchemy/pool/base.py", line 449, in connect
    return _ConnectionFairy._checkout(self)
  File "/Users/chronos_386/PycharmProjects/FaceRecognizerServer/.venv/lib/python3.8/site-packages/sqlalchemy/pool/base.py", line 1263, in _checkout
    fairy = _ConnectionRecord.checkout(pool)
  File "/Users/chronos_386/PycharmProjects/FaceRecognizerServer/.venv/lib/python3.8/site-packages/sqlalchemy/pool/base.py", line 712, in checkout
    rec = pool._do_get()
  File "/Users/chronos_386/PycharmProjects/FaceRecognizerServer/.venv/lib/python3.8/site-packages/sqlalchemy/pool/impl.py", line 180, in _do_get
    self._dec_overflow()
  File "/Users/chronos_386/PycharmProjects/FaceRecognizerServer/.venv/lib/python3.8/site-packages/sqlalchemy/util/langhelpers.py", line 146, in __exit__
    raise exc_value.with_traceback(exc_tb)
  File "/Users/chronos_386/PycharmProjects/FaceRecognizerServer/.venv/lib/python3.8/site-packages/sqlalchemy/pool/impl.py", line 177, in _do_get
    return self._create_connection()
  File "/Users/chronos_386/PycharmProjects/FaceRecognizerServer/.venv/lib/python3.8/site-packages/sqlalchemy/pool/base.py", line 390, in _create_connection
    return _ConnectionRecord(self)
  File "/Users/chronos_386/PycharmProjects/FaceRecognizerServer/.venv/lib/python3.8/site-packages/sqlalchemy/pool/base.py", line 674, in __init__
    self.__connect()
  File "/Users/chronos_386/PycharmProjects/FaceRecognizerServer/.venv/lib/python3.8/site-packages/sqlalchemy/pool/base.py", line 901, in __connect
    pool.logger.debug("Error on connect(): %s", e)
  File "/Users/chronos_386/PycharmProjects/FaceRecognizerServer/.venv/lib/python3.8/site-packages/sqlalchemy/util/langhelpers.py", line 146, in __exit__
    raise exc_value.with_traceback(exc_tb)
  File "/Users/chronos_386/PycharmProjects/FaceRecognizerServer/.venv/lib/python3.8/site-packages/sqlalchemy/pool/base.py", line 896, in __connect
    self.dbapi_connection = connection = pool._invoke_creator(self)
  File "/Users/chronos_386/PycharmProjects/FaceRecognizerServer/.venv/lib/python3.8/site-packages/sqlalchemy/engine/create.py", line 643, in connect
    return dialect.connect(*cargs, **cparams)
  File "/Users/chronos_386/PycharmProjects/FaceRecognizerServer/.venv/lib/python3.8/site-packages/sqlalchemy/engine/default.py", line 621, in connect
    return self.loaded_dbapi.connect(*cargs, **cparams)
  File "/Users/chronos_386/PycharmProjects/FaceRecognizerServer/.venv/lib/python3.8/site-packages/pg8000/__init__.py", line 111, in connect
    return Connection(
  File "/Users/chronos_386/PycharmProjects/FaceRecognizerServer/.venv/lib/python3.8/site-packages/pg8000/legacy.py", line 443, in __init__
    super().__init__(*args, **kwargs)
  File "/Users/chronos_386/PycharmProjects/FaceRecognizerServer/.venv/lib/python3.8/site-packages/pg8000/core.py", line 320, in __init__
    self.channel_binding, self._usock = _make_socket(
  File "/Users/chronos_386/PycharmProjects/FaceRecognizerServer/.venv/lib/python3.8/site-packages/pg8000/core.py", line 208, in _make_socket
    raise InterfaceError(
pg8000.exceptions.InterfaceError: Can't create a connection to host localhost and port 5432 (timeout is None and source_address is None).

The above exception was the direct cause of the following exception:

Traceback (most recent call last):
  File "/Users/chronos_386/PycharmProjects/FaceRecognizerServer/.venv/lib/python3.8/site-packages/flask/app.py", line 880, in full_dispatch_request
    rv = self.dispatch_request()
  File "/Users/chronos_386/PycharmProjects/FaceRecognizerServer/.venv/lib/python3.8/site-packages/flask/app.py", line 865, in dispatch_request
    return self.ensure_sync(self.view_functions[rule.endpoint])(**view_args)  # type: ignore[no-any-return]
  File "/Users/chronos_386/PycharmProjects/FaceRecognizerServer/.venv/lib/python3.8/site-packages/flask_restful/__init__.py", line 489, in wrapper
    resp = resource(*args, **kwargs)
  File "/Users/chronos_386/PycharmProjects/FaceRecognizerServer/.venv/lib/python3.8/site-packages/flask/views.py", line 110, in view
    return current_app.ensure_sync(self.dispatch_request)(**kwargs)  # type: ignore[no-any-return]
  File "/Users/chronos_386/PycharmProjects/FaceRecognizerServer/.venv/lib/python3.8/site-packages/flask_restful/__init__.py", line 604, in dispatch_request
    resp = meth(*args, **kwargs)
  File "/Users/chronos_386/PycharmProjects/FaceRecognizerServer/source_code/resources/schedule_device_res.py", line 12, in post
    student_id, json_model, code = self.api_connector.getStudentScheduleByPhoto(file)
  File "/Users/chronos_386/PycharmProjects/FaceRecognizerServer/source_code/api_connection/api_connector.py", line 674, in getStudentScheduleByPhoto
    student, code = self.__handleGetStudentByPhoto(photo)
  File "/Users/chronos_386/PycharmProjects/FaceRecognizerServer/source_code/api_connection/api_connector.py", line 89, in __handleGetStudentByPhoto
    emb: List[FaceEmbeddingsDB] = self.db_class.getAllEmbeddings()
  File "/Users/chronos_386/PycharmProjects/FaceRecognizerServer/source_code/db_connection/db_class.py", line 176, in getAllEmbeddings
    embeddings: List[Type[FaceEmbeddingsDB]] = self.session.query(FaceEmbeddingsDB).all()
  File "/Users/chronos_386/PycharmProjects/FaceRecognizerServer/.venv/lib/python3.8/site-packages/sqlalchemy/orm/query.py", line 2673, in all
    return self._iter().all()  # type: ignore
  File "/Users/chronos_386/PycharmProjects/FaceRecognizerServer/.venv/lib/python3.8/site-packages/sqlalchemy/orm/query.py", line 2827, in _iter
    result: Union[ScalarResult[_T], Result[_T]] = self.session.execute(
  File "/Users/chronos_386/PycharmProjects/FaceRecognizerServer/.venv/lib/python3.8/site-packages/sqlalchemy/orm/session.py", line 2362, in execute
    return self._execute_internal(
  File "/Users/chronos_386/PycharmProjects/FaceRecognizerServer/.venv/lib/python3.8/site-packages/sqlalchemy/orm/session.py", line 2237, in _execute_internal
    conn = self._connection_for_bind(bind)
  File "/Users/chronos_386/PycharmProjects/FaceRecognizerServer/.venv/lib/python3.8/site-packages/sqlalchemy/orm/session.py", line 2106, in _connection_for_bind
    return trans._connection_for_bind(engine, execution_options)
  File "<string>", line 2, in _connection_for_bind
  File "/Users/chronos_386/PycharmProjects/FaceRecognizerServer/.venv/lib/python3.8/site-packages/sqlalchemy/orm/state_changes.py", line 139, in _go
    ret_value = fn(self, *arg, **kw)
  File "/Users/chronos_386/PycharmProjects/FaceRecognizerServer/.venv/lib/python3.8/site-packages/sqlalchemy/orm/session.py", line 1189, in _connection_for_bind
    conn = bind.connect()
  File "/Users/chronos_386/PycharmProjects/FaceRecognizerServer/.venv/lib/python3.8/site-packages/sqlalchemy/engine/base.py", line 3278, in connect
    return self._connection_cls(self)
  File "/Users/chronos_386/PycharmProjects/FaceRecognizerServer/.venv/lib/python3.8/site-packages/sqlalchemy/engine/base.py", line 148, in __init__
    Connection._handle_dbapi_exception_noconnection(
  File "/Users/chronos_386/PycharmProjects/FaceRecognizerServer/.venv/lib/python3.8/site-packages/sqlalchemy/engine/base.py", line 2442, in _handle_dbapi_exception_noconnection
    raise sqlalchemy_exception.with_traceback(exc_info[2]) from e
  File "/Users/chronos_386/PycharmProjects/FaceRecognizerServer/.venv/lib/python3.8/site-packages/sqlalchemy/engine/base.py", line 146, in __init__
    self._dbapi_connection = engine.raw_connection()
  File "/Users/chronos_386/PycharmProjects/FaceRecognizerServer/.venv/lib/python3.8/site-packages/sqlalchemy/engine/base.py", line 3302, in raw_connection
    return self.pool.connect()
  File "/Users/chronos_386/PycharmProjects/FaceRecognizerServer/.venv/lib/python3.8/site-packages/sqlalchemy/pool/base.py", line 449, in connect
    return _ConnectionFairy._checkout(self)
  File "/Users/chronos_386/PycharmProjects/FaceRecognizerServer/.venv/lib/python3.8/site-packages/sqlalchemy/pool/base.py", line 1263, in _checkout
    fairy = _ConnectionRecord.checkout(pool)
  File "/Users/chronos_386/PycharmProjects/FaceRecognizerServer/.venv/lib/python3.8/site-packages/sqlalchemy/pool/base.py", line 712, in checkout
    rec = pool._do_get()
  File "/Users/chronos_386/PycharmProjects/FaceRecognizerServer/.venv/lib/python3.8/site-packages/sqlalchemy/pool/impl.py", line 180, in _do_get
    self._dec_overflow()
  File "/Users/chronos_386/PycharmProjects/FaceRecognizerServer/.venv/lib/python3.8/site-packages/sqlalchemy/util/langhelpers.py", line 146, in __exit__
    raise exc_value.with_traceback(exc_tb)
  File "/Users/chronos_386/PycharmProjects/FaceRecognizerServer/.venv/lib/python3.8/site-packages/sqlalchemy/pool/impl.py", line 177, in _do_get
    return self._create_connection()
  File "/Users/chronos_386/PycharmProjects/FaceRecognizerServer/.venv/lib/python3.8/site-packages/sqlalchemy/pool/base.py", line 390, in _create_connection
    return _ConnectionRecord(self)
  File "/Users/chronos_386/PycharmProjects/FaceRecognizerServer/.venv/lib/python3.8/site-packages/sqlalchemy/pool/base.py", line 674, in __init__
    self.__connect()
  File "/Users/chronos_386/PycharmProjects/FaceRecognizerServer/.venv/lib/python3.8/site-packages/sqlalchemy/pool/base.py", line 901, in __connect
    pool.logger.debug("Error on connect(): %s", e)
  File "/Users/chronos_386/PycharmProjects/FaceRecognizerServer/.venv/lib/python3.8/site-packages/sqlalchemy/util/langhelpers.py", line 146, in __exit__
    raise exc_value.with_traceback(exc_tb)
  File "/Users/chronos_386/PycharmProjects/FaceRecognizerServer/.venv/lib/python3.8/site-packages/sqlalchemy/pool/base.py", line 896, in __connect
    self.dbapi_connection = connection = pool._invoke_creator(self)
  File "/Users/chronos_386/PycharmProjects/FaceRecognizerServer/.venv/lib/python3.8/site-packages/sqlalchemy/engine/create.py", line 643, in connect
    return dialect.connect(*cargs, **cparams)
  File "/Users/chronos_386/PycharmProjects/FaceRecognizerServer/.venv/lib/python3.8/site-packages/sqlalchemy/engine/default.py", line 621, in connect
    return self.loaded_dbapi.connect(*cargs, **cparams)
  File "/Users/chronos_386/PycharmProjects/FaceRecognizerServer/.venv/lib/python3.8/site-packages/pg8000/__init__.py", line 111, in connect
    return Connection(
  File "/Users/chronos_386/PycharmProjects/FaceRecognizerServer/.venv/lib/python3.8/site-packages/pg8000/legacy.py", line 443, in __init__
    super().__init__(*args, **kwargs)
  File "/Users/chronos_386/PycharmProjects/FaceRecognizerServer/.venv/lib/python3.8/site-packages/pg8000/core.py", line 320, in __init__
    self.channel_binding, self._usock = _make_socket(
  File "/Users/chronos_386/PycharmProjects/FaceRecognizerServer/.venv/lib/python3.8/site-packages/pg8000/core.py", line 208, in _make_socket
    raise InterfaceError(
sqlalchemy.exc.InterfaceError: (pg8000.exceptions.InterfaceError) Can't create a connection to host localhost and port 5432 (timeout is None and source_address is None).
(Background on this error at: https://sqlalche.me/e/20/rvf5)


2025-01-26 17:21:51 - ERROR - Необработанная ошибка: (pg8000.exceptions.InterfaceError) Can't create a connection to host localhost and port 5432 (timeout is None and source_address is None).
(Background on this error at: https://sqlalche.me/e/20/rvf5)
Traceback (most recent call last):
  File "/Users/chronos_386/PycharmProjects/FaceRecognizerServer/.venv/lib/python3.8/site-packages/pg8000/core.py", line 206, in _make_socket
    sock = socket.create_connection((host, port), timeout, source_address)
  File "/Library/Frameworks/Python.framework/Versions/3.8/lib/python3.8/socket.py", line 808, in create_connection
    raise err
  File "/Library/Frameworks/Python.framework/Versions/3.8/lib/python3.8/socket.py", line 796, in create_connection
    sock.connect(sa)
ConnectionRefusedError: [Errno 61] Connection refused

The above exception was the direct cause of the following exception:

Traceback (most recent call last):
  File "/Users/chronos_386/PycharmProjects/FaceRecognizerServer/.venv/lib/python3.8/site-packages/sqlalchemy/engine/base.py", line 146, in __init__
    self._dbapi_connection = engine.raw_connection()
  File "/Users/chronos_386/PycharmProjects/FaceRecognizerServer/.venv/lib/python3.8/site-packages/sqlalchemy/engine/base.py", line 3302, in raw_connection
    return self.pool.connect()
  File "/Users/chronos_386/PycharmProjects/FaceRecognizerServer/.venv/lib/python3.8/site-packages/sqlalchemy/pool/base.py", line 449, in connect
    return _ConnectionFairy._checkout(self)
  File "/Users/chronos_386/PycharmProjects/FaceRecognizerServer/.venv/lib/python3.8/site-packages/sqlalchemy/pool/base.py", line 1263, in _checkout
    fairy = _ConnectionRecord.checkout(pool)
  File "/Users/chronos_386/PycharmProjects/FaceRecognizerServer/.venv/lib/python3.8/site-packages/sqlalchemy/pool/base.py", line 712, in checkout
    rec = pool._do_get()
  File "/Users/chronos_386/PycharmProjects/FaceRecognizerServer/.venv/lib/python3.8/site-packages/sqlalchemy/pool/impl.py", line 180, in _do_get
    self._dec_overflow()
  File "/Users/chronos_386/PycharmProjects/FaceRecognizerServer/.venv/lib/python3.8/site-packages/sqlalchemy/util/langhelpers.py", line 146, in __exit__
    raise exc_value.with_traceback(exc_tb)
  File "/Users/chronos_386/PycharmProjects/FaceRecognizerServer/.venv/lib/python3.8/site-packages/sqlalchemy/pool/impl.py", line 177, in _do_get
    return self._create_connection()
  File "/Users/chronos_386/PycharmProjects/FaceRecognizerServer/.venv/lib/python3.8/site-packages/sqlalchemy/pool/base.py", line 390, in _create_connection
    return _ConnectionRecord(self)
  File "/Users/chronos_386/PycharmProjects/FaceRecognizerServer/.venv/lib/python3.8/site-packages/sqlalchemy/pool/base.py", line 674, in __init__
    self.__connect()
  File "/Users/chronos_386/PycharmProjects/FaceRecognizerServer/.venv/lib/python3.8/site-packages/sqlalchemy/pool/base.py", line 901, in __connect
    pool.logger.debug("Error on connect(): %s", e)
  File "/Users/chronos_386/PycharmProjects/FaceRecognizerServer/.venv/lib/python3.8/site-packages/sqlalchemy/util/langhelpers.py", line 146, in __exit__
    raise exc_value.with_traceback(exc_tb)
  File "/Users/chronos_386/PycharmProjects/FaceRecognizerServer/.venv/lib/python3.8/site-packages/sqlalchemy/pool/base.py", line 896, in __connect
    self.dbapi_connection = connection = pool._invoke_creator(self)
  File "/Users/chronos_386/PycharmProjects/FaceRecognizerServer/.venv/lib/python3.8/site-packages/sqlalchemy/engine/create.py", line 643, in connect
    return dialect.connect(*cargs, **cparams)
  File "/Users/chronos_386/PycharmProjects/FaceRecognizerServer/.venv/lib/python3.8/site-packages/sqlalchemy/engine/default.py", line 621, in connect
    return self.loaded_dbapi.connect(*cargs, **cparams)
  File "/Users/chronos_386/PycharmProjects/FaceRecognizerServer/.venv/lib/python3.8/site-packages/pg8000/__init__.py", line 111, in connect
    return Connection(
  File "/Users/chronos_386/PycharmProjects/FaceRecognizerServer/.venv/lib/python3.8/site-packages/pg8000/legacy.py", line 443, in __init__
    super().__init__(*args, **kwargs)
  File "/Users/chronos_386/PycharmProjects/FaceRecognizerServer/.venv/lib/python3.8/site-packages/pg8000/core.py", line 320, in __init__
    self.channel_binding, self._usock = _make_socket(
  File "/Users/chronos_386/PycharmProjects/FaceRecognizerServer/.venv/lib/python3.8/site-packages/pg8000/core.py", line 208, in _make_socket
    raise InterfaceError(
pg8000.exceptions.InterfaceError: Can't create a connection to host localhost and port 5432 (timeout is None and source_address is None).

The above exception was the direct cause of the following exception:

Traceback (most recent call last):
  File "/Users/chronos_386/PycharmProjects/FaceRecognizerServer/.venv/lib/python3.8/site-packages/flask/app.py", line 880, in full_dispatch_request
    rv = self.dispatch_request()
  File "/Users/chronos_386/PycharmProjects/FaceRecognizerServer/.venv/lib/python3.8/site-packages/flask/app.py", line 865, in dispatch_request
    return self.ensure_sync(self.view_functions[rule.endpoint])(**view_args)  # type: ignore[no-any-return]
  File "/Users/chronos_386/PycharmProjects/FaceRecognizerServer/.venv/lib/python3.8/site-packages/flask_restful/__init__.py", line 489, in wrapper
    resp = resource(*args, **kwargs)
  File "/Users/chronos_386/PycharmProjects/FaceRecognizerServer/.venv/lib/python3.8/site-packages/flask/views.py", line 110, in view
    return current_app.ensure_sync(self.dispatch_request)(**kwargs)  # type: ignore[no-any-return]
  File "/Users/chronos_386/PycharmProjects/FaceRecognizerServer/.venv/lib/python3.8/site-packages/flask_restful/__init__.py", line 604, in dispatch_request
    resp = meth(*args, **kwargs)
  File "/Users/chronos_386/PycharmProjects/FaceRecognizerServer/source_code/resources/schedule_device_res.py", line 12, in post
    student_id, json_model, code = self.api_connector.getStudentScheduleByPhoto(file)
  File "/Users/chronos_386/PycharmProjects/FaceRecognizerServer/source_code/api_connection/api_connector.py", line 674, in getStudentScheduleByPhoto
    student, code = self.__handleGetStudentByPhoto(photo)
  File "/Users/chronos_386/PycharmProjects/FaceRecognizerServer/source_code/api_connection/api_connector.py", line 89, in __handleGetStudentByPhoto
    emb: List[FaceEmbeddingsDB] = self.db_class.getAllEmbeddings()
  File "/Users/chronos_386/PycharmProjects/FaceRecognizerServer/source_code/db_connection/db_class.py", line 176, in getAllEmbeddings
    embeddings: List[Type[FaceEmbeddingsDB]] = self.session.query(FaceEmbeddingsDB).all()
  File "/Users/chronos_386/PycharmProjects/FaceRecognizerServer/.venv/lib/python3.8/site-packages/sqlalchemy/orm/query.py", line 2673, in all
    return self._iter().all()  # type: ignore
  File "/Users/chronos_386/PycharmProjects/FaceRecognizerServer/.venv/lib/python3.8/site-packages/sqlalchemy/orm/query.py", line 2827, in _iter
    result: Union[ScalarResult[_T], Result[_T]] = self.session.execute(
  File "/Users/chronos_386/PycharmProjects/FaceRecognizerServer/.venv/lib/python3.8/site-packages/sqlalchemy/orm/session.py", line 2362, in execute
    return self._execute_internal(
  File "/Users/chronos_386/PycharmProjects/FaceRecognizerServer/.venv/lib/python3.8/site-packages/sqlalchemy/orm/session.py", line 2237, in _execute_internal
    conn = self._connection_for_bind(bind)
  File "/Users/chronos_386/PycharmProjects/FaceRecognizerServer/.venv/lib/python3.8/site-packages/sqlalchemy/orm/session.py", line 2106, in _connection_for_bind
    return trans._connection_for_bind(engine, execution_options)
  File "<string>", line 2, in _connection_for_bind
  File "/Users/chronos_386/PycharmProjects/FaceRecognizerServer/.venv/lib/python3.8/site-packages/sqlalchemy/orm/state_changes.py", line 139, in _go
    ret_value = fn(self, *arg, **kw)
  File "/Users/chronos_386/PycharmProjects/FaceRecognizerServer/.venv/lib/python3.8/site-packages/sqlalchemy/orm/session.py", line 1189, in _connection_for_bind
    conn = bind.connect()
  File "/Users/chronos_386/PycharmProjects/FaceRecognizerServer/.venv/lib/python3.8/site-packages/sqlalchemy/engine/base.py", line 3278, in connect
    return self._connection_cls(self)
  File "/Users/chronos_386/PycharmProjects/FaceRecognizerServer/.venv/lib/python3.8/site-packages/sqlalchemy/engine/base.py", line 148, in __init__
    Connection._handle_dbapi_exception_noconnection(
  File "/Users/chronos_386/PycharmProjects/FaceRecognizerServer/.venv/lib/python3.8/site-packages/sqlalchemy/engine/base.py", line 2442, in _handle_dbapi_exception_noconnection
    raise sqlalchemy_exception.with_traceback(exc_info[2]) from e
  File "/Users/chronos_386/PycharmProjects/FaceRecognizerServer/.venv/lib/python3.8/site-packages/sqlalchemy/engine/base.py", line 146, in __init__
    self._dbapi_connection = engine.raw_connection()
  File "/Users/chronos_386/PycharmProjects/FaceRecognizerServer/.venv/lib/python3.8/site-packages/sqlalchemy/engine/base.py", line 3302, in raw_connection
    return self.pool.connect()
  File "/Users/chronos_386/PycharmProjects/FaceRecognizerServer/.venv/lib/python3.8/site-packages/sqlalchemy/pool/base.py", line 449, in connect
    return _ConnectionFairy._checkout(self)
  File "/Users/chronos_386/PycharmProjects/FaceRecognizerServer/.venv/lib/python3.8/site-packages/sqlalchemy/pool/base.py", line 1263, in _checkout
    fairy = _ConnectionRecord.checkout(pool)
  File "/Users/chronos_386/PycharmProjects/FaceRecognizerServer/.venv/lib/python3.8/site-packages/sqlalchemy/pool/base.py", line 712, in checkout
    rec = pool._do_get()
  File "/Users/chronos_386/PycharmProjects/FaceRecognizerServer/.venv/lib/python3.8/site-packages/sqlalchemy/pool/impl.py", line 180, in _do_get
    self._dec_overflow()
  File "/Users/chronos_386/PycharmProjects/FaceRecognizerServer/.venv/lib/python3.8/site-packages/sqlalchemy/util/langhelpers.py", line 146, in __exit__
    raise exc_value.with_traceback(exc_tb)
  File "/Users/chronos_386/PycharmProjects/FaceRecognizerServer/.venv/lib/python3.8/site-packages/sqlalchemy/pool/impl.py", line 177, in _do_get
    return self._create_connection()
  File "/Users/chronos_386/PycharmProjects/FaceRecognizerServer/.venv/lib/python3.8/site-packages/sqlalchemy/pool/base.py", line 390, in _create_connection
    return _ConnectionRecord(self)
  File "/Users/chronos_386/PycharmProjects/FaceRecognizerServer/.venv/lib/python3.8/site-packages/sqlalchemy/pool/base.py", line 674, in __init__
    self.__connect()
  File "/Users/chronos_386/PycharmProjects/FaceRecognizerServer/.venv/lib/python3.8/site-packages/sqlalchemy/pool/base.py", line 901, in __connect
    pool.logger.debug("Error on connect(): %s", e)
  File "/Users/chronos_386/PycharmProjects/FaceRecognizerServer/.venv/lib/python3.8/site-packages/sqlalchemy/util/langhelpers.py", line 146, in __exit__
    raise exc_value.with_traceback(exc_tb)
  File "/Users/chronos_386/PycharmProjects/FaceRecognizerServer/.venv/lib/python3.8/site-packages/sqlalchemy/pool/base.py", line 896, in __connect
    self.dbapi_connection = connection = pool._invoke_creator(self)
  File "/Users/chronos_386/PycharmProjects/FaceRecognizerServer/.venv/lib/python3.8/site-packages/sqlalchemy/engine/create.py", line 643, in connect
    return dialect.connect(*cargs, **cparams)
  File "/Users/chronos_386/PycharmProjects/FaceRecognizerServer/.venv/lib/python3.8/site-packages/sqlalchemy/engine/default.py", line 621, in connect
    return self.loaded_dbapi.connect(*cargs, **cparams)
  File "/Users/chronos_386/PycharmProjects/FaceRecognizerServer/.venv/lib/python3.8/site-packages/pg8000/__init__.py", line 111, in connect
    return Connection(
  File "/Users/chronos_386/PycharmProjects/FaceRecognizerServer/.venv/lib/python3.8/site-packages/pg8000/legacy.py", line 443, in __init__
    super().__init__(*args, **kwargs)
  File "/Users/chronos_386/PycharmProjects/FaceRecognizerServer/.venv/lib/python3.8/site-packages/pg8000/core.py", line 320, in __init__
    self.channel_binding, self._usock = _make_socket(
  File "/Users/chronos_386/PycharmProjects/FaceRecognizerServer/.venv/lib/python3.8/site-packages/pg8000/core.py", line 208, in _make_socket
    raise InterfaceError(
sqlalchemy.exc.InterfaceError: (pg8000.exceptions.InterfaceError) Can't create a connection to host localhost and port 5432 (timeout is None and source_address is None).
(Background on this error at: https://sqlalche.me/e/20/rvf5)


2025-01-26 17:21:51 - ERROR - Необработанная ошибка: (pg8000.exceptions.InterfaceError) Can't create a connection to host localhost and port 5432 (timeout is None and source_address is None).
(Background on this error at: https://sqlalche.me/e/20/rvf5)
Traceback (most recent call last):
  File "/Users/chronos_386/PycharmProjects/FaceRecognizerServer/.venv/lib/python3.8/site-packages/pg8000/core.py", line 206, in _make_socket
    sock = socket.create_connection((host, port), timeout, source_address)
  File "/Library/Frameworks/Python.framework/Versions/3.8/lib/python3.8/socket.py", line 808, in create_connection
    raise err
  File "/Library/Frameworks/Python.framework/Versions/3.8/lib/python3.8/socket.py", line 796, in create_connection
    sock.connect(sa)
ConnectionRefusedError: [Errno 61] Connection refused

The above exception was the direct cause of the following exception:

Traceback (most recent call last):
  File "/Users/chronos_386/PycharmProjects/FaceRecognizerServer/.venv/lib/python3.8/site-packages/sqlalchemy/engine/base.py", line 146, in __init__
    self._dbapi_connection = engine.raw_connection()
  File "/Users/chronos_386/PycharmProjects/FaceRecognizerServer/.venv/lib/python3.8/site-packages/sqlalchemy/engine/base.py", line 3302, in raw_connection
    return self.pool.connect()
  File "/Users/chronos_386/PycharmProjects/FaceRecognizerServer/.venv/lib/python3.8/site-packages/sqlalchemy/pool/base.py", line 449, in connect
    return _ConnectionFairy._checkout(self)
  File "/Users/chronos_386/PycharmProjects/FaceRecognizerServer/.venv/lib/python3.8/site-packages/sqlalchemy/pool/base.py", line 1263, in _checkout
    fairy = _ConnectionRecord.checkout(pool)
  File "/Users/chronos_386/PycharmProjects/FaceRecognizerServer/.venv/lib/python3.8/site-packages/sqlalchemy/pool/base.py", line 712, in checkout
    rec = pool._do_get()
  File "/Users/chronos_386/PycharmProjects/FaceRecognizerServer/.venv/lib/python3.8/site-packages/sqlalchemy/pool/impl.py", line 180, in _do_get
    self._dec_overflow()
  File "/Users/chronos_386/PycharmProjects/FaceRecognizerServer/.venv/lib/python3.8/site-packages/sqlalchemy/util/langhelpers.py", line 146, in __exit__
    raise exc_value.with_traceback(exc_tb)
  File "/Users/chronos_386/PycharmProjects/FaceRecognizerServer/.venv/lib/python3.8/site-packages/sqlalchemy/pool/impl.py", line 177, in _do_get
    return self._create_connection()
  File "/Users/chronos_386/PycharmProjects/FaceRecognizerServer/.venv/lib/python3.8/site-packages/sqlalchemy/pool/base.py", line 390, in _create_connection
    return _ConnectionRecord(self)
  File "/Users/chronos_386/PycharmProjects/FaceRecognizerServer/.venv/lib/python3.8/site-packages/sqlalchemy/pool/base.py", line 674, in __init__
    self.__connect()
  File "/Users/chronos_386/PycharmProjects/FaceRecognizerServer/.venv/lib/python3.8/site-packages/sqlalchemy/pool/base.py", line 901, in __connect
    pool.logger.debug("Error on connect(): %s", e)
  File "/Users/chronos_386/PycharmProjects/FaceRecognizerServer/.venv/lib/python3.8/site-packages/sqlalchemy/util/langhelpers.py", line 146, in __exit__
    raise exc_value.with_traceback(exc_tb)
  File "/Users/chronos_386/PycharmProjects/FaceRecognizerServer/.venv/lib/python3.8/site-packages/sqlalchemy/pool/base.py", line 896, in __connect
    self.dbapi_connection = connection = pool._invoke_creator(self)
  File "/Users/chronos_386/PycharmProjects/FaceRecognizerServer/.venv/lib/python3.8/site-packages/sqlalchemy/engine/create.py", line 643, in connect
    return dialect.connect(*cargs, **cparams)
  File "/Users/chronos_386/PycharmProjects/FaceRecognizerServer/.venv/lib/python3.8/site-packages/sqlalchemy/engine/default.py", line 621, in connect
    return self.loaded_dbapi.connect(*cargs, **cparams)
  File "/Users/chronos_386/PycharmProjects/FaceRecognizerServer/.venv/lib/python3.8/site-packages/pg8000/__init__.py", line 111, in connect
    return Connection(
  File "/Users/chronos_386/PycharmProjects/FaceRecognizerServer/.venv/lib/python3.8/site-packages/pg8000/legacy.py", line 443, in __init__
    super().__init__(*args, **kwargs)
  File "/Users/chronos_386/PycharmProjects/FaceRecognizerServer/.venv/lib/python3.8/site-packages/pg8000/core.py", line 320, in __init__
    self.channel_binding, self._usock = _make_socket(
  File "/Users/chronos_386/PycharmProjects/FaceRecognizerServer/.venv/lib/python3.8/site-packages/pg8000/core.py", line 208, in _make_socket
    raise InterfaceError(
pg8000.exceptions.InterfaceError: Can't create a connection to host localhost and port 5432 (timeout is None and source_address is None).

The above exception was the direct cause of the following exception:

Traceback (most recent call last):
  File "/Users/chronos_386/PycharmProjects/FaceRecognizerServer/.venv/lib/python3.8/site-packages/flask/app.py", line 880, in full_dispatch_request
    rv = self.dispatch_request()
  File "/Users/chronos_386/PycharmProjects/FaceRecognizerServer/.venv/lib/python3.8/site-packages/flask/app.py", line 865, in dispatch_request
    return self.ensure_sync(self.view_functions[rule.endpoint])(**view_args)  # type: ignore[no-any-return]
  File "/Users/chronos_386/PycharmProjects/FaceRecognizerServer/.venv/lib/python3.8/site-packages/flask_restful/__init__.py", line 489, in wrapper
    resp = resource(*args, **kwargs)
  File "/Users/chronos_386/PycharmProjects/FaceRecognizerServer/.venv/lib/python3.8/site-packages/flask/views.py", line 110, in view
    return current_app.ensure_sync(self.dispatch_request)(**kwargs)  # type: ignore[no-any-return]
  File "/Users/chronos_386/PycharmProjects/FaceRecognizerServer/.venv/lib/python3.8/site-packages/flask_restful/__init__.py", line 604, in dispatch_request
    resp = meth(*args, **kwargs)
  File "/Users/chronos_386/PycharmProjects/FaceRecognizerServer/source_code/resources/schedule_device_res.py", line 12, in post
    student_id, json_model, code = self.api_connector.getStudentScheduleByPhoto(file)
  File "/Users/chronos_386/PycharmProjects/FaceRecognizerServer/source_code/api_connection/api_connector.py", line 674, in getStudentScheduleByPhoto
    student, code = self.__handleGetStudentByPhoto(photo)
  File "/Users/chronos_386/PycharmProjects/FaceRecognizerServer/source_code/api_connection/api_connector.py", line 89, in __handleGetStudentByPhoto
    emb: List[FaceEmbeddingsDB] = self.db_class.getAllEmbeddings()
  File "/Users/chronos_386/PycharmProjects/FaceRecognizerServer/source_code/db_connection/db_class.py", line 176, in getAllEmbeddings
    embeddings: List[Type[FaceEmbeddingsDB]] = self.session.query(FaceEmbeddingsDB).all()
  File "/Users/chronos_386/PycharmProjects/FaceRecognizerServer/.venv/lib/python3.8/site-packages/sqlalchemy/orm/query.py", line 2673, in all
    return self._iter().all()  # type: ignore
  File "/Users/chronos_386/PycharmProjects/FaceRecognizerServer/.venv/lib/python3.8/site-packages/sqlalchemy/orm/query.py", line 2827, in _iter
    result: Union[ScalarResult[_T], Result[_T]] = self.session.execute(
  File "/Users/chronos_386/PycharmProjects/FaceRecognizerServer/.venv/lib/python3.8/site-packages/sqlalchemy/orm/session.py", line 2362, in execute
    return self._execute_internal(
  File "/Users/chronos_386/PycharmProjects/FaceRecognizerServer/.venv/lib/python3.8/site-packages/sqlalchemy/orm/session.py", line 2237, in _execute_internal
    conn = self._connection_for_bind(bind)
  File "/Users/chronos_386/PycharmProjects/FaceRecognizerServer/.venv/lib/python3.8/site-packages/sqlalchemy/orm/session.py", line 2106, in _connection_for_bind
    return trans._connection_for_bind(engine, execution_options)
  File "<string>", line 2, in _connection_for_bind
  File "/Users/chronos_386/PycharmProjects/FaceRecognizerServer/.venv/lib/python3.8/site-packages/sqlalchemy/orm/state_changes.py", line 139, in _go
    ret_value = fn(self, *arg, **kw)
  File "/Users/chronos_386/PycharmProjects/FaceRecognizerServer/.venv/lib/python3.8/site-packages/sqlalchemy/orm/session.py", line 1189, in _connection_for_bind
    conn = bind.connect()
  File "/Users/chronos_386/PycharmProjects/FaceRecognizerServer/.venv/lib/python3.8/site-packages/sqlalchemy/engine/base.py", line 3278, in connect
    return self._connection_cls(self)
  File "/Users/chronos_386/PycharmProjects/FaceRecognizerServer/.venv/lib/python3.8/site-packages/sqlalchemy/engine/base.py", line 148, in __init__
    Connection._handle_dbapi_exception_noconnection(
  File "/Users/chronos_386/PycharmProjects/FaceRecognizerServer/.venv/lib/python3.8/site-packages/sqlalchemy/engine/base.py", line 2442, in _handle_dbapi_exception_noconnection
    raise sqlalchemy_exception.with_traceback(exc_info[2]) from e
  File "/Users/chronos_386/PycharmProjects/FaceRecognizerServer/.venv/lib/python3.8/site-packages/sqlalchemy/engine/base.py", line 146, in __init__
    self._dbapi_connection = engine.raw_connection()
  File "/Users/chronos_386/PycharmProjects/FaceRecognizerServer/.venv/lib/python3.8/site-packages/sqlalchemy/engine/base.py", line 3302, in raw_connection
    return self.pool.connect()
  File "/Users/chronos_386/PycharmProjects/FaceRecognizerServer/.venv/lib/python3.8/site-packages/sqlalchemy/pool/base.py", line 449, in connect
    return _ConnectionFairy._checkout(self)
  File "/Users/chronos_386/PycharmProjects/FaceRecognizerServer/.venv/lib/python3.8/site-packages/sqlalchemy/pool/base.py", line 1263, in _checkout
    fairy = _ConnectionRecord.checkout(pool)
  File "/Users/chronos_386/PycharmProjects/FaceRecognizerServer/.venv/lib/python3.8/site-packages/sqlalchemy/pool/base.py", line 712, in checkout
    rec = pool._do_get()
  File "/Users/chronos_386/PycharmProjects/FaceRecognizerServer/.venv/lib/python3.8/site-packages/sqlalchemy/pool/impl.py", line 180, in _do_get
    self._dec_overflow()
  File "/Users/chronos_386/PycharmProjects/FaceRecognizerServer/.venv/lib/python3.8/site-packages/sqlalchemy/util/langhelpers.py", line 146, in __exit__
    raise exc_value.with_traceback(exc_tb)
  File "/Users/chronos_386/PycharmProjects/FaceRecognizerServer/.venv/lib/python3.8/site-packages/sqlalchemy/pool/impl.py", line 177, in _do_get
    return self._create_connection()
  File "/Users/chronos_386/PycharmProjects/FaceRecognizerServer/.venv/lib/python3.8/site-packages/sqlalchemy/pool/base.py", line 390, in _create_connection
    return _ConnectionRecord(self)
  File "/Users/chronos_386/PycharmProjects/FaceRecognizerServer/.venv/lib/python3.8/site-packages/sqlalchemy/pool/base.py", line 674, in __init__
    self.__connect()
  File "/Users/chronos_386/PycharmProjects/FaceRecognizerServer/.venv/lib/python3.8/site-packages/sqlalchemy/pool/base.py", line 901, in __connect
    pool.logger.debug("Error on connect(): %s", e)
  File "/Users/chronos_386/PycharmProjects/FaceRecognizerServer/.venv/lib/python3.8/site-packages/sqlalchemy/util/langhelpers.py", line 146, in __exit__
    raise exc_value.with_traceback(exc_tb)
  File "/Users/chronos_386/PycharmProjects/FaceRecognizerServer/.venv/lib/python3.8/site-packages/sqlalchemy/pool/base.py", line 896, in __connect
    self.dbapi_connection = connection = pool._invoke_creator(self)
  File "/Users/chronos_386/PycharmProjects/FaceRecognizerServer/.venv/lib/python3.8/site-packages/sqlalchemy/engine/create.py", line 643, in connect
    return dialect.connect(*cargs, **cparams)
  File "/Users/chronos_386/PycharmProjects/FaceRecognizerServer/.venv/lib/python3.8/site-packages/sqlalchemy/engine/default.py", line 621, in connect
    return self.loaded_dbapi.connect(*cargs, **cparams)
  File "/Users/chronos_386/PycharmProjects/FaceRecognizerServer/.venv/lib/python3.8/site-packages/pg8000/__init__.py", line 111, in connect
    return Connection(
  File "/Users/chronos_386/PycharmProjects/FaceRecognizerServer/.venv/lib/python3.8/site-packages/pg8000/legacy.py", line 443, in __init__
    super().__init__(*args, **kwargs)
  File "/Users/chronos_386/PycharmProjects/FaceRecognizerServer/.venv/lib/python3.8/site-packages/pg8000/core.py", line 320, in __init__
    self.channel_binding, self._usock = _make_socket(
  File "/Users/chronos_386/PycharmProjects/FaceRecognizerServer/.venv/lib/python3.8/site-packages/pg8000/core.py", line 208, in _make_socket
    raise InterfaceError(
sqlalchemy.exc.InterfaceError: (pg8000.exceptions.InterfaceError) Can't create a connection to host localhost and port 5432 (timeout is None and source_address is None).
(Background on this error at: https://sqlalche.me/e/20/rvf5)


2025-01-26 17:21:51 - ERROR - Необработанная ошибка: (pg8000.exceptions.InterfaceError) Can't create a connection to host localhost and port 5432 (timeout is None and source_address is None).
(Background on this error at: https://sqlalche.me/e/20/rvf5)
Traceback (most recent call last):
  File "/Users/chronos_386/PycharmProjects/FaceRecognizerServer/.venv/lib/python3.8/site-packages/pg8000/core.py", line 206, in _make_socket
    sock = socket.create_connection((host, port), timeout, source_address)
  File "/Library/Frameworks/Python.framework/Versions/3.8/lib/python3.8/socket.py", line 808, in create_connection
    raise err
  File "/Library/Frameworks/Python.framework/Versions/3.8/lib/python3.8/socket.py", line 796, in create_connection
    sock.connect(sa)
ConnectionRefusedError: [Errno 61] Connection refused

The above exception was the direct cause of the following exception:

Traceback (most recent call last):
  File "/Users/chronos_386/PycharmProjects/FaceRecognizerServer/.venv/lib/python3.8/site-packages/sqlalchemy/engine/base.py", line 146, in __init__
    self._dbapi_connection = engine.raw_connection()
  File "/Users/chronos_386/PycharmProjects/FaceRecognizerServer/.venv/lib/python3.8/site-packages/sqlalchemy/engine/base.py", line 3302, in raw_connection
    return self.pool.connect()
  File "/Users/chronos_386/PycharmProjects/FaceRecognizerServer/.venv/lib/python3.8/site-packages/sqlalchemy/pool/base.py", line 449, in connect
    return _ConnectionFairy._checkout(self)
  File "/Users/chronos_386/PycharmProjects/FaceRecognizerServer/.venv/lib/python3.8/site-packages/sqlalchemy/pool/base.py", line 1263, in _checkout
    fairy = _ConnectionRecord.checkout(pool)
  File "/Users/chronos_386/PycharmProjects/FaceRecognizerServer/.venv/lib/python3.8/site-packages/sqlalchemy/pool/base.py", line 712, in checkout
    rec = pool._do_get()
  File "/Users/chronos_386/PycharmProjects/FaceRecognizerServer/.venv/lib/python3.8/site-packages/sqlalchemy/pool/impl.py", line 180, in _do_get
    self._dec_overflow()
  File "/Users/chronos_386/PycharmProjects/FaceRecognizerServer/.venv/lib/python3.8/site-packages/sqlalchemy/util/langhelpers.py", line 146, in __exit__
    raise exc_value.with_traceback(exc_tb)
  File "/Users/chronos_386/PycharmProjects/FaceRecognizerServer/.venv/lib/python3.8/site-packages/sqlalchemy/pool/impl.py", line 177, in _do_get
    return self._create_connection()
  File "/Users/chronos_386/PycharmProjects/FaceRecognizerServer/.venv/lib/python3.8/site-packages/sqlalchemy/pool/base.py", line 390, in _create_connection
    return _ConnectionRecord(self)
  File "/Users/chronos_386/PycharmProjects/FaceRecognizerServer/.venv/lib/python3.8/site-packages/sqlalchemy/pool/base.py", line 674, in __init__
    self.__connect()
  File "/Users/chronos_386/PycharmProjects/FaceRecognizerServer/.venv/lib/python3.8/site-packages/sqlalchemy/pool/base.py", line 901, in __connect
    pool.logger.debug("Error on connect(): %s", e)
  File "/Users/chronos_386/PycharmProjects/FaceRecognizerServer/.venv/lib/python3.8/site-packages/sqlalchemy/util/langhelpers.py", line 146, in __exit__
    raise exc_value.with_traceback(exc_tb)
  File "/Users/chronos_386/PycharmProjects/FaceRecognizerServer/.venv/lib/python3.8/site-packages/sqlalchemy/pool/base.py", line 896, in __connect
    self.dbapi_connection = connection = pool._invoke_creator(self)
  File "/Users/chronos_386/PycharmProjects/FaceRecognizerServer/.venv/lib/python3.8/site-packages/sqlalchemy/engine/create.py", line 643, in connect
    return dialect.connect(*cargs, **cparams)
  File "/Users/chronos_386/PycharmProjects/FaceRecognizerServer/.venv/lib/python3.8/site-packages/sqlalchemy/engine/default.py", line 621, in connect
    return self.loaded_dbapi.connect(*cargs, **cparams)
  File "/Users/chronos_386/PycharmProjects/FaceRecognizerServer/.venv/lib/python3.8/site-packages/pg8000/__init__.py", line 111, in connect
    return Connection(
  File "/Users/chronos_386/PycharmProjects/FaceRecognizerServer/.venv/lib/python3.8/site-packages/pg8000/legacy.py", line 443, in __init__
    super().__init__(*args, **kwargs)
  File "/Users/chronos_386/PycharmProjects/FaceRecognizerServer/.venv/lib/python3.8/site-packages/pg8000/core.py", line 320, in __init__
    self.channel_binding, self._usock = _make_socket(
  File "/Users/chronos_386/PycharmProjects/FaceRecognizerServer/.venv/lib/python3.8/site-packages/pg8000/core.py", line 208, in _make_socket
    raise InterfaceError(
pg8000.exceptions.InterfaceError: Can't create a connection to host localhost and port 5432 (timeout is None and source_address is None).

The above exception was the direct cause of the following exception:

Traceback (most recent call last):
  File "/Users/chronos_386/PycharmProjects/FaceRecognizerServer/.venv/lib/python3.8/site-packages/flask/app.py", line 880, in full_dispatch_request
    rv = self.dispatch_request()
  File "/Users/chronos_386/PycharmProjects/FaceRecognizerServer/.venv/lib/python3.8/site-packages/flask/app.py", line 865, in dispatch_request
    return self.ensure_sync(self.view_functions[rule.endpoint])(**view_args)  # type: ignore[no-any-return]
  File "/Users/chronos_386/PycharmProjects/FaceRecognizerServer/.venv/lib/python3.8/site-packages/flask_restful/__init__.py", line 489, in wrapper
    resp = resource(*args, **kwargs)
  File "/Users/chronos_386/PycharmProjects/FaceRecognizerServer/.venv/lib/python3.8/site-packages/flask/views.py", line 110, in view
    return current_app.ensure_sync(self.dispatch_request)(**kwargs)  # type: ignore[no-any-return]
  File "/Users/chronos_386/PycharmProjects/FaceRecognizerServer/.venv/lib/python3.8/site-packages/flask_restful/__init__.py", line 604, in dispatch_request
    resp = meth(*args, **kwargs)
  File "/Users/chronos_386/PycharmProjects/FaceRecognizerServer/source_code/resources/schedule_device_res.py", line 12, in post
    student_id, json_model, code = self.api_connector.getStudentScheduleByPhoto(file)
  File "/Users/chronos_386/PycharmProjects/FaceRecognizerServer/source_code/api_connection/api_connector.py", line 674, in getStudentScheduleByPhoto
    student, code = self.__handleGetStudentByPhoto(photo)
  File "/Users/chronos_386/PycharmProjects/FaceRecognizerServer/source_code/api_connection/api_connector.py", line 89, in __handleGetStudentByPhoto
    emb: List[FaceEmbeddingsDB] = self.db_class.getAllEmbeddings()
  File "/Users/chronos_386/PycharmProjects/FaceRecognizerServer/source_code/db_connection/db_class.py", line 176, in getAllEmbeddings
    embeddings: List[Type[FaceEmbeddingsDB]] = self.session.query(FaceEmbeddingsDB).all()
  File "/Users/chronos_386/PycharmProjects/FaceRecognizerServer/.venv/lib/python3.8/site-packages/sqlalchemy/orm/query.py", line 2673, in all
    return self._iter().all()  # type: ignore
  File "/Users/chronos_386/PycharmProjects/FaceRecognizerServer/.venv/lib/python3.8/site-packages/sqlalchemy/orm/query.py", line 2827, in _iter
    result: Union[ScalarResult[_T], Result[_T]] = self.session.execute(
  File "/Users/chronos_386/PycharmProjects/FaceRecognizerServer/.venv/lib/python3.8/site-packages/sqlalchemy/orm/session.py", line 2362, in execute
    return self._execute_internal(
  File "/Users/chronos_386/PycharmProjects/FaceRecognizerServer/.venv/lib/python3.8/site-packages/sqlalchemy/orm/session.py", line 2237, in _execute_internal
    conn = self._connection_for_bind(bind)
  File "/Users/chronos_386/PycharmProjects/FaceRecognizerServer/.venv/lib/python3.8/site-packages/sqlalchemy/orm/session.py", line 2106, in _connection_for_bind
    return trans._connection_for_bind(engine, execution_options)
  File "<string>", line 2, in _connection_for_bind
  File "/Users/chronos_386/PycharmProjects/FaceRecognizerServer/.venv/lib/python3.8/site-packages/sqlalchemy/orm/state_changes.py", line 139, in _go
    ret_value = fn(self, *arg, **kw)
  File "/Users/chronos_386/PycharmProjects/FaceRecognizerServer/.venv/lib/python3.8/site-packages/sqlalchemy/orm/session.py", line 1189, in _connection_for_bind
    conn = bind.connect()
  File "/Users/chronos_386/PycharmProjects/FaceRecognizerServer/.venv/lib/python3.8/site-packages/sqlalchemy/engine/base.py", line 3278, in connect
    return self._connection_cls(self)
  File "/Users/chronos_386/PycharmProjects/FaceRecognizerServer/.venv/lib/python3.8/site-packages/sqlalchemy/engine/base.py", line 148, in __init__
    Connection._handle_dbapi_exception_noconnection(
  File "/Users/chronos_386/PycharmProjects/FaceRecognizerServer/.venv/lib/python3.8/site-packages/sqlalchemy/engine/base.py", line 2442, in _handle_dbapi_exception_noconnection
    raise sqlalchemy_exception.with_traceback(exc_info[2]) from e
  File "/Users/chronos_386/PycharmProjects/FaceRecognizerServer/.venv/lib/python3.8/site-packages/sqlalchemy/engine/base.py", line 146, in __init__
    self._dbapi_connection = engine.raw_connection()
  File "/Users/chronos_386/PycharmProjects/FaceRecognizerServer/.venv/lib/python3.8/site-packages/sqlalchemy/engine/base.py", line 3302, in raw_connection
    return self.pool.connect()
  File "/Users/chronos_386/PycharmProjects/FaceRecognizerServer/.venv/lib/python3.8/site-packages/sqlalchemy/pool/base.py", line 449, in connect
    return _ConnectionFairy._checkout(self)
  File "/Users/chronos_386/PycharmProjects/FaceRecognizerServer/.venv/lib/python3.8/site-packages/sqlalchemy/pool/base.py", line 1263, in _checkout
    fairy = _ConnectionRecord.checkout(pool)
  File "/Users/chronos_386/PycharmProjects/FaceRecognizerServer/.venv/lib/python3.8/site-packages/sqlalchemy/pool/base.py", line 712, in checkout
    rec = pool._do_get()
  File "/Users/chronos_386/PycharmProjects/FaceRecognizerServer/.venv/lib/python3.8/site-packages/sqlalchemy/pool/impl.py", line 180, in _do_get
    self._dec_overflow()
  File "/Users/chronos_386/PycharmProjects/FaceRecognizerServer/.venv/lib/python3.8/site-packages/sqlalchemy/util/langhelpers.py", line 146, in __exit__
    raise exc_value.with_traceback(exc_tb)
  File "/Users/chronos_386/PycharmProjects/FaceRecognizerServer/.venv/lib/python3.8/site-packages/sqlalchemy/pool/impl.py", line 177, in _do_get
    return self._create_connection()
  File "/Users/chronos_386/PycharmProjects/FaceRecognizerServer/.venv/lib/python3.8/site-packages/sqlalchemy/pool/base.py", line 390, in _create_connection
    return _ConnectionRecord(self)
  File "/Users/chronos_386/PycharmProjects/FaceRecognizerServer/.venv/lib/python3.8/site-packages/sqlalchemy/pool/base.py", line 674, in __init__
    self.__connect()
  File "/Users/chronos_386/PycharmProjects/FaceRecognizerServer/.venv/lib/python3.8/site-packages/sqlalchemy/pool/base.py", line 901, in __connect
    pool.logger.debug("Error on connect(): %s", e)
  File "/Users/chronos_386/PycharmProjects/FaceRecognizerServer/.venv/lib/python3.8/site-packages/sqlalchemy/util/langhelpers.py", line 146, in __exit__
    raise exc_value.with_traceback(exc_tb)
  File "/Users/chronos_386/PycharmProjects/FaceRecognizerServer/.venv/lib/python3.8/site-packages/sqlalchemy/pool/base.py", line 896, in __connect
    self.dbapi_connection = connection = pool._invoke_creator(self)
  File "/Users/chronos_386/PycharmProjects/FaceRecognizerServer/.venv/lib/python3.8/site-packages/sqlalchemy/engine/create.py", line 643, in connect
    return dialect.connect(*cargs, **cparams)
  File "/Users/chronos_386/PycharmProjects/FaceRecognizerServer/.venv/lib/python3.8/site-packages/sqlalchemy/engine/default.py", line 621, in connect
    return self.loaded_dbapi.connect(*cargs, **cparams)
  File "/Users/chronos_386/PycharmProjects/FaceRecognizerServer/.venv/lib/python3.8/site-packages/pg8000/__init__.py", line 111, in connect
    return Connection(
  File "/Users/chronos_386/PycharmProjects/FaceRecognizerServer/.venv/lib/python3.8/site-packages/pg8000/legacy.py", line 443, in __init__
    super().__init__(*args, **kwargs)
  File "/Users/chronos_386/PycharmProjects/FaceRecognizerServer/.venv/lib/python3.8/site-packages/pg8000/core.py", line 320, in __init__
    self.channel_binding, self._usock = _make_socket(
  File "/Users/chronos_386/PycharmProjects/FaceRecognizerServer/.venv/lib/python3.8/site-packages/pg8000/core.py", line 208, in _make_socket
    raise InterfaceError(
sqlalchemy.exc.InterfaceError: (pg8000.exceptions.InterfaceError) Can't create a connection to host localhost and port 5432 (timeout is None and source_address is None).
(Background on this error at: https://sqlalche.me/e/20/rvf5)


2025-01-26 17:23:18 - ERROR - Необработанная ошибка: (pg8000.exceptions.InterfaceError) Can't create a connection to host localhost and port 5432 (timeout is None and source_address is None).
(Background on this error at: https://sqlalche.me/e/20/rvf5)
Traceback (most recent call last):
  File "/Users/chronos_386/PycharmProjects/FaceRecognizerServer/.venv/lib/python3.8/site-packages/pg8000/core.py", line 206, in _make_socket
    sock = socket.create_connection((host, port), timeout, source_address)
  File "/Library/Frameworks/Python.framework/Versions/3.8/lib/python3.8/socket.py", line 808, in create_connection
    raise err
  File "/Library/Frameworks/Python.framework/Versions/3.8/lib/python3.8/socket.py", line 796, in create_connection
    sock.connect(sa)
ConnectionRefusedError: [Errno 61] Connection refused

The above exception was the direct cause of the following exception:

Traceback (most recent call last):
  File "/Users/chronos_386/PycharmProjects/FaceRecognizerServer/.venv/lib/python3.8/site-packages/sqlalchemy/engine/base.py", line 146, in __init__
    self._dbapi_connection = engine.raw_connection()
  File "/Users/chronos_386/PycharmProjects/FaceRecognizerServer/.venv/lib/python3.8/site-packages/sqlalchemy/engine/base.py", line 3302, in raw_connection
    return self.pool.connect()
  File "/Users/chronos_386/PycharmProjects/FaceRecognizerServer/.venv/lib/python3.8/site-packages/sqlalchemy/pool/base.py", line 449, in connect
    return _ConnectionFairy._checkout(self)
  File "/Users/chronos_386/PycharmProjects/FaceRecognizerServer/.venv/lib/python3.8/site-packages/sqlalchemy/pool/base.py", line 1263, in _checkout
    fairy = _ConnectionRecord.checkout(pool)
  File "/Users/chronos_386/PycharmProjects/FaceRecognizerServer/.venv/lib/python3.8/site-packages/sqlalchemy/pool/base.py", line 712, in checkout
    rec = pool._do_get()
  File "/Users/chronos_386/PycharmProjects/FaceRecognizerServer/.venv/lib/python3.8/site-packages/sqlalchemy/pool/impl.py", line 180, in _do_get
    self._dec_overflow()
  File "/Users/chronos_386/PycharmProjects/FaceRecognizerServer/.venv/lib/python3.8/site-packages/sqlalchemy/util/langhelpers.py", line 146, in __exit__
    raise exc_value.with_traceback(exc_tb)
  File "/Users/chronos_386/PycharmProjects/FaceRecognizerServer/.venv/lib/python3.8/site-packages/sqlalchemy/pool/impl.py", line 177, in _do_get
    return self._create_connection()
  File "/Users/chronos_386/PycharmProjects/FaceRecognizerServer/.venv/lib/python3.8/site-packages/sqlalchemy/pool/base.py", line 390, in _create_connection
    return _ConnectionRecord(self)
  File "/Users/chronos_386/PycharmProjects/FaceRecognizerServer/.venv/lib/python3.8/site-packages/sqlalchemy/pool/base.py", line 674, in __init__
    self.__connect()
  File "/Users/chronos_386/PycharmProjects/FaceRecognizerServer/.venv/lib/python3.8/site-packages/sqlalchemy/pool/base.py", line 901, in __connect
    pool.logger.debug("Error on connect(): %s", e)
  File "/Users/chronos_386/PycharmProjects/FaceRecognizerServer/.venv/lib/python3.8/site-packages/sqlalchemy/util/langhelpers.py", line 146, in __exit__
    raise exc_value.with_traceback(exc_tb)
  File "/Users/chronos_386/PycharmProjects/FaceRecognizerServer/.venv/lib/python3.8/site-packages/sqlalchemy/pool/base.py", line 896, in __connect
    self.dbapi_connection = connection = pool._invoke_creator(self)
  File "/Users/chronos_386/PycharmProjects/FaceRecognizerServer/.venv/lib/python3.8/site-packages/sqlalchemy/engine/create.py", line 643, in connect
    return dialect.connect(*cargs, **cparams)
  File "/Users/chronos_386/PycharmProjects/FaceRecognizerServer/.venv/lib/python3.8/site-packages/sqlalchemy/engine/default.py", line 621, in connect
    return self.loaded_dbapi.connect(*cargs, **cparams)
  File "/Users/chronos_386/PycharmProjects/FaceRecognizerServer/.venv/lib/python3.8/site-packages/pg8000/__init__.py", line 111, in connect
    return Connection(
  File "/Users/chronos_386/PycharmProjects/FaceRecognizerServer/.venv/lib/python3.8/site-packages/pg8000/legacy.py", line 443, in __init__
    super().__init__(*args, **kwargs)
  File "/Users/chronos_386/PycharmProjects/FaceRecognizerServer/.venv/lib/python3.8/site-packages/pg8000/core.py", line 320, in __init__
    self.channel_binding, self._usock = _make_socket(
  File "/Users/chronos_386/PycharmProjects/FaceRecognizerServer/.venv/lib/python3.8/site-packages/pg8000/core.py", line 208, in _make_socket
    raise InterfaceError(
pg8000.exceptions.InterfaceError: Can't create a connection to host localhost and port 5432 (timeout is None and source_address is None).

The above exception was the direct cause of the following exception:

Traceback (most recent call last):
  File "/Users/chronos_386/PycharmProjects/FaceRecognizerServer/.venv/lib/python3.8/site-packages/flask/app.py", line 880, in full_dispatch_request
    rv = self.dispatch_request()
  File "/Users/chronos_386/PycharmProjects/FaceRecognizerServer/.venv/lib/python3.8/site-packages/flask/app.py", line 865, in dispatch_request
    return self.ensure_sync(self.view_functions[rule.endpoint])(**view_args)  # type: ignore[no-any-return]
  File "/Users/chronos_386/PycharmProjects/FaceRecognizerServer/.venv/lib/python3.8/site-packages/flask_restful/__init__.py", line 489, in wrapper
    resp = resource(*args, **kwargs)
  File "/Users/chronos_386/PycharmProjects/FaceRecognizerServer/.venv/lib/python3.8/site-packages/flask/views.py", line 110, in view
    return current_app.ensure_sync(self.dispatch_request)(**kwargs)  # type: ignore[no-any-return]
  File "/Users/chronos_386/PycharmProjects/FaceRecognizerServer/.venv/lib/python3.8/site-packages/flask_restful/__init__.py", line 604, in dispatch_request
    resp = meth(*args, **kwargs)
  File "/Users/chronos_386/PycharmProjects/FaceRecognizerServer/source_code/resources/schedule_device_res.py", line 12, in post
    student_id, json_model, code = self.api_connector.getStudentScheduleByPhoto(file)
  File "/Users/chronos_386/PycharmProjects/FaceRecognizerServer/source_code/api_connection/api_connector.py", line 674, in getStudentScheduleByPhoto
    student, code = self.__handleGetStudentByPhoto(photo)
  File "/Users/chronos_386/PycharmProjects/FaceRecognizerServer/source_code/api_connection/api_connector.py", line 89, in __handleGetStudentByPhoto
    emb: List[FaceEmbeddingsDB] = self.db_class.getAllEmbeddings()
  File "/Users/chronos_386/PycharmProjects/FaceRecognizerServer/source_code/db_connection/db_class.py", line 176, in getAllEmbeddings
    embeddings: List[Type[FaceEmbeddingsDB]] = self.session.query(FaceEmbeddingsDB).all()
  File "/Users/chronos_386/PycharmProjects/FaceRecognizerServer/.venv/lib/python3.8/site-packages/sqlalchemy/orm/query.py", line 2673, in all
    return self._iter().all()  # type: ignore
  File "/Users/chronos_386/PycharmProjects/FaceRecognizerServer/.venv/lib/python3.8/site-packages/sqlalchemy/orm/query.py", line 2827, in _iter
    result: Union[ScalarResult[_T], Result[_T]] = self.session.execute(
  File "/Users/chronos_386/PycharmProjects/FaceRecognizerServer/.venv/lib/python3.8/site-packages/sqlalchemy/orm/session.py", line 2362, in execute
    return self._execute_internal(
  File "/Users/chronos_386/PycharmProjects/FaceRecognizerServer/.venv/lib/python3.8/site-packages/sqlalchemy/orm/session.py", line 2237, in _execute_internal
    conn = self._connection_for_bind(bind)
  File "/Users/chronos_386/PycharmProjects/FaceRecognizerServer/.venv/lib/python3.8/site-packages/sqlalchemy/orm/session.py", line 2106, in _connection_for_bind
    return trans._connection_for_bind(engine, execution_options)
  File "<string>", line 2, in _connection_for_bind
  File "/Users/chronos_386/PycharmProjects/FaceRecognizerServer/.venv/lib/python3.8/site-packages/sqlalchemy/orm/state_changes.py", line 139, in _go
    ret_value = fn(self, *arg, **kw)
  File "/Users/chronos_386/PycharmProjects/FaceRecognizerServer/.venv/lib/python3.8/site-packages/sqlalchemy/orm/session.py", line 1189, in _connection_for_bind
    conn = bind.connect()
  File "/Users/chronos_386/PycharmProjects/FaceRecognizerServer/.venv/lib/python3.8/site-packages/sqlalchemy/engine/base.py", line 3278, in connect
    return self._connection_cls(self)
  File "/Users/chronos_386/PycharmProjects/FaceRecognizerServer/.venv/lib/python3.8/site-packages/sqlalchemy/engine/base.py", line 148, in __init__
    Connection._handle_dbapi_exception_noconnection(
  File "/Users/chronos_386/PycharmProjects/FaceRecognizerServer/.venv/lib/python3.8/site-packages/sqlalchemy/engine/base.py", line 2442, in _handle_dbapi_exception_noconnection
    raise sqlalchemy_exception.with_traceback(exc_info[2]) from e
  File "/Users/chronos_386/PycharmProjects/FaceRecognizerServer/.venv/lib/python3.8/site-packages/sqlalchemy/engine/base.py", line 146, in __init__
    self._dbapi_connection = engine.raw_connection()
  File "/Users/chronos_386/PycharmProjects/FaceRecognizerServer/.venv/lib/python3.8/site-packages/sqlalchemy/engine/base.py", line 3302, in raw_connection
    return self.pool.connect()
  File "/Users/chronos_386/PycharmProjects/FaceRecognizerServer/.venv/lib/python3.8/site-packages/sqlalchemy/pool/base.py", line 449, in connect
    return _ConnectionFairy._checkout(self)
  File "/Users/chronos_386/PycharmProjects/FaceRecognizerServer/.venv/lib/python3.8/site-packages/sqlalchemy/pool/base.py", line 1263, in _checkout
    fairy = _ConnectionRecord.checkout(pool)
  File "/Users/chronos_386/PycharmProjects/FaceRecognizerServer/.venv/lib/python3.8/site-packages/sqlalchemy/pool/base.py", line 712, in checkout
    rec = pool._do_get()
  File "/Users/chronos_386/PycharmProjects/FaceRecognizerServer/.venv/lib/python3.8/site-packages/sqlalchemy/pool/impl.py", line 180, in _do_get
    self._dec_overflow()
  File "/Users/chronos_386/PycharmProjects/FaceRecognizerServer/.venv/lib/python3.8/site-packages/sqlalchemy/util/langhelpers.py", line 146, in __exit__
    raise exc_value.with_traceback(exc_tb)
  File "/Users/chronos_386/PycharmProjects/FaceRecognizerServer/.venv/lib/python3.8/site-packages/sqlalchemy/pool/impl.py", line 177, in _do_get
    return self._create_connection()
  File "/Users/chronos_386/PycharmProjects/FaceRecognizerServer/.venv/lib/python3.8/site-packages/sqlalchemy/pool/base.py", line 390, in _create_connection
    return _ConnectionRecord(self)
  File "/Users/chronos_386/PycharmProjects/FaceRecognizerServer/.venv/lib/python3.8/site-packages/sqlalchemy/pool/base.py", line 674, in __init__
    self.__connect()
  File "/Users/chronos_386/PycharmProjects/FaceRecognizerServer/.venv/lib/python3.8/site-packages/sqlalchemy/pool/base.py", line 901, in __connect
    pool.logger.debug("Error on connect(): %s", e)
  File "/Users/chronos_386/PycharmProjects/FaceRecognizerServer/.venv/lib/python3.8/site-packages/sqlalchemy/util/langhelpers.py", line 146, in __exit__
    raise exc_value.with_traceback(exc_tb)
  File "/Users/chronos_386/PycharmProjects/FaceRecognizerServer/.venv/lib/python3.8/site-packages/sqlalchemy/pool/base.py", line 896, in __connect
    self.dbapi_connection = connection = pool._invoke_creator(self)
  File "/Users/chronos_386/PycharmProjects/FaceRecognizerServer/.venv/lib/python3.8/site-packages/sqlalchemy/engine/create.py", line 643, in connect
    return dialect.connect(*cargs, **cparams)
  File "/Users/chronos_386/PycharmProjects/FaceRecognizerServer/.venv/lib/python3.8/site-packages/sqlalchemy/engine/default.py", line 621, in connect
    return self.loaded_dbapi.connect(*cargs, **cparams)
  File "/Users/chronos_386/PycharmProjects/FaceRecognizerServer/.venv/lib/python3.8/site-packages/pg8000/__init__.py", line 111, in connect
    return Connection(
  File "/Users/chronos_386/PycharmProjects/FaceRecognizerServer/.venv/lib/python3.8/site-packages/pg8000/legacy.py", line 443, in __init__
    super().__init__(*args, **kwargs)
  File "/Users/chronos_386/PycharmProjects/FaceRecognizerServer/.venv/lib/python3.8/site-packages/pg8000/core.py", line 320, in __init__
    self.channel_binding, self._usock = _make_socket(
  File "/Users/chronos_386/PycharmProjects/FaceRecognizerServer/.venv/lib/python3.8/site-packages/pg8000/core.py", line 208, in _make_socket
    raise InterfaceError(
sqlalchemy.exc.InterfaceError: (pg8000.exceptions.InterfaceError) Can't create a connection to host localhost and port 5432 (timeout is None and source_address is None).
(Background on this error at: https://sqlalche.me/e/20/rvf5)


2025-01-26 17:23:18 - ERROR - Необработанная ошибка: (pg8000.exceptions.InterfaceError) Can't create a connection to host localhost and port 5432 (timeout is None and source_address is None).
(Background on this error at: https://sqlalche.me/e/20/rvf5)
Traceback (most recent call last):
  File "/Users/chronos_386/PycharmProjects/FaceRecognizerServer/.venv/lib/python3.8/site-packages/pg8000/core.py", line 206, in _make_socket
    sock = socket.create_connection((host, port), timeout, source_address)
  File "/Library/Frameworks/Python.framework/Versions/3.8/lib/python3.8/socket.py", line 808, in create_connection
    raise err
  File "/Library/Frameworks/Python.framework/Versions/3.8/lib/python3.8/socket.py", line 796, in create_connection
    sock.connect(sa)
ConnectionRefusedError: [Errno 61] Connection refused

The above exception was the direct cause of the following exception:

Traceback (most recent call last):
  File "/Users/chronos_386/PycharmProjects/FaceRecognizerServer/.venv/lib/python3.8/site-packages/sqlalchemy/engine/base.py", line 146, in __init__
    self._dbapi_connection = engine.raw_connection()
  File "/Users/chronos_386/PycharmProjects/FaceRecognizerServer/.venv/lib/python3.8/site-packages/sqlalchemy/engine/base.py", line 3302, in raw_connection
    return self.pool.connect()
  File "/Users/chronos_386/PycharmProjects/FaceRecognizerServer/.venv/lib/python3.8/site-packages/sqlalchemy/pool/base.py", line 449, in connect
    return _ConnectionFairy._checkout(self)
  File "/Users/chronos_386/PycharmProjects/FaceRecognizerServer/.venv/lib/python3.8/site-packages/sqlalchemy/pool/base.py", line 1263, in _checkout
    fairy = _ConnectionRecord.checkout(pool)
  File "/Users/chronos_386/PycharmProjects/FaceRecognizerServer/.venv/lib/python3.8/site-packages/sqlalchemy/pool/base.py", line 712, in checkout
    rec = pool._do_get()
  File "/Users/chronos_386/PycharmProjects/FaceRecognizerServer/.venv/lib/python3.8/site-packages/sqlalchemy/pool/impl.py", line 180, in _do_get
    self._dec_overflow()
  File "/Users/chronos_386/PycharmProjects/FaceRecognizerServer/.venv/lib/python3.8/site-packages/sqlalchemy/util/langhelpers.py", line 146, in __exit__
    raise exc_value.with_traceback(exc_tb)
  File "/Users/chronos_386/PycharmProjects/FaceRecognizerServer/.venv/lib/python3.8/site-packages/sqlalchemy/pool/impl.py", line 177, in _do_get
    return self._create_connection()
  File "/Users/chronos_386/PycharmProjects/FaceRecognizerServer/.venv/lib/python3.8/site-packages/sqlalchemy/pool/base.py", line 390, in _create_connection
    return _ConnectionRecord(self)
  File "/Users/chronos_386/PycharmProjects/FaceRecognizerServer/.venv/lib/python3.8/site-packages/sqlalchemy/pool/base.py", line 674, in __init__
    self.__connect()
  File "/Users/chronos_386/PycharmProjects/FaceRecognizerServer/.venv/lib/python3.8/site-packages/sqlalchemy/pool/base.py", line 901, in __connect
    pool.logger.debug("Error on connect(): %s", e)
  File "/Users/chronos_386/PycharmProjects/FaceRecognizerServer/.venv/lib/python3.8/site-packages/sqlalchemy/util/langhelpers.py", line 146, in __exit__
    raise exc_value.with_traceback(exc_tb)
  File "/Users/chronos_386/PycharmProjects/FaceRecognizerServer/.venv/lib/python3.8/site-packages/sqlalchemy/pool/base.py", line 896, in __connect
    self.dbapi_connection = connection = pool._invoke_creator(self)
  File "/Users/chronos_386/PycharmProjects/FaceRecognizerServer/.venv/lib/python3.8/site-packages/sqlalchemy/engine/create.py", line 643, in connect
    return dialect.connect(*cargs, **cparams)
  File "/Users/chronos_386/PycharmProjects/FaceRecognizerServer/.venv/lib/python3.8/site-packages/sqlalchemy/engine/default.py", line 621, in connect
    return self.loaded_dbapi.connect(*cargs, **cparams)
  File "/Users/chronos_386/PycharmProjects/FaceRecognizerServer/.venv/lib/python3.8/site-packages/pg8000/__init__.py", line 111, in connect
    return Connection(
  File "/Users/chronos_386/PycharmProjects/FaceRecognizerServer/.venv/lib/python3.8/site-packages/pg8000/legacy.py", line 443, in __init__
    super().__init__(*args, **kwargs)
  File "/Users/chronos_386/PycharmProjects/FaceRecognizerServer/.venv/lib/python3.8/site-packages/pg8000/core.py", line 320, in __init__
    self.channel_binding, self._usock = _make_socket(
  File "/Users/chronos_386/PycharmProjects/FaceRecognizerServer/.venv/lib/python3.8/site-packages/pg8000/core.py", line 208, in _make_socket
    raise InterfaceError(
pg8000.exceptions.InterfaceError: Can't create a connection to host localhost and port 5432 (timeout is None and source_address is None).

The above exception was the direct cause of the following exception:

Traceback (most recent call last):
  File "/Users/chronos_386/PycharmProjects/FaceRecognizerServer/.venv/lib/python3.8/site-packages/flask/app.py", line 880, in full_dispatch_request
    rv = self.dispatch_request()
  File "/Users/chronos_386/PycharmProjects/FaceRecognizerServer/.venv/lib/python3.8/site-packages/flask/app.py", line 865, in dispatch_request
    return self.ensure_sync(self.view_functions[rule.endpoint])(**view_args)  # type: ignore[no-any-return]
  File "/Users/chronos_386/PycharmProjects/FaceRecognizerServer/.venv/lib/python3.8/site-packages/flask_restful/__init__.py", line 489, in wrapper
    resp = resource(*args, **kwargs)
  File "/Users/chronos_386/PycharmProjects/FaceRecognizerServer/.venv/lib/python3.8/site-packages/flask/views.py", line 110, in view
    return current_app.ensure_sync(self.dispatch_request)(**kwargs)  # type: ignore[no-any-return]
  File "/Users/chronos_386/PycharmProjects/FaceRecognizerServer/.venv/lib/python3.8/site-packages/flask_restful/__init__.py", line 604, in dispatch_request
    resp = meth(*args, **kwargs)
  File "/Users/chronos_386/PycharmProjects/FaceRecognizerServer/source_code/resources/schedule_device_res.py", line 12, in post
    student_id, json_model, code = self.api_connector.getStudentScheduleByPhoto(file)
  File "/Users/chronos_386/PycharmProjects/FaceRecognizerServer/source_code/api_connection/api_connector.py", line 674, in getStudentScheduleByPhoto
    student, code = self.__handleGetStudentByPhoto(photo)
  File "/Users/chronos_386/PycharmProjects/FaceRecognizerServer/source_code/api_connection/api_connector.py", line 89, in __handleGetStudentByPhoto
    emb: List[FaceEmbeddingsDB] = self.db_class.getAllEmbeddings()
  File "/Users/chronos_386/PycharmProjects/FaceRecognizerServer/source_code/db_connection/db_class.py", line 176, in getAllEmbeddings
    embeddings: List[Type[FaceEmbeddingsDB]] = self.session.query(FaceEmbeddingsDB).all()
  File "/Users/chronos_386/PycharmProjects/FaceRecognizerServer/.venv/lib/python3.8/site-packages/sqlalchemy/orm/query.py", line 2673, in all
    return self._iter().all()  # type: ignore
  File "/Users/chronos_386/PycharmProjects/FaceRecognizerServer/.venv/lib/python3.8/site-packages/sqlalchemy/orm/query.py", line 2827, in _iter
    result: Union[ScalarResult[_T], Result[_T]] = self.session.execute(
  File "/Users/chronos_386/PycharmProjects/FaceRecognizerServer/.venv/lib/python3.8/site-packages/sqlalchemy/orm/session.py", line 2362, in execute
    return self._execute_internal(
  File "/Users/chronos_386/PycharmProjects/FaceRecognizerServer/.venv/lib/python3.8/site-packages/sqlalchemy/orm/session.py", line 2237, in _execute_internal
    conn = self._connection_for_bind(bind)
  File "/Users/chronos_386/PycharmProjects/FaceRecognizerServer/.venv/lib/python3.8/site-packages/sqlalchemy/orm/session.py", line 2106, in _connection_for_bind
    return trans._connection_for_bind(engine, execution_options)
  File "<string>", line 2, in _connection_for_bind
  File "/Users/chronos_386/PycharmProjects/FaceRecognizerServer/.venv/lib/python3.8/site-packages/sqlalchemy/orm/state_changes.py", line 139, in _go
    ret_value = fn(self, *arg, **kw)
  File "/Users/chronos_386/PycharmProjects/FaceRecognizerServer/.venv/lib/python3.8/site-packages/sqlalchemy/orm/session.py", line 1189, in _connection_for_bind
    conn = bind.connect()
  File "/Users/chronos_386/PycharmProjects/FaceRecognizerServer/.venv/lib/python3.8/site-packages/sqlalchemy/engine/base.py", line 3278, in connect
    return self._connection_cls(self)
  File "/Users/chronos_386/PycharmProjects/FaceRecognizerServer/.venv/lib/python3.8/site-packages/sqlalchemy/engine/base.py", line 148, in __init__
    Connection._handle_dbapi_exception_noconnection(
  File "/Users/chronos_386/PycharmProjects/FaceRecognizerServer/.venv/lib/python3.8/site-packages/sqlalchemy/engine/base.py", line 2442, in _handle_dbapi_exception_noconnection
    raise sqlalchemy_exception.with_traceback(exc_info[2]) from e
  File "/Users/chronos_386/PycharmProjects/FaceRecognizerServer/.venv/lib/python3.8/site-packages/sqlalchemy/engine/base.py", line 146, in __init__
    self._dbapi_connection = engine.raw_connection()
  File "/Users/chronos_386/PycharmProjects/FaceRecognizerServer/.venv/lib/python3.8/site-packages/sqlalchemy/engine/base.py", line 3302, in raw_connection
    return self.pool.connect()
  File "/Users/chronos_386/PycharmProjects/FaceRecognizerServer/.venv/lib/python3.8/site-packages/sqlalchemy/pool/base.py", line 449, in connect
    return _ConnectionFairy._checkout(self)
  File "/Users/chronos_386/PycharmProjects/FaceRecognizerServer/.venv/lib/python3.8/site-packages/sqlalchemy/pool/base.py", line 1263, in _checkout
    fairy = _ConnectionRecord.checkout(pool)
  File "/Users/chronos_386/PycharmProjects/FaceRecognizerServer/.venv/lib/python3.8/site-packages/sqlalchemy/pool/base.py", line 712, in checkout
    rec = pool._do_get()
  File "/Users/chronos_386/PycharmProjects/FaceRecognizerServer/.venv/lib/python3.8/site-packages/sqlalchemy/pool/impl.py", line 180, in _do_get
    self._dec_overflow()
  File "/Users/chronos_386/PycharmProjects/FaceRecognizerServer/.venv/lib/python3.8/site-packages/sqlalchemy/util/langhelpers.py", line 146, in __exit__
    raise exc_value.with_traceback(exc_tb)
  File "/Users/chronos_386/PycharmProjects/FaceRecognizerServer/.venv/lib/python3.8/site-packages/sqlalchemy/pool/impl.py", line 177, in _do_get
    return self._create_connection()
  File "/Users/chronos_386/PycharmProjects/FaceRecognizerServer/.venv/lib/python3.8/site-packages/sqlalchemy/pool/base.py", line 390, in _create_connection
    return _ConnectionRecord(self)
  File "/Users/chronos_386/PycharmProjects/FaceRecognizerServer/.venv/lib/python3.8/site-packages/sqlalchemy/pool/base.py", line 674, in __init__
    self.__connect()
  File "/Users/chronos_386/PycharmProjects/FaceRecognizerServer/.venv/lib/python3.8/site-packages/sqlalchemy/pool/base.py", line 901, in __connect
    pool.logger.debug("Error on connect(): %s", e)
  File "/Users/chronos_386/PycharmProjects/FaceRecognizerServer/.venv/lib/python3.8/site-packages/sqlalchemy/util/langhelpers.py", line 146, in __exit__
    raise exc_value.with_traceback(exc_tb)
  File "/Users/chronos_386/PycharmProjects/FaceRecognizerServer/.venv/lib/python3.8/site-packages/sqlalchemy/pool/base.py", line 896, in __connect
    self.dbapi_connection = connection = pool._invoke_creator(self)
  File "/Users/chronos_386/PycharmProjects/FaceRecognizerServer/.venv/lib/python3.8/site-packages/sqlalchemy/engine/create.py", line 643, in connect
    return dialect.connect(*cargs, **cparams)
  File "/Users/chronos_386/PycharmProjects/FaceRecognizerServer/.venv/lib/python3.8/site-packages/sqlalchemy/engine/default.py", line 621, in connect
    return self.loaded_dbapi.connect(*cargs, **cparams)
  File "/Users/chronos_386/PycharmProjects/FaceRecognizerServer/.venv/lib/python3.8/site-packages/pg8000/__init__.py", line 111, in connect
    return Connection(
  File "/Users/chronos_386/PycharmProjects/FaceRecognizerServer/.venv/lib/python3.8/site-packages/pg8000/legacy.py", line 443, in __init__
    super().__init__(*args, **kwargs)
  File "/Users/chronos_386/PycharmProjects/FaceRecognizerServer/.venv/lib/python3.8/site-packages/pg8000/core.py", line 320, in __init__
    self.channel_binding, self._usock = _make_socket(
  File "/Users/chronos_386/PycharmProjects/FaceRecognizerServer/.venv/lib/python3.8/site-packages/pg8000/core.py", line 208, in _make_socket
    raise InterfaceError(
sqlalchemy.exc.InterfaceError: (pg8000.exceptions.InterfaceError) Can't create a connection to host localhost and port 5432 (timeout is None and source_address is None).
(Background on this error at: https://sqlalche.me/e/20/rvf5)


2025-01-26 17:23:18 - ERROR - Необработанная ошибка: (pg8000.exceptions.InterfaceError) Can't create a connection to host localhost and port 5432 (timeout is None and source_address is None).
(Background on this error at: https://sqlalche.me/e/20/rvf5)
Traceback (most recent call last):
  File "/Users/chronos_386/PycharmProjects/FaceRecognizerServer/.venv/lib/python3.8/site-packages/pg8000/core.py", line 206, in _make_socket
    sock = socket.create_connection((host, port), timeout, source_address)
  File "/Library/Frameworks/Python.framework/Versions/3.8/lib/python3.8/socket.py", line 808, in create_connection
    raise err
  File "/Library/Frameworks/Python.framework/Versions/3.8/lib/python3.8/socket.py", line 796, in create_connection
    sock.connect(sa)
ConnectionRefusedError: [Errno 61] Connection refused

The above exception was the direct cause of the following exception:

Traceback (most recent call last):
  File "/Users/chronos_386/PycharmProjects/FaceRecognizerServer/.venv/lib/python3.8/site-packages/sqlalchemy/engine/base.py", line 146, in __init__
    self._dbapi_connection = engine.raw_connection()
  File "/Users/chronos_386/PycharmProjects/FaceRecognizerServer/.venv/lib/python3.8/site-packages/sqlalchemy/engine/base.py", line 3302, in raw_connection
    return self.pool.connect()
  File "/Users/chronos_386/PycharmProjects/FaceRecognizerServer/.venv/lib/python3.8/site-packages/sqlalchemy/pool/base.py", line 449, in connect
    return _ConnectionFairy._checkout(self)
  File "/Users/chronos_386/PycharmProjects/FaceRecognizerServer/.venv/lib/python3.8/site-packages/sqlalchemy/pool/base.py", line 1263, in _checkout
    fairy = _ConnectionRecord.checkout(pool)
  File "/Users/chronos_386/PycharmProjects/FaceRecognizerServer/.venv/lib/python3.8/site-packages/sqlalchemy/pool/base.py", line 712, in checkout
    rec = pool._do_get()
  File "/Users/chronos_386/PycharmProjects/FaceRecognizerServer/.venv/lib/python3.8/site-packages/sqlalchemy/pool/impl.py", line 180, in _do_get
    self._dec_overflow()
  File "/Users/chronos_386/PycharmProjects/FaceRecognizerServer/.venv/lib/python3.8/site-packages/sqlalchemy/util/langhelpers.py", line 146, in __exit__
    raise exc_value.with_traceback(exc_tb)
  File "/Users/chronos_386/PycharmProjects/FaceRecognizerServer/.venv/lib/python3.8/site-packages/sqlalchemy/pool/impl.py", line 177, in _do_get
    return self._create_connection()
  File "/Users/chronos_386/PycharmProjects/FaceRecognizerServer/.venv/lib/python3.8/site-packages/sqlalchemy/pool/base.py", line 390, in _create_connection
    return _ConnectionRecord(self)
  File "/Users/chronos_386/PycharmProjects/FaceRecognizerServer/.venv/lib/python3.8/site-packages/sqlalchemy/pool/base.py", line 674, in __init__
    self.__connect()
  File "/Users/chronos_386/PycharmProjects/FaceRecognizerServer/.venv/lib/python3.8/site-packages/sqlalchemy/pool/base.py", line 901, in __connect
    pool.logger.debug("Error on connect(): %s", e)
  File "/Users/chronos_386/PycharmProjects/FaceRecognizerServer/.venv/lib/python3.8/site-packages/sqlalchemy/util/langhelpers.py", line 146, in __exit__
    raise exc_value.with_traceback(exc_tb)
  File "/Users/chronos_386/PycharmProjects/FaceRecognizerServer/.venv/lib/python3.8/site-packages/sqlalchemy/pool/base.py", line 896, in __connect
    self.dbapi_connection = connection = pool._invoke_creator(self)
  File "/Users/chronos_386/PycharmProjects/FaceRecognizerServer/.venv/lib/python3.8/site-packages/sqlalchemy/engine/create.py", line 643, in connect
    return dialect.connect(*cargs, **cparams)
  File "/Users/chronos_386/PycharmProjects/FaceRecognizerServer/.venv/lib/python3.8/site-packages/sqlalchemy/engine/default.py", line 621, in connect
    return self.loaded_dbapi.connect(*cargs, **cparams)
  File "/Users/chronos_386/PycharmProjects/FaceRecognizerServer/.venv/lib/python3.8/site-packages/pg8000/__init__.py", line 111, in connect
    return Connection(
  File "/Users/chronos_386/PycharmProjects/FaceRecognizerServer/.venv/lib/python3.8/site-packages/pg8000/legacy.py", line 443, in __init__
    super().__init__(*args, **kwargs)
  File "/Users/chronos_386/PycharmProjects/FaceRecognizerServer/.venv/lib/python3.8/site-packages/pg8000/core.py", line 320, in __init__
    self.channel_binding, self._usock = _make_socket(
  File "/Users/chronos_386/PycharmProjects/FaceRecognizerServer/.venv/lib/python3.8/site-packages/pg8000/core.py", line 208, in _make_socket
    raise InterfaceError(
pg8000.exceptions.InterfaceError: Can't create a connection to host localhost and port 5432 (timeout is None and source_address is None).

The above exception was the direct cause of the following exception:

Traceback (most recent call last):
  File "/Users/chronos_386/PycharmProjects/FaceRecognizerServer/.venv/lib/python3.8/site-packages/flask/app.py", line 880, in full_dispatch_request
    rv = self.dispatch_request()
  File "/Users/chronos_386/PycharmProjects/FaceRecognizerServer/.venv/lib/python3.8/site-packages/flask/app.py", line 865, in dispatch_request
    return self.ensure_sync(self.view_functions[rule.endpoint])(**view_args)  # type: ignore[no-any-return]
  File "/Users/chronos_386/PycharmProjects/FaceRecognizerServer/.venv/lib/python3.8/site-packages/flask_restful/__init__.py", line 489, in wrapper
    resp = resource(*args, **kwargs)
  File "/Users/chronos_386/PycharmProjects/FaceRecognizerServer/.venv/lib/python3.8/site-packages/flask/views.py", line 110, in view
    return current_app.ensure_sync(self.dispatch_request)(**kwargs)  # type: ignore[no-any-return]
  File "/Users/chronos_386/PycharmProjects/FaceRecognizerServer/.venv/lib/python3.8/site-packages/flask_restful/__init__.py", line 604, in dispatch_request
    resp = meth(*args, **kwargs)
  File "/Users/chronos_386/PycharmProjects/FaceRecognizerServer/source_code/resources/schedule_device_res.py", line 12, in post
    student_id, json_model, code = self.api_connector.getStudentScheduleByPhoto(file)
  File "/Users/chronos_386/PycharmProjects/FaceRecognizerServer/source_code/api_connection/api_connector.py", line 674, in getStudentScheduleByPhoto
    student, code = self.__handleGetStudentByPhoto(photo)
  File "/Users/chronos_386/PycharmProjects/FaceRecognizerServer/source_code/api_connection/api_connector.py", line 89, in __handleGetStudentByPhoto
    emb: List[FaceEmbeddingsDB] = self.db_class.getAllEmbeddings()
  File "/Users/chronos_386/PycharmProjects/FaceRecognizerServer/source_code/db_connection/db_class.py", line 176, in getAllEmbeddings
    embeddings: List[Type[FaceEmbeddingsDB]] = self.session.query(FaceEmbeddingsDB).all()
  File "/Users/chronos_386/PycharmProjects/FaceRecognizerServer/.venv/lib/python3.8/site-packages/sqlalchemy/orm/query.py", line 2673, in all
    return self._iter().all()  # type: ignore
  File "/Users/chronos_386/PycharmProjects/FaceRecognizerServer/.venv/lib/python3.8/site-packages/sqlalchemy/orm/query.py", line 2827, in _iter
    result: Union[ScalarResult[_T], Result[_T]] = self.session.execute(
  File "/Users/chronos_386/PycharmProjects/FaceRecognizerServer/.venv/lib/python3.8/site-packages/sqlalchemy/orm/session.py", line 2362, in execute
    return self._execute_internal(
  File "/Users/chronos_386/PycharmProjects/FaceRecognizerServer/.venv/lib/python3.8/site-packages/sqlalchemy/orm/session.py", line 2237, in _execute_internal
    conn = self._connection_for_bind(bind)
  File "/Users/chronos_386/PycharmProjects/FaceRecognizerServer/.venv/lib/python3.8/site-packages/sqlalchemy/orm/session.py", line 2106, in _connection_for_bind
    return trans._connection_for_bind(engine, execution_options)
  File "<string>", line 2, in _connection_for_bind
  File "/Users/chronos_386/PycharmProjects/FaceRecognizerServer/.venv/lib/python3.8/site-packages/sqlalchemy/orm/state_changes.py", line 139, in _go
    ret_value = fn(self, *arg, **kw)
  File "/Users/chronos_386/PycharmProjects/FaceRecognizerServer/.venv/lib/python3.8/site-packages/sqlalchemy/orm/session.py", line 1189, in _connection_for_bind
    conn = bind.connect()
  File "/Users/chronos_386/PycharmProjects/FaceRecognizerServer/.venv/lib/python3.8/site-packages/sqlalchemy/engine/base.py", line 3278, in connect
    return self._connection_cls(self)
  File "/Users/chronos_386/PycharmProjects/FaceRecognizerServer/.venv/lib/python3.8/site-packages/sqlalchemy/engine/base.py", line 148, in __init__
    Connection._handle_dbapi_exception_noconnection(
  File "/Users/chronos_386/PycharmProjects/FaceRecognizerServer/.venv/lib/python3.8/site-packages/sqlalchemy/engine/base.py", line 2442, in _handle_dbapi_exception_noconnection
    raise sqlalchemy_exception.with_traceback(exc_info[2]) from e
  File "/Users/chronos_386/PycharmProjects/FaceRecognizerServer/.venv/lib/python3.8/site-packages/sqlalchemy/engine/base.py", line 146, in __init__
    self._dbapi_connection = engine.raw_connection()
  File "/Users/chronos_386/PycharmProjects/FaceRecognizerServer/.venv/lib/python3.8/site-packages/sqlalchemy/engine/base.py", line 3302, in raw_connection
    return self.pool.connect()
  File "/Users/chronos_386/PycharmProjects/FaceRecognizerServer/.venv/lib/python3.8/site-packages/sqlalchemy/pool/base.py", line 449, in connect
    return _ConnectionFairy._checkout(self)
  File "/Users/chronos_386/PycharmProjects/FaceRecognizerServer/.venv/lib/python3.8/site-packages/sqlalchemy/pool/base.py", line 1263, in _checkout
    fairy = _ConnectionRecord.checkout(pool)
  File "/Users/chronos_386/PycharmProjects/FaceRecognizerServer/.venv/lib/python3.8/site-packages/sqlalchemy/pool/base.py", line 712, in checkout
    rec = pool._do_get()
  File "/Users/chronos_386/PycharmProjects/FaceRecognizerServer/.venv/lib/python3.8/site-packages/sqlalchemy/pool/impl.py", line 180, in _do_get
    self._dec_overflow()
  File "/Users/chronos_386/PycharmProjects/FaceRecognizerServer/.venv/lib/python3.8/site-packages/sqlalchemy/util/langhelpers.py", line 146, in __exit__
    raise exc_value.with_traceback(exc_tb)
  File "/Users/chronos_386/PycharmProjects/FaceRecognizerServer/.venv/lib/python3.8/site-packages/sqlalchemy/pool/impl.py", line 177, in _do_get
    return self._create_connection()
  File "/Users/chronos_386/PycharmProjects/FaceRecognizerServer/.venv/lib/python3.8/site-packages/sqlalchemy/pool/base.py", line 390, in _create_connection
    return _ConnectionRecord(self)
  File "/Users/chronos_386/PycharmProjects/FaceRecognizerServer/.venv/lib/python3.8/site-packages/sqlalchemy/pool/base.py", line 674, in __init__
    self.__connect()
  File "/Users/chronos_386/PycharmProjects/FaceRecognizerServer/.venv/lib/python3.8/site-packages/sqlalchemy/pool/base.py", line 901, in __connect
    pool.logger.debug("Error on connect(): %s", e)
  File "/Users/chronos_386/PycharmProjects/FaceRecognizerServer/.venv/lib/python3.8/site-packages/sqlalchemy/util/langhelpers.py", line 146, in __exit__
    raise exc_value.with_traceback(exc_tb)
  File "/Users/chronos_386/PycharmProjects/FaceRecognizerServer/.venv/lib/python3.8/site-packages/sqlalchemy/pool/base.py", line 896, in __connect
    self.dbapi_connection = connection = pool._invoke_creator(self)
  File "/Users/chronos_386/PycharmProjects/FaceRecognizerServer/.venv/lib/python3.8/site-packages/sqlalchemy/engine/create.py", line 643, in connect
    return dialect.connect(*cargs, **cparams)
  File "/Users/chronos_386/PycharmProjects/FaceRecognizerServer/.venv/lib/python3.8/site-packages/sqlalchemy/engine/default.py", line 621, in connect
    return self.loaded_dbapi.connect(*cargs, **cparams)
  File "/Users/chronos_386/PycharmProjects/FaceRecognizerServer/.venv/lib/python3.8/site-packages/pg8000/__init__.py", line 111, in connect
    return Connection(
  File "/Users/chronos_386/PycharmProjects/FaceRecognizerServer/.venv/lib/python3.8/site-packages/pg8000/legacy.py", line 443, in __init__
    super().__init__(*args, **kwargs)
  File "/Users/chronos_386/PycharmProjects/FaceRecognizerServer/.venv/lib/python3.8/site-packages/pg8000/core.py", line 320, in __init__
    self.channel_binding, self._usock = _make_socket(
  File "/Users/chronos_386/PycharmProjects/FaceRecognizerServer/.venv/lib/python3.8/site-packages/pg8000/core.py", line 208, in _make_socket
    raise InterfaceError(
sqlalchemy.exc.InterfaceError: (pg8000.exceptions.InterfaceError) Can't create a connection to host localhost and port 5432 (timeout is None and source_address is None).
(Background on this error at: https://sqlalche.me/e/20/rvf5)


2025-01-26 17:23:18 - ERROR - Необработанная ошибка: (pg8000.exceptions.InterfaceError) Can't create a connection to host localhost and port 5432 (timeout is None and source_address is None).
(Background on this error at: https://sqlalche.me/e/20/rvf5)
Traceback (most recent call last):
  File "/Users/chronos_386/PycharmProjects/FaceRecognizerServer/.venv/lib/python3.8/site-packages/pg8000/core.py", line 206, in _make_socket
    sock = socket.create_connection((host, port), timeout, source_address)
  File "/Library/Frameworks/Python.framework/Versions/3.8/lib/python3.8/socket.py", line 808, in create_connection
    raise err
  File "/Library/Frameworks/Python.framework/Versions/3.8/lib/python3.8/socket.py", line 796, in create_connection
    sock.connect(sa)
ConnectionRefusedError: [Errno 61] Connection refused

The above exception was the direct cause of the following exception:

Traceback (most recent call last):
  File "/Users/chronos_386/PycharmProjects/FaceRecognizerServer/.venv/lib/python3.8/site-packages/sqlalchemy/engine/base.py", line 146, in __init__
    self._dbapi_connection = engine.raw_connection()
  File "/Users/chronos_386/PycharmProjects/FaceRecognizerServer/.venv/lib/python3.8/site-packages/sqlalchemy/engine/base.py", line 3302, in raw_connection
    return self.pool.connect()
  File "/Users/chronos_386/PycharmProjects/FaceRecognizerServer/.venv/lib/python3.8/site-packages/sqlalchemy/pool/base.py", line 449, in connect
    return _ConnectionFairy._checkout(self)
  File "/Users/chronos_386/PycharmProjects/FaceRecognizerServer/.venv/lib/python3.8/site-packages/sqlalchemy/pool/base.py", line 1263, in _checkout
    fairy = _ConnectionRecord.checkout(pool)
  File "/Users/chronos_386/PycharmProjects/FaceRecognizerServer/.venv/lib/python3.8/site-packages/sqlalchemy/pool/base.py", line 712, in checkout
    rec = pool._do_get()
  File "/Users/chronos_386/PycharmProjects/FaceRecognizerServer/.venv/lib/python3.8/site-packages/sqlalchemy/pool/impl.py", line 180, in _do_get
    self._dec_overflow()
  File "/Users/chronos_386/PycharmProjects/FaceRecognizerServer/.venv/lib/python3.8/site-packages/sqlalchemy/util/langhelpers.py", line 146, in __exit__
    raise exc_value.with_traceback(exc_tb)
  File "/Users/chronos_386/PycharmProjects/FaceRecognizerServer/.venv/lib/python3.8/site-packages/sqlalchemy/pool/impl.py", line 177, in _do_get
    return self._create_connection()
  File "/Users/chronos_386/PycharmProjects/FaceRecognizerServer/.venv/lib/python3.8/site-packages/sqlalchemy/pool/base.py", line 390, in _create_connection
    return _ConnectionRecord(self)
  File "/Users/chronos_386/PycharmProjects/FaceRecognizerServer/.venv/lib/python3.8/site-packages/sqlalchemy/pool/base.py", line 674, in __init__
    self.__connect()
  File "/Users/chronos_386/PycharmProjects/FaceRecognizerServer/.venv/lib/python3.8/site-packages/sqlalchemy/pool/base.py", line 901, in __connect
    pool.logger.debug("Error on connect(): %s", e)
  File "/Users/chronos_386/PycharmProjects/FaceRecognizerServer/.venv/lib/python3.8/site-packages/sqlalchemy/util/langhelpers.py", line 146, in __exit__
    raise exc_value.with_traceback(exc_tb)
  File "/Users/chronos_386/PycharmProjects/FaceRecognizerServer/.venv/lib/python3.8/site-packages/sqlalchemy/pool/base.py", line 896, in __connect
    self.dbapi_connection = connection = pool._invoke_creator(self)
  File "/Users/chronos_386/PycharmProjects/FaceRecognizerServer/.venv/lib/python3.8/site-packages/sqlalchemy/engine/create.py", line 643, in connect
    return dialect.connect(*cargs, **cparams)
  File "/Users/chronos_386/PycharmProjects/FaceRecognizerServer/.venv/lib/python3.8/site-packages/sqlalchemy/engine/default.py", line 621, in connect
    return self.loaded_dbapi.connect(*cargs, **cparams)
  File "/Users/chronos_386/PycharmProjects/FaceRecognizerServer/.venv/lib/python3.8/site-packages/pg8000/__init__.py", line 111, in connect
    return Connection(
  File "/Users/chronos_386/PycharmProjects/FaceRecognizerServer/.venv/lib/python3.8/site-packages/pg8000/legacy.py", line 443, in __init__
    super().__init__(*args, **kwargs)
  File "/Users/chronos_386/PycharmProjects/FaceRecognizerServer/.venv/lib/python3.8/site-packages/pg8000/core.py", line 320, in __init__
    self.channel_binding, self._usock = _make_socket(
  File "/Users/chronos_386/PycharmProjects/FaceRecognizerServer/.venv/lib/python3.8/site-packages/pg8000/core.py", line 208, in _make_socket
    raise InterfaceError(
pg8000.exceptions.InterfaceError: Can't create a connection to host localhost and port 5432 (timeout is None and source_address is None).

The above exception was the direct cause of the following exception:

Traceback (most recent call last):
  File "/Users/chronos_386/PycharmProjects/FaceRecognizerServer/.venv/lib/python3.8/site-packages/flask/app.py", line 880, in full_dispatch_request
    rv = self.dispatch_request()
  File "/Users/chronos_386/PycharmProjects/FaceRecognizerServer/.venv/lib/python3.8/site-packages/flask/app.py", line 865, in dispatch_request
    return self.ensure_sync(self.view_functions[rule.endpoint])(**view_args)  # type: ignore[no-any-return]
  File "/Users/chronos_386/PycharmProjects/FaceRecognizerServer/.venv/lib/python3.8/site-packages/flask_restful/__init__.py", line 489, in wrapper
    resp = resource(*args, **kwargs)
  File "/Users/chronos_386/PycharmProjects/FaceRecognizerServer/.venv/lib/python3.8/site-packages/flask/views.py", line 110, in view
    return current_app.ensure_sync(self.dispatch_request)(**kwargs)  # type: ignore[no-any-return]
  File "/Users/chronos_386/PycharmProjects/FaceRecognizerServer/.venv/lib/python3.8/site-packages/flask_restful/__init__.py", line 604, in dispatch_request
    resp = meth(*args, **kwargs)
  File "/Users/chronos_386/PycharmProjects/FaceRecognizerServer/source_code/resources/schedule_device_res.py", line 12, in post
    student_id, json_model, code = self.api_connector.getStudentScheduleByPhoto(file)
  File "/Users/chronos_386/PycharmProjects/FaceRecognizerServer/source_code/api_connection/api_connector.py", line 674, in getStudentScheduleByPhoto
    student, code = self.__handleGetStudentByPhoto(photo)
  File "/Users/chronos_386/PycharmProjects/FaceRecognizerServer/source_code/api_connection/api_connector.py", line 89, in __handleGetStudentByPhoto
    emb: List[FaceEmbeddingsDB] = self.db_class.getAllEmbeddings()
  File "/Users/chronos_386/PycharmProjects/FaceRecognizerServer/source_code/db_connection/db_class.py", line 176, in getAllEmbeddings
    embeddings: List[Type[FaceEmbeddingsDB]] = self.session.query(FaceEmbeddingsDB).all()
  File "/Users/chronos_386/PycharmProjects/FaceRecognizerServer/.venv/lib/python3.8/site-packages/sqlalchemy/orm/query.py", line 2673, in all
    return self._iter().all()  # type: ignore
  File "/Users/chronos_386/PycharmProjects/FaceRecognizerServer/.venv/lib/python3.8/site-packages/sqlalchemy/orm/query.py", line 2827, in _iter
    result: Union[ScalarResult[_T], Result[_T]] = self.session.execute(
  File "/Users/chronos_386/PycharmProjects/FaceRecognizerServer/.venv/lib/python3.8/site-packages/sqlalchemy/orm/session.py", line 2362, in execute
    return self._execute_internal(
  File "/Users/chronos_386/PycharmProjects/FaceRecognizerServer/.venv/lib/python3.8/site-packages/sqlalchemy/orm/session.py", line 2237, in _execute_internal
    conn = self._connection_for_bind(bind)
  File "/Users/chronos_386/PycharmProjects/FaceRecognizerServer/.venv/lib/python3.8/site-packages/sqlalchemy/orm/session.py", line 2106, in _connection_for_bind
    return trans._connection_for_bind(engine, execution_options)
  File "<string>", line 2, in _connection_for_bind
  File "/Users/chronos_386/PycharmProjects/FaceRecognizerServer/.venv/lib/python3.8/site-packages/sqlalchemy/orm/state_changes.py", line 139, in _go
    ret_value = fn(self, *arg, **kw)
  File "/Users/chronos_386/PycharmProjects/FaceRecognizerServer/.venv/lib/python3.8/site-packages/sqlalchemy/orm/session.py", line 1189, in _connection_for_bind
    conn = bind.connect()
  File "/Users/chronos_386/PycharmProjects/FaceRecognizerServer/.venv/lib/python3.8/site-packages/sqlalchemy/engine/base.py", line 3278, in connect
    return self._connection_cls(self)
  File "/Users/chronos_386/PycharmProjects/FaceRecognizerServer/.venv/lib/python3.8/site-packages/sqlalchemy/engine/base.py", line 148, in __init__
    Connection._handle_dbapi_exception_noconnection(
  File "/Users/chronos_386/PycharmProjects/FaceRecognizerServer/.venv/lib/python3.8/site-packages/sqlalchemy/engine/base.py", line 2442, in _handle_dbapi_exception_noconnection
    raise sqlalchemy_exception.with_traceback(exc_info[2]) from e
  File "/Users/chronos_386/PycharmProjects/FaceRecognizerServer/.venv/lib/python3.8/site-packages/sqlalchemy/engine/base.py", line 146, in __init__
    self._dbapi_connection = engine.raw_connection()
  File "/Users/chronos_386/PycharmProjects/FaceRecognizerServer/.venv/lib/python3.8/site-packages/sqlalchemy/engine/base.py", line 3302, in raw_connection
    return self.pool.connect()
  File "/Users/chronos_386/PycharmProjects/FaceRecognizerServer/.venv/lib/python3.8/site-packages/sqlalchemy/pool/base.py", line 449, in connect
    return _ConnectionFairy._checkout(self)
  File "/Users/chronos_386/PycharmProjects/FaceRecognizerServer/.venv/lib/python3.8/site-packages/sqlalchemy/pool/base.py", line 1263, in _checkout
    fairy = _ConnectionRecord.checkout(pool)
  File "/Users/chronos_386/PycharmProjects/FaceRecognizerServer/.venv/lib/python3.8/site-packages/sqlalchemy/pool/base.py", line 712, in checkout
    rec = pool._do_get()
  File "/Users/chronos_386/PycharmProjects/FaceRecognizerServer/.venv/lib/python3.8/site-packages/sqlalchemy/pool/impl.py", line 180, in _do_get
    self._dec_overflow()
  File "/Users/chronos_386/PycharmProjects/FaceRecognizerServer/.venv/lib/python3.8/site-packages/sqlalchemy/util/langhelpers.py", line 146, in __exit__
    raise exc_value.with_traceback(exc_tb)
  File "/Users/chronos_386/PycharmProjects/FaceRecognizerServer/.venv/lib/python3.8/site-packages/sqlalchemy/pool/impl.py", line 177, in _do_get
    return self._create_connection()
  File "/Users/chronos_386/PycharmProjects/FaceRecognizerServer/.venv/lib/python3.8/site-packages/sqlalchemy/pool/base.py", line 390, in _create_connection
    return _ConnectionRecord(self)
  File "/Users/chronos_386/PycharmProjects/FaceRecognizerServer/.venv/lib/python3.8/site-packages/sqlalchemy/pool/base.py", line 674, in __init__
    self.__connect()
  File "/Users/chronos_386/PycharmProjects/FaceRecognizerServer/.venv/lib/python3.8/site-packages/sqlalchemy/pool/base.py", line 901, in __connect
    pool.logger.debug("Error on connect(): %s", e)
  File "/Users/chronos_386/PycharmProjects/FaceRecognizerServer/.venv/lib/python3.8/site-packages/sqlalchemy/util/langhelpers.py", line 146, in __exit__
    raise exc_value.with_traceback(exc_tb)
  File "/Users/chronos_386/PycharmProjects/FaceRecognizerServer/.venv/lib/python3.8/site-packages/sqlalchemy/pool/base.py", line 896, in __connect
    self.dbapi_connection = connection = pool._invoke_creator(self)
  File "/Users/chronos_386/PycharmProjects/FaceRecognizerServer/.venv/lib/python3.8/site-packages/sqlalchemy/engine/create.py", line 643, in connect
    return dialect.connect(*cargs, **cparams)
  File "/Users/chronos_386/PycharmProjects/FaceRecognizerServer/.venv/lib/python3.8/site-packages/sqlalchemy/engine/default.py", line 621, in connect
    return self.loaded_dbapi.connect(*cargs, **cparams)
  File "/Users/chronos_386/PycharmProjects/FaceRecognizerServer/.venv/lib/python3.8/site-packages/pg8000/__init__.py", line 111, in connect
    return Connection(
  File "/Users/chronos_386/PycharmProjects/FaceRecognizerServer/.venv/lib/python3.8/site-packages/pg8000/legacy.py", line 443, in __init__
    super().__init__(*args, **kwargs)
  File "/Users/chronos_386/PycharmProjects/FaceRecognizerServer/.venv/lib/python3.8/site-packages/pg8000/core.py", line 320, in __init__
    self.channel_binding, self._usock = _make_socket(
  File "/Users/chronos_386/PycharmProjects/FaceRecognizerServer/.venv/lib/python3.8/site-packages/pg8000/core.py", line 208, in _make_socket
    raise InterfaceError(
sqlalchemy.exc.InterfaceError: (pg8000.exceptions.InterfaceError) Can't create a connection to host localhost and port 5432 (timeout is None and source_address is None).
(Background on this error at: https://sqlalche.me/e/20/rvf5)


2025-01-26 17:27:25 - ERROR - Необработанная ошибка: (pg8000.exceptions.InterfaceError) Can't create a connection to host localhost and port 5432 (timeout is None and source_address is None).
(Background on this error at: https://sqlalche.me/e/20/rvf5)
Traceback (most recent call last):
  File "/Users/chronos_386/PycharmProjects/FaceRecognizerServer/.venv/lib/python3.8/site-packages/pg8000/core.py", line 206, in _make_socket
    sock = socket.create_connection((host, port), timeout, source_address)
  File "/Library/Frameworks/Python.framework/Versions/3.8/lib/python3.8/socket.py", line 808, in create_connection
    raise err
  File "/Library/Frameworks/Python.framework/Versions/3.8/lib/python3.8/socket.py", line 796, in create_connection
    sock.connect(sa)
ConnectionRefusedError: [Errno 61] Connection refused

The above exception was the direct cause of the following exception:

Traceback (most recent call last):
  File "/Users/chronos_386/PycharmProjects/FaceRecognizerServer/.venv/lib/python3.8/site-packages/sqlalchemy/engine/base.py", line 146, in __init__
    self._dbapi_connection = engine.raw_connection()
  File "/Users/chronos_386/PycharmProjects/FaceRecognizerServer/.venv/lib/python3.8/site-packages/sqlalchemy/engine/base.py", line 3302, in raw_connection
    return self.pool.connect()
  File "/Users/chronos_386/PycharmProjects/FaceRecognizerServer/.venv/lib/python3.8/site-packages/sqlalchemy/pool/base.py", line 449, in connect
    return _ConnectionFairy._checkout(self)
  File "/Users/chronos_386/PycharmProjects/FaceRecognizerServer/.venv/lib/python3.8/site-packages/sqlalchemy/pool/base.py", line 1263, in _checkout
    fairy = _ConnectionRecord.checkout(pool)
  File "/Users/chronos_386/PycharmProjects/FaceRecognizerServer/.venv/lib/python3.8/site-packages/sqlalchemy/pool/base.py", line 712, in checkout
    rec = pool._do_get()
  File "/Users/chronos_386/PycharmProjects/FaceRecognizerServer/.venv/lib/python3.8/site-packages/sqlalchemy/pool/impl.py", line 180, in _do_get
    self._dec_overflow()
  File "/Users/chronos_386/PycharmProjects/FaceRecognizerServer/.venv/lib/python3.8/site-packages/sqlalchemy/util/langhelpers.py", line 146, in __exit__
    raise exc_value.with_traceback(exc_tb)
  File "/Users/chronos_386/PycharmProjects/FaceRecognizerServer/.venv/lib/python3.8/site-packages/sqlalchemy/pool/impl.py", line 177, in _do_get
    return self._create_connection()
  File "/Users/chronos_386/PycharmProjects/FaceRecognizerServer/.venv/lib/python3.8/site-packages/sqlalchemy/pool/base.py", line 390, in _create_connection
    return _ConnectionRecord(self)
  File "/Users/chronos_386/PycharmProjects/FaceRecognizerServer/.venv/lib/python3.8/site-packages/sqlalchemy/pool/base.py", line 674, in __init__
    self.__connect()
  File "/Users/chronos_386/PycharmProjects/FaceRecognizerServer/.venv/lib/python3.8/site-packages/sqlalchemy/pool/base.py", line 901, in __connect
    pool.logger.debug("Error on connect(): %s", e)
  File "/Users/chronos_386/PycharmProjects/FaceRecognizerServer/.venv/lib/python3.8/site-packages/sqlalchemy/util/langhelpers.py", line 146, in __exit__
    raise exc_value.with_traceback(exc_tb)
  File "/Users/chronos_386/PycharmProjects/FaceRecognizerServer/.venv/lib/python3.8/site-packages/sqlalchemy/pool/base.py", line 896, in __connect
    self.dbapi_connection = connection = pool._invoke_creator(self)
  File "/Users/chronos_386/PycharmProjects/FaceRecognizerServer/.venv/lib/python3.8/site-packages/sqlalchemy/engine/create.py", line 643, in connect
    return dialect.connect(*cargs, **cparams)
  File "/Users/chronos_386/PycharmProjects/FaceRecognizerServer/.venv/lib/python3.8/site-packages/sqlalchemy/engine/default.py", line 621, in connect
    return self.loaded_dbapi.connect(*cargs, **cparams)
  File "/Users/chronos_386/PycharmProjects/FaceRecognizerServer/.venv/lib/python3.8/site-packages/pg8000/__init__.py", line 111, in connect
    return Connection(
  File "/Users/chronos_386/PycharmProjects/FaceRecognizerServer/.venv/lib/python3.8/site-packages/pg8000/legacy.py", line 443, in __init__
    super().__init__(*args, **kwargs)
  File "/Users/chronos_386/PycharmProjects/FaceRecognizerServer/.venv/lib/python3.8/site-packages/pg8000/core.py", line 320, in __init__
    self.channel_binding, self._usock = _make_socket(
  File "/Users/chronos_386/PycharmProjects/FaceRecognizerServer/.venv/lib/python3.8/site-packages/pg8000/core.py", line 208, in _make_socket
    raise InterfaceError(
pg8000.exceptions.InterfaceError: Can't create a connection to host localhost and port 5432 (timeout is None and source_address is None).

The above exception was the direct cause of the following exception:

Traceback (most recent call last):
  File "/Users/chronos_386/PycharmProjects/FaceRecognizerServer/.venv/lib/python3.8/site-packages/flask/app.py", line 880, in full_dispatch_request
    rv = self.dispatch_request()
  File "/Users/chronos_386/PycharmProjects/FaceRecognizerServer/.venv/lib/python3.8/site-packages/flask/app.py", line 865, in dispatch_request
    return self.ensure_sync(self.view_functions[rule.endpoint])(**view_args)  # type: ignore[no-any-return]
  File "/Users/chronos_386/PycharmProjects/FaceRecognizerServer/.venv/lib/python3.8/site-packages/flask_restful/__init__.py", line 489, in wrapper
    resp = resource(*args, **kwargs)
  File "/Users/chronos_386/PycharmProjects/FaceRecognizerServer/.venv/lib/python3.8/site-packages/flask/views.py", line 110, in view
    return current_app.ensure_sync(self.dispatch_request)(**kwargs)  # type: ignore[no-any-return]
  File "/Users/chronos_386/PycharmProjects/FaceRecognizerServer/.venv/lib/python3.8/site-packages/flask_restful/__init__.py", line 604, in dispatch_request
    resp = meth(*args, **kwargs)
  File "/Users/chronos_386/PycharmProjects/FaceRecognizerServer/source_code/resources/user_acc_res.py", line 10, in post
    json_model = self.api_connector.loginByPassword(login, password)
  File "/Users/chronos_386/PycharmProjects/FaceRecognizerServer/source_code/api_connection/api_connector.py", line 212, in loginByPassword
    account_tuple: Optional[Tuple[AccountsDB, str]] = self.db_class.loginByPassword(login, password)
  File "/Users/chronos_386/PycharmProjects/FaceRecognizerServer/source_code/db_connection/db_class.py", line 80, in loginByPassword
    account_db = self.session.query(AccountsDB).filter_by(email=email, password=password).first()
  File "/Users/chronos_386/PycharmProjects/FaceRecognizerServer/.venv/lib/python3.8/site-packages/sqlalchemy/orm/query.py", line 2728, in first
    return self.limit(1)._iter().first()  # type: ignore
  File "/Users/chronos_386/PycharmProjects/FaceRecognizerServer/.venv/lib/python3.8/site-packages/sqlalchemy/orm/query.py", line 2827, in _iter
    result: Union[ScalarResult[_T], Result[_T]] = self.session.execute(
  File "/Users/chronos_386/PycharmProjects/FaceRecognizerServer/.venv/lib/python3.8/site-packages/sqlalchemy/orm/session.py", line 2362, in execute
    return self._execute_internal(
  File "/Users/chronos_386/PycharmProjects/FaceRecognizerServer/.venv/lib/python3.8/site-packages/sqlalchemy/orm/session.py", line 2237, in _execute_internal
    conn = self._connection_for_bind(bind)
  File "/Users/chronos_386/PycharmProjects/FaceRecognizerServer/.venv/lib/python3.8/site-packages/sqlalchemy/orm/session.py", line 2106, in _connection_for_bind
    return trans._connection_for_bind(engine, execution_options)
  File "<string>", line 2, in _connection_for_bind
  File "/Users/chronos_386/PycharmProjects/FaceRecognizerServer/.venv/lib/python3.8/site-packages/sqlalchemy/orm/state_changes.py", line 139, in _go
    ret_value = fn(self, *arg, **kw)
  File "/Users/chronos_386/PycharmProjects/FaceRecognizerServer/.venv/lib/python3.8/site-packages/sqlalchemy/orm/session.py", line 1189, in _connection_for_bind
    conn = bind.connect()
  File "/Users/chronos_386/PycharmProjects/FaceRecognizerServer/.venv/lib/python3.8/site-packages/sqlalchemy/engine/base.py", line 3278, in connect
    return self._connection_cls(self)
  File "/Users/chronos_386/PycharmProjects/FaceRecognizerServer/.venv/lib/python3.8/site-packages/sqlalchemy/engine/base.py", line 148, in __init__
    Connection._handle_dbapi_exception_noconnection(
  File "/Users/chronos_386/PycharmProjects/FaceRecognizerServer/.venv/lib/python3.8/site-packages/sqlalchemy/engine/base.py", line 2442, in _handle_dbapi_exception_noconnection
    raise sqlalchemy_exception.with_traceback(exc_info[2]) from e
  File "/Users/chronos_386/PycharmProjects/FaceRecognizerServer/.venv/lib/python3.8/site-packages/sqlalchemy/engine/base.py", line 146, in __init__
    self._dbapi_connection = engine.raw_connection()
  File "/Users/chronos_386/PycharmProjects/FaceRecognizerServer/.venv/lib/python3.8/site-packages/sqlalchemy/engine/base.py", line 3302, in raw_connection
    return self.pool.connect()
  File "/Users/chronos_386/PycharmProjects/FaceRecognizerServer/.venv/lib/python3.8/site-packages/sqlalchemy/pool/base.py", line 449, in connect
    return _ConnectionFairy._checkout(self)
  File "/Users/chronos_386/PycharmProjects/FaceRecognizerServer/.venv/lib/python3.8/site-packages/sqlalchemy/pool/base.py", line 1263, in _checkout
    fairy = _ConnectionRecord.checkout(pool)
  File "/Users/chronos_386/PycharmProjects/FaceRecognizerServer/.venv/lib/python3.8/site-packages/sqlalchemy/pool/base.py", line 712, in checkout
    rec = pool._do_get()
  File "/Users/chronos_386/PycharmProjects/FaceRecognizerServer/.venv/lib/python3.8/site-packages/sqlalchemy/pool/impl.py", line 180, in _do_get
    self._dec_overflow()
  File "/Users/chronos_386/PycharmProjects/FaceRecognizerServer/.venv/lib/python3.8/site-packages/sqlalchemy/util/langhelpers.py", line 146, in __exit__
    raise exc_value.with_traceback(exc_tb)
  File "/Users/chronos_386/PycharmProjects/FaceRecognizerServer/.venv/lib/python3.8/site-packages/sqlalchemy/pool/impl.py", line 177, in _do_get
    return self._create_connection()
  File "/Users/chronos_386/PycharmProjects/FaceRecognizerServer/.venv/lib/python3.8/site-packages/sqlalchemy/pool/base.py", line 390, in _create_connection
    return _ConnectionRecord(self)
  File "/Users/chronos_386/PycharmProjects/FaceRecognizerServer/.venv/lib/python3.8/site-packages/sqlalchemy/pool/base.py", line 674, in __init__
    self.__connect()
  File "/Users/chronos_386/PycharmProjects/FaceRecognizerServer/.venv/lib/python3.8/site-packages/sqlalchemy/pool/base.py", line 901, in __connect
    pool.logger.debug("Error on connect(): %s", e)
  File "/Users/chronos_386/PycharmProjects/FaceRecognizerServer/.venv/lib/python3.8/site-packages/sqlalchemy/util/langhelpers.py", line 146, in __exit__
    raise exc_value.with_traceback(exc_tb)
  File "/Users/chronos_386/PycharmProjects/FaceRecognizerServer/.venv/lib/python3.8/site-packages/sqlalchemy/pool/base.py", line 896, in __connect
    self.dbapi_connection = connection = pool._invoke_creator(self)
  File "/Users/chronos_386/PycharmProjects/FaceRecognizerServer/.venv/lib/python3.8/site-packages/sqlalchemy/engine/create.py", line 643, in connect
    return dialect.connect(*cargs, **cparams)
  File "/Users/chronos_386/PycharmProjects/FaceRecognizerServer/.venv/lib/python3.8/site-packages/sqlalchemy/engine/default.py", line 621, in connect
    return self.loaded_dbapi.connect(*cargs, **cparams)
  File "/Users/chronos_386/PycharmProjects/FaceRecognizerServer/.venv/lib/python3.8/site-packages/pg8000/__init__.py", line 111, in connect
    return Connection(
  File "/Users/chronos_386/PycharmProjects/FaceRecognizerServer/.venv/lib/python3.8/site-packages/pg8000/legacy.py", line 443, in __init__
    super().__init__(*args, **kwargs)
  File "/Users/chronos_386/PycharmProjects/FaceRecognizerServer/.venv/lib/python3.8/site-packages/pg8000/core.py", line 320, in __init__
    self.channel_binding, self._usock = _make_socket(
  File "/Users/chronos_386/PycharmProjects/FaceRecognizerServer/.venv/lib/python3.8/site-packages/pg8000/core.py", line 208, in _make_socket
    raise InterfaceError(
sqlalchemy.exc.InterfaceError: (pg8000.exceptions.InterfaceError) Can't create a connection to host localhost and port 5432 (timeout is None and source_address is None).
(Background on this error at: https://sqlalche.me/e/20/rvf5)


2025-01-26 17:28:55 - ERROR - Лицо не обнаружено на изображении
NoneType: None


2025-01-26 17:28:58 - ERROR - Лицо не обнаружено на изображении
NoneType: None


2025-01-26 17:29:01 - ERROR - Лицо не обнаружено на изображении
NoneType: None


2025-01-26 17:39:50 - ERROR - Необработанная ошибка: (pg8000.exceptions.InterfaceError) network error
[SQL: SELECT face_embeddings.id AS face_embeddings_id, face_embeddings.embedding AS face_embeddings_embedding, face_embeddings.student_id AS face_embeddings_student_id, face_embeddings.path_photo AS face_embeddings_path_photo 
FROM face_embeddings]
(Background on this error at: https://sqlalche.me/e/20/rvf5)
Traceback (most recent call last):
  File "/Users/chronos_386/PycharmProjects/FaceRecognizerServer/.venv/lib/python3.8/site-packages/pg8000/core.py", line 144, in _flush
    sock.flush()
  File "/Library/Frameworks/Python.framework/Versions/3.8/lib/python3.8/socket.py", line 687, in write
    return self._sock.send(b)
BrokenPipeError: [Errno 32] Broken pipe

The above exception was the direct cause of the following exception:

Traceback (most recent call last):
  File "/Users/chronos_386/PycharmProjects/FaceRecognizerServer/.venv/lib/python3.8/site-packages/sqlalchemy/engine/base.py", line 1967, in _exec_single_context
    self.dialect.do_execute(
  File "/Users/chronos_386/PycharmProjects/FaceRecognizerServer/.venv/lib/python3.8/site-packages/sqlalchemy/engine/default.py", line 941, in do_execute
    cursor.execute(statement, parameters)
  File "/Users/chronos_386/PycharmProjects/FaceRecognizerServer/.venv/lib/python3.8/site-packages/pg8000/legacy.py", line 248, in execute
    self._c.execute_simple("begin transaction")
  File "/Users/chronos_386/PycharmProjects/FaceRecognizerServer/.venv/lib/python3.8/site-packages/pg8000/core.py", line 685, in execute_simple
    _flush(self._sock)
  File "/Users/chronos_386/PycharmProjects/FaceRecognizerServer/.venv/lib/python3.8/site-packages/pg8000/core.py", line 146, in _flush
    raise InterfaceError("network error") from e
pg8000.exceptions.InterfaceError: network error

The above exception was the direct cause of the following exception:

Traceback (most recent call last):
  File "/Users/chronos_386/PycharmProjects/FaceRecognizerServer/.venv/lib/python3.8/site-packages/flask/app.py", line 880, in full_dispatch_request
    rv = self.dispatch_request()
  File "/Users/chronos_386/PycharmProjects/FaceRecognizerServer/.venv/lib/python3.8/site-packages/flask/app.py", line 865, in dispatch_request
    return self.ensure_sync(self.view_functions[rule.endpoint])(**view_args)  # type: ignore[no-any-return]
  File "/Users/chronos_386/PycharmProjects/FaceRecognizerServer/.venv/lib/python3.8/site-packages/flask_restful/__init__.py", line 489, in wrapper
    resp = resource(*args, **kwargs)
  File "/Users/chronos_386/PycharmProjects/FaceRecognizerServer/.venv/lib/python3.8/site-packages/flask/views.py", line 110, in view
    return current_app.ensure_sync(self.dispatch_request)(**kwargs)  # type: ignore[no-any-return]
  File "/Users/chronos_386/PycharmProjects/FaceRecognizerServer/.venv/lib/python3.8/site-packages/flask_restful/__init__.py", line 604, in dispatch_request
    resp = meth(*args, **kwargs)
  File "/Users/chronos_386/PycharmProjects/FaceRecognizerServer/source_code/resources/schedule_device_res.py", line 12, in post
    student_id, json_model, code = self.api_connector.getStudentScheduleByPhoto(file)
  File "/Users/chronos_386/PycharmProjects/FaceRecognizerServer/source_code/api_connection/api_connector.py", line 674, in getStudentScheduleByPhoto
    student, code = self.__handleGetStudentByPhoto(photo)
  File "/Users/chronos_386/PycharmProjects/FaceRecognizerServer/source_code/api_connection/api_connector.py", line 89, in __handleGetStudentByPhoto
    emb: List[FaceEmbeddingsDB] = self.db_class.getAllEmbeddings()
  File "/Users/chronos_386/PycharmProjects/FaceRecognizerServer/source_code/db_connection/db_class.py", line 176, in getAllEmbeddings
    embeddings: List[Type[FaceEmbeddingsDB]] = self.session.query(FaceEmbeddingsDB).all()
  File "/Users/chronos_386/PycharmProjects/FaceRecognizerServer/.venv/lib/python3.8/site-packages/sqlalchemy/orm/query.py", line 2673, in all
    return self._iter().all()  # type: ignore
  File "/Users/chronos_386/PycharmProjects/FaceRecognizerServer/.venv/lib/python3.8/site-packages/sqlalchemy/orm/query.py", line 2827, in _iter
    result: Union[ScalarResult[_T], Result[_T]] = self.session.execute(
  File "/Users/chronos_386/PycharmProjects/FaceRecognizerServer/.venv/lib/python3.8/site-packages/sqlalchemy/orm/session.py", line 2362, in execute
    return self._execute_internal(
  File "/Users/chronos_386/PycharmProjects/FaceRecognizerServer/.venv/lib/python3.8/site-packages/sqlalchemy/orm/session.py", line 2247, in _execute_internal
    result: Result[Any] = compile_state_cls.orm_execute_statement(
  File "/Users/chronos_386/PycharmProjects/FaceRecognizerServer/.venv/lib/python3.8/site-packages/sqlalchemy/orm/context.py", line 305, in orm_execute_statement
    result = conn.execute(
  File "/Users/chronos_386/PycharmProjects/FaceRecognizerServer/.venv/lib/python3.8/site-packages/sqlalchemy/engine/base.py", line 1418, in execute
    return meth(
  File "/Users/chronos_386/PycharmProjects/FaceRecognizerServer/.venv/lib/python3.8/site-packages/sqlalchemy/sql/elements.py", line 515, in _execute_on_connection
    return connection._execute_clauseelement(
  File "/Users/chronos_386/PycharmProjects/FaceRecognizerServer/.venv/lib/python3.8/site-packages/sqlalchemy/engine/base.py", line 1640, in _execute_clauseelement
    ret = self._execute_context(
  File "/Users/chronos_386/PycharmProjects/FaceRecognizerServer/.venv/lib/python3.8/site-packages/sqlalchemy/engine/base.py", line 1846, in _execute_context
    return self._exec_single_context(
  File "/Users/chronos_386/PycharmProjects/FaceRecognizerServer/.venv/lib/python3.8/site-packages/sqlalchemy/engine/base.py", line 1986, in _exec_single_context
    self._handle_dbapi_exception(
  File "/Users/chronos_386/PycharmProjects/FaceRecognizerServer/.venv/lib/python3.8/site-packages/sqlalchemy/engine/base.py", line 2355, in _handle_dbapi_exception
    raise sqlalchemy_exception.with_traceback(exc_info[2]) from e
  File "/Users/chronos_386/PycharmProjects/FaceRecognizerServer/.venv/lib/python3.8/site-packages/sqlalchemy/engine/base.py", line 1967, in _exec_single_context
    self.dialect.do_execute(
  File "/Users/chronos_386/PycharmProjects/FaceRecognizerServer/.venv/lib/python3.8/site-packages/sqlalchemy/engine/default.py", line 941, in do_execute
    cursor.execute(statement, parameters)
  File "/Users/chronos_386/PycharmProjects/FaceRecognizerServer/.venv/lib/python3.8/site-packages/pg8000/legacy.py", line 248, in execute
    self._c.execute_simple("begin transaction")
  File "/Users/chronos_386/PycharmProjects/FaceRecognizerServer/.venv/lib/python3.8/site-packages/pg8000/core.py", line 685, in execute_simple
    _flush(self._sock)
  File "/Users/chronos_386/PycharmProjects/FaceRecognizerServer/.venv/lib/python3.8/site-packages/pg8000/core.py", line 146, in _flush
    raise InterfaceError("network error") from e
sqlalchemy.exc.InterfaceError: (pg8000.exceptions.InterfaceError) network error
[SQL: SELECT face_embeddings.id AS face_embeddings_id, face_embeddings.embedding AS face_embeddings_embedding, face_embeddings.student_id AS face_embeddings_student_id, face_embeddings.path_photo AS face_embeddings_path_photo 
FROM face_embeddings]
(Background on this error at: https://sqlalche.me/e/20/rvf5)


2025-01-26 17:40:08 - ERROR - Необработанная ошибка: Can't reconnect until invalid transaction is rolled back.  Please rollback() fully before proceeding (Background on this error at: https://sqlalche.me/e/20/8s2b)
Traceback (most recent call last):
  File "/Users/chronos_386/PycharmProjects/FaceRecognizerServer/.venv/lib/python3.8/site-packages/flask/app.py", line 880, in full_dispatch_request
    rv = self.dispatch_request()
  File "/Users/chronos_386/PycharmProjects/FaceRecognizerServer/.venv/lib/python3.8/site-packages/flask/app.py", line 865, in dispatch_request
    return self.ensure_sync(self.view_functions[rule.endpoint])(**view_args)  # type: ignore[no-any-return]
  File "/Users/chronos_386/PycharmProjects/FaceRecognizerServer/.venv/lib/python3.8/site-packages/flask_restful/__init__.py", line 489, in wrapper
    resp = resource(*args, **kwargs)
  File "/Users/chronos_386/PycharmProjects/FaceRecognizerServer/.venv/lib/python3.8/site-packages/flask/views.py", line 110, in view
    return current_app.ensure_sync(self.dispatch_request)(**kwargs)  # type: ignore[no-any-return]
  File "/Users/chronos_386/PycharmProjects/FaceRecognizerServer/.venv/lib/python3.8/site-packages/flask_restful/__init__.py", line 604, in dispatch_request
    resp = meth(*args, **kwargs)
  File "/Users/chronos_386/PycharmProjects/FaceRecognizerServer/source_code/resources/schedule_device_res.py", line 12, in post
    student_id, json_model, code = self.api_connector.getStudentScheduleByPhoto(file)
  File "/Users/chronos_386/PycharmProjects/FaceRecognizerServer/source_code/api_connection/api_connector.py", line 674, in getStudentScheduleByPhoto
    student, code = self.__handleGetStudentByPhoto(photo)
  File "/Users/chronos_386/PycharmProjects/FaceRecognizerServer/source_code/api_connection/api_connector.py", line 89, in __handleGetStudentByPhoto
    emb: List[FaceEmbeddingsDB] = self.db_class.getAllEmbeddings()
  File "/Users/chronos_386/PycharmProjects/FaceRecognizerServer/source_code/db_connection/db_class.py", line 176, in getAllEmbeddings
    embeddings: List[Type[FaceEmbeddingsDB]] = self.session.query(FaceEmbeddingsDB).all()
  File "/Users/chronos_386/PycharmProjects/FaceRecognizerServer/.venv/lib/python3.8/site-packages/sqlalchemy/orm/query.py", line 2673, in all
    return self._iter().all()  # type: ignore
  File "/Users/chronos_386/PycharmProjects/FaceRecognizerServer/.venv/lib/python3.8/site-packages/sqlalchemy/orm/query.py", line 2827, in _iter
    result: Union[ScalarResult[_T], Result[_T]] = self.session.execute(
  File "/Users/chronos_386/PycharmProjects/FaceRecognizerServer/.venv/lib/python3.8/site-packages/sqlalchemy/orm/session.py", line 2362, in execute
    return self._execute_internal(
  File "/Users/chronos_386/PycharmProjects/FaceRecognizerServer/.venv/lib/python3.8/site-packages/sqlalchemy/orm/session.py", line 2247, in _execute_internal
    result: Result[Any] = compile_state_cls.orm_execute_statement(
  File "/Users/chronos_386/PycharmProjects/FaceRecognizerServer/.venv/lib/python3.8/site-packages/sqlalchemy/orm/context.py", line 305, in orm_execute_statement
    result = conn.execute(
  File "/Users/chronos_386/PycharmProjects/FaceRecognizerServer/.venv/lib/python3.8/site-packages/sqlalchemy/engine/base.py", line 1418, in execute
    return meth(
  File "/Users/chronos_386/PycharmProjects/FaceRecognizerServer/.venv/lib/python3.8/site-packages/sqlalchemy/sql/elements.py", line 515, in _execute_on_connection
    return connection._execute_clauseelement(
  File "/Users/chronos_386/PycharmProjects/FaceRecognizerServer/.venv/lib/python3.8/site-packages/sqlalchemy/engine/base.py", line 1640, in _execute_clauseelement
    ret = self._execute_context(
  File "/Users/chronos_386/PycharmProjects/FaceRecognizerServer/.venv/lib/python3.8/site-packages/sqlalchemy/engine/base.py", line 1813, in _execute_context
    conn = self._revalidate_connection()
  File "/Users/chronos_386/PycharmProjects/FaceRecognizerServer/.venv/lib/python3.8/site-packages/sqlalchemy/engine/base.py", line 677, in _revalidate_connection
    self._invalid_transaction()
  File "/Users/chronos_386/PycharmProjects/FaceRecognizerServer/.venv/lib/python3.8/site-packages/sqlalchemy/engine/base.py", line 667, in _invalid_transaction
    raise exc.PendingRollbackError(
sqlalchemy.exc.PendingRollbackError: Can't reconnect until invalid transaction is rolled back.  Please rollback() fully before proceeding (Background on this error at: https://sqlalche.me/e/20/8s2b)


2025-01-26 18:38:28 - ERROR - Лицо не обнаружено на изображении
NoneType: None


2025-01-26 18:38:51 - ERROR - Лицо не обнаружено на изображении
NoneType: None


