2024-10-15 02:37:04 - ERROR - Необработанная ошибка: int() argument must be a string, a bytes-like object or a real number, not 'NoneType'
Traceback (most recent call last):
  File "D:\anaconda3\Lib\site-packages\flask_restful\__init__.py", line 295, in error_router
    return self.handle_error(e)
           ^^^^^^^^^^^^^^^^^^^^
  File "D:\anaconda3\Lib\site-packages\flask_restful\__init__.py", line 310, in handle_error
    _handle_flask_propagate_exceptions_config(current_app, e)
  File "D:\anaconda3\Lib\site-packages\flask\app.py", line 1820, in full_dispatch_request
    rv = self.dispatch_request()
         ^^^^^^^^^^^^^^^^^^^^^^^
  File "D:\anaconda3\Lib\site-packages\flask\app.py", line 1796, in dispatch_request
    return self.ensure_sync(self.view_functions[rule.endpoint])(**view_args)
           ^^^^^^^^^^^^^^^^^^^^^^^^^^^^^^^^^^^^^^^^^^^^^^^^^^^^^^^^^^^^^^^^^
  File "D:\anaconda3\Lib\site-packages\flask_restful\__init__.py", line 489, in wrapper
    resp = resource(*args, **kwargs)
           ^^^^^^^^^^^^^^^^^^^^^^^^^
  File "D:\anaconda3\Lib\site-packages\flask\views.py", line 107, in view
    return current_app.ensure_sync(self.dispatch_request)(**kwargs)
           ^^^^^^^^^^^^^^^^^^^^^^^^^^^^^^^^^^^^^^^^^^^^^^^^^^^^^^^^
  File "D:\anaconda3\Lib\site-packages\flask_restful\__init__.py", line 604, in dispatch_request
    resp = meth(*args, **kwargs)
           ^^^^^^^^^^^^^^^^^^^^^
  File "D:\PythonProjects\FaceRecognizerServer\source_code\resources\attendance_group_teacher_res.py", line 8, in post
    hash_user: str = request.form.get('hash')
                      ^^^^^^^^^^^^^^^^^^^^^^^^
TypeError: int() argument must be a string, a bytes-like object or a real number, not 'NoneType'


2024-10-15 02:58:45 - ERROR - Необработанная ошибка: 404 Not Found: The requested URL was not found on the server. If you entered the URL manually please check your spelling and try again.
Traceback (most recent call last):
  File "D:\anaconda3\Lib\site-packages\flask\app.py", line 1820, in full_dispatch_request
    rv = self.dispatch_request()
         ^^^^^^^^^^^^^^^^^^^^^^^
  File "D:\anaconda3\Lib\site-packages\flask\app.py", line 1785, in dispatch_request
    self.raise_routing_exception(req)
  File "D:\anaconda3\Lib\site-packages\flask\app.py", line 1767, in raise_routing_exception
    raise request.routing_exception  # type: ignore
    ^^^^^^^^^^^^^^^^^^^^^^^^^^^^^^^
  File "D:\anaconda3\Lib\site-packages\flask\ctx.py", line 351, in match_request
    result = self.url_adapter.match(return_rule=True)  # type: ignore
             ^^^^^^^^^^^^^^^^^^^^^^^^^^^^^^^^^^^^^^^^
  File "D:\anaconda3\Lib\site-packages\werkzeug\routing\map.py", line 624, in match
    raise NotFound() from None
werkzeug.exceptions.NotFound: 404 Not Found: The requested URL was not found on the server. If you entered the URL manually please check your spelling and try again.


