2024-11-01 03:34:43 - ERROR - Необработанная ошибка: DLL load failed while importing _psycopg: Не найден указанный модуль.
Traceback (most recent call last):
  File "D:\PythonProjects\FaceRecognizerServer\.venv\lib\site-packages\flask\app.py", line 880, in full_dispatch_request
    rv = self.dispatch_request()
  File "D:\PythonProjects\FaceRecognizerServer\.venv\lib\site-packages\flask\app.py", line 865, in dispatch_request
    return self.ensure_sync(self.view_functions[rule.endpoint])(**view_args)  # type: ignore[no-any-return]
  File "D:\PythonProjects\FaceRecognizerServer\.venv\lib\site-packages\flask_restful\__init__.py", line 489, in wrapper
    resp = resource(*args, **kwargs)
  File "D:\PythonProjects\FaceRecognizerServer\.venv\lib\site-packages\flask\views.py", line 107, in view
    self = view.view_class(  # type: ignore[attr-defined]
  File "src/dependency_injector/_cwiring.pyx", line 26, in dependency_injector._cwiring._get_sync_patched._patched
  File "src/dependency_injector/providers.pyx", line 225, in dependency_injector.providers.Provider.__call__
  File "src/dependency_injector/providers.pyx", line 3049, in dependency_injector.providers.Singleton._provide
  File "src/dependency_injector/providers.pxd", line 650, in dependency_injector.providers.__factory_call
  File "src/dependency_injector/providers.pxd", line 577, in dependency_injector.providers.__call
  File "src/dependency_injector/providers.pxd", line 445, in dependency_injector.providers.__provide_keyword_args
  File "src/dependency_injector/providers.pxd", line 365, in dependency_injector.providers.__get_value
  File "src/dependency_injector/providers.pyx", line 225, in dependency_injector.providers.Provider.__call__
  File "src/dependency_injector/providers.pyx", line 3049, in dependency_injector.providers.Singleton._provide
  File "src/dependency_injector/providers.pxd", line 650, in dependency_injector.providers.__factory_call
  File "src/dependency_injector/providers.pxd", line 608, in dependency_injector.providers.__call
  File "D:\PythonProjects\FaceRecognizerServer\source_code\db_connection\db_class.py", line 25, in __init__
    self.engine = create_engine("postgresql+psycopg2://postgres:Chronos386@localhost/face_recognition_db")
  File "<string>", line 2, in create_engine
  File "D:\PythonProjects\FaceRecognizerServer\.venv\lib\site-packages\sqlalchemy\util\deprecations.py", line 281, in warned
    return fn(*args, **kwargs)  # type: ignore[no-any-return]
  File "D:\PythonProjects\FaceRecognizerServer\.venv\lib\site-packages\sqlalchemy\engine\create.py", line 599, in create_engine
    dbapi = dbapi_meth(**dbapi_args)
  File "D:\PythonProjects\FaceRecognizerServer\.venv\lib\site-packages\sqlalchemy\dialects\postgresql\psycopg2.py", line 690, in import_dbapi
    import psycopg2
  File "D:\PythonProjects\FaceRecognizerServer\.venv\lib\site-packages\psycopg2\__init__.py", line 51, in <module>
    from psycopg2._psycopg import (                     # noqa
ImportError: DLL load failed while importing _psycopg: Не найден указанный модуль.


2024-11-01 03:39:20 - ERROR - Необработанная ошибка: DLL load failed while importing _psycopg: Не найден указанный модуль.
Traceback (most recent call last):
  File "D:\PythonProjects\FaceRecognizerServer\.venv\lib\site-packages\flask\app.py", line 880, in full_dispatch_request
    rv = self.dispatch_request()
  File "D:\PythonProjects\FaceRecognizerServer\.venv\lib\site-packages\flask\app.py", line 865, in dispatch_request
    return self.ensure_sync(self.view_functions[rule.endpoint])(**view_args)  # type: ignore[no-any-return]
  File "D:\PythonProjects\FaceRecognizerServer\.venv\lib\site-packages\flask_restful\__init__.py", line 489, in wrapper
    resp = resource(*args, **kwargs)
  File "D:\PythonProjects\FaceRecognizerServer\.venv\lib\site-packages\flask\views.py", line 107, in view
    self = view.view_class(  # type: ignore[attr-defined]
  File "src/dependency_injector/_cwiring.pyx", line 26, in dependency_injector._cwiring._get_sync_patched._patched
  File "src/dependency_injector/providers.pyx", line 225, in dependency_injector.providers.Provider.__call__
  File "src/dependency_injector/providers.pyx", line 3049, in dependency_injector.providers.Singleton._provide
  File "src/dependency_injector/providers.pxd", line 650, in dependency_injector.providers.__factory_call
  File "src/dependency_injector/providers.pxd", line 577, in dependency_injector.providers.__call
  File "src/dependency_injector/providers.pxd", line 445, in dependency_injector.providers.__provide_keyword_args
  File "src/dependency_injector/providers.pxd", line 365, in dependency_injector.providers.__get_value
  File "src/dependency_injector/providers.pyx", line 225, in dependency_injector.providers.Provider.__call__
  File "src/dependency_injector/providers.pyx", line 3049, in dependency_injector.providers.Singleton._provide
  File "src/dependency_injector/providers.pxd", line 650, in dependency_injector.providers.__factory_call
  File "src/dependency_injector/providers.pxd", line 608, in dependency_injector.providers.__call
  File "D:\PythonProjects\FaceRecognizerServer\source_code\db_connection\db_class.py", line 25, in __init__
    self.engine = create_engine("postgresql+psycopg2://postgres:Chronos386@localhost/face_recognition_db")
  File "<string>", line 2, in create_engine
  File "D:\PythonProjects\FaceRecognizerServer\.venv\lib\site-packages\sqlalchemy\util\deprecations.py", line 281, in warned
    return fn(*args, **kwargs)  # type: ignore[no-any-return]
  File "D:\PythonProjects\FaceRecognizerServer\.venv\lib\site-packages\sqlalchemy\engine\create.py", line 599, in create_engine
    dbapi = dbapi_meth(**dbapi_args)
  File "D:\PythonProjects\FaceRecognizerServer\.venv\lib\site-packages\sqlalchemy\dialects\postgresql\psycopg2.py", line 690, in import_dbapi
    import psycopg2
  File "D:\PythonProjects\FaceRecognizerServer\.venv\lib\site-packages\psycopg2\__init__.py", line 51, in <module>
    from psycopg2._psycopg import (                     # noqa
ImportError: DLL load failed while importing _psycopg: Не найден указанный модуль.


2024-11-01 03:42:36 - ERROR - Необработанная ошибка: DLL load failed while importing _psycopg: Не найден указанный модуль.
Traceback (most recent call last):
  File "D:\PythonProjects\FaceRecognizerServer\.venv\lib\site-packages\flask\app.py", line 880, in full_dispatch_request
    rv = self.dispatch_request()
  File "D:\PythonProjects\FaceRecognizerServer\.venv\lib\site-packages\flask\app.py", line 865, in dispatch_request
    return self.ensure_sync(self.view_functions[rule.endpoint])(**view_args)  # type: ignore[no-any-return]
  File "D:\PythonProjects\FaceRecognizerServer\.venv\lib\site-packages\flask_restful\__init__.py", line 489, in wrapper
    resp = resource(*args, **kwargs)
  File "D:\PythonProjects\FaceRecognizerServer\.venv\lib\site-packages\flask\views.py", line 107, in view
    self = view.view_class(  # type: ignore[attr-defined]
  File "src/dependency_injector/_cwiring.pyx", line 26, in dependency_injector._cwiring._get_sync_patched._patched
  File "src/dependency_injector/providers.pyx", line 225, in dependency_injector.providers.Provider.__call__
  File "src/dependency_injector/providers.pyx", line 3049, in dependency_injector.providers.Singleton._provide
  File "src/dependency_injector/providers.pxd", line 650, in dependency_injector.providers.__factory_call
  File "src/dependency_injector/providers.pxd", line 577, in dependency_injector.providers.__call
  File "src/dependency_injector/providers.pxd", line 445, in dependency_injector.providers.__provide_keyword_args
  File "src/dependency_injector/providers.pxd", line 365, in dependency_injector.providers.__get_value
  File "src/dependency_injector/providers.pyx", line 225, in dependency_injector.providers.Provider.__call__
  File "src/dependency_injector/providers.pyx", line 3049, in dependency_injector.providers.Singleton._provide
  File "src/dependency_injector/providers.pxd", line 650, in dependency_injector.providers.__factory_call
  File "src/dependency_injector/providers.pxd", line 608, in dependency_injector.providers.__call
  File "D:\PythonProjects\FaceRecognizerServer\source_code\db_connection\db_class.py", line 25, in __init__
    self.engine = create_engine("postgresql+psycopg2://postgres:Chronos386@localhost/face_recognition_db")
  File "<string>", line 2, in create_engine
  File "D:\PythonProjects\FaceRecognizerServer\.venv\lib\site-packages\sqlalchemy\util\deprecations.py", line 281, in warned
    return fn(*args, **kwargs)  # type: ignore[no-any-return]
  File "D:\PythonProjects\FaceRecognizerServer\.venv\lib\site-packages\sqlalchemy\engine\create.py", line 599, in create_engine
    dbapi = dbapi_meth(**dbapi_args)
  File "D:\PythonProjects\FaceRecognizerServer\.venv\lib\site-packages\sqlalchemy\dialects\postgresql\psycopg2.py", line 690, in import_dbapi
    import psycopg2
  File "D:\PythonProjects\FaceRecognizerServer\.venv\lib\site-packages\psycopg2\__init__.py", line 51, in <module>
    from psycopg2._psycopg import (                     # noqa
ImportError: DLL load failed while importing _psycopg: Не найден указанный модуль.


2024-11-01 03:43:45 - ERROR - Необработанная ошибка: No module named 'psycopg2'
Traceback (most recent call last):
  File "D:\PythonProjects\FaceRecognizerServer\.venv\lib\site-packages\flask\app.py", line 880, in full_dispatch_request
    rv = self.dispatch_request()
  File "D:\PythonProjects\FaceRecognizerServer\.venv\lib\site-packages\flask\app.py", line 865, in dispatch_request
    return self.ensure_sync(self.view_functions[rule.endpoint])(**view_args)  # type: ignore[no-any-return]
  File "D:\PythonProjects\FaceRecognizerServer\.venv\lib\site-packages\flask_restful\__init__.py", line 489, in wrapper
    resp = resource(*args, **kwargs)
  File "D:\PythonProjects\FaceRecognizerServer\.venv\lib\site-packages\flask\views.py", line 107, in view
    self = view.view_class(  # type: ignore[attr-defined]
  File "src/dependency_injector/_cwiring.pyx", line 26, in dependency_injector._cwiring._get_sync_patched._patched
  File "src/dependency_injector/providers.pyx", line 225, in dependency_injector.providers.Provider.__call__
  File "src/dependency_injector/providers.pyx", line 3049, in dependency_injector.providers.Singleton._provide
  File "src/dependency_injector/providers.pxd", line 650, in dependency_injector.providers.__factory_call
  File "src/dependency_injector/providers.pxd", line 577, in dependency_injector.providers.__call
  File "src/dependency_injector/providers.pxd", line 445, in dependency_injector.providers.__provide_keyword_args
  File "src/dependency_injector/providers.pxd", line 365, in dependency_injector.providers.__get_value
  File "src/dependency_injector/providers.pyx", line 225, in dependency_injector.providers.Provider.__call__
  File "src/dependency_injector/providers.pyx", line 3049, in dependency_injector.providers.Singleton._provide
  File "src/dependency_injector/providers.pxd", line 650, in dependency_injector.providers.__factory_call
  File "src/dependency_injector/providers.pxd", line 608, in dependency_injector.providers.__call
  File "D:\PythonProjects\FaceRecognizerServer\source_code\db_connection\db_class.py", line 25, in __init__
    self.engine = create_engine("postgresql+psycopg2://postgres:Chronos386@localhost/face_recognition_db")
  File "<string>", line 2, in create_engine
  File "D:\PythonProjects\FaceRecognizerServer\.venv\lib\site-packages\sqlalchemy\util\deprecations.py", line 281, in warned
    return fn(*args, **kwargs)  # type: ignore[no-any-return]
  File "D:\PythonProjects\FaceRecognizerServer\.venv\lib\site-packages\sqlalchemy\engine\create.py", line 599, in create_engine
    dbapi = dbapi_meth(**dbapi_args)
  File "D:\PythonProjects\FaceRecognizerServer\.venv\lib\site-packages\sqlalchemy\dialects\postgresql\psycopg2.py", line 690, in import_dbapi
    import psycopg2
ModuleNotFoundError: No module named 'psycopg2'


2024-11-01 03:51:49 - ERROR - Необработанная ошибка: DLL load failed while importing _psycopg: Не найден указанный модуль.
Traceback (most recent call last):
  File "D:\PythonProjects\FaceRecognizerServer\.venv\lib\site-packages\flask\app.py", line 880, in full_dispatch_request
    rv = self.dispatch_request()
  File "D:\PythonProjects\FaceRecognizerServer\.venv\lib\site-packages\flask\app.py", line 865, in dispatch_request
    return self.ensure_sync(self.view_functions[rule.endpoint])(**view_args)  # type: ignore[no-any-return]
  File "D:\PythonProjects\FaceRecognizerServer\.venv\lib\site-packages\flask_restful\__init__.py", line 489, in wrapper
    resp = resource(*args, **kwargs)
  File "D:\PythonProjects\FaceRecognizerServer\.venv\lib\site-packages\flask\views.py", line 107, in view
    self = view.view_class(  # type: ignore[attr-defined]
  File "src/dependency_injector/_cwiring.pyx", line 26, in dependency_injector._cwiring._get_sync_patched._patched
  File "src/dependency_injector/providers.pyx", line 225, in dependency_injector.providers.Provider.__call__
  File "src/dependency_injector/providers.pyx", line 3049, in dependency_injector.providers.Singleton._provide
  File "src/dependency_injector/providers.pxd", line 650, in dependency_injector.providers.__factory_call
  File "src/dependency_injector/providers.pxd", line 577, in dependency_injector.providers.__call
  File "src/dependency_injector/providers.pxd", line 445, in dependency_injector.providers.__provide_keyword_args
  File "src/dependency_injector/providers.pxd", line 365, in dependency_injector.providers.__get_value
  File "src/dependency_injector/providers.pyx", line 225, in dependency_injector.providers.Provider.__call__
  File "src/dependency_injector/providers.pyx", line 3049, in dependency_injector.providers.Singleton._provide
  File "src/dependency_injector/providers.pxd", line 650, in dependency_injector.providers.__factory_call
  File "src/dependency_injector/providers.pxd", line 608, in dependency_injector.providers.__call
  File "D:\PythonProjects\FaceRecognizerServer\source_code\db_connection\db_class.py", line 25, in __init__
    self.engine = create_engine("postgresql+psycopg2://postgres:Chronos386@localhost/face_recognition_db")
  File "<string>", line 2, in create_engine
  File "D:\PythonProjects\FaceRecognizerServer\.venv\lib\site-packages\sqlalchemy\util\deprecations.py", line 281, in warned
    return fn(*args, **kwargs)  # type: ignore[no-any-return]
  File "D:\PythonProjects\FaceRecognizerServer\.venv\lib\site-packages\sqlalchemy\engine\create.py", line 599, in create_engine
    dbapi = dbapi_meth(**dbapi_args)
  File "D:\PythonProjects\FaceRecognizerServer\.venv\lib\site-packages\sqlalchemy\dialects\postgresql\psycopg2.py", line 690, in import_dbapi
    import psycopg2
  File "D:\PythonProjects\FaceRecognizerServer\.venv\lib\site-packages\psycopg2\__init__.py", line 51, in <module>
    from psycopg2._psycopg import (                     # noqa
ImportError: DLL load failed while importing _psycopg: Не найден указанный модуль.


2024-11-01 04:04:47 - ERROR - Необработанная ошибка: DLL load failed while importing _psycopg: Не найден указанный модуль.
Traceback (most recent call last):
  File "D:\PythonProjects\FaceRecognizerServer\.venv\lib\site-packages\flask\app.py", line 880, in full_dispatch_request
    rv = self.dispatch_request()
  File "D:\PythonProjects\FaceRecognizerServer\.venv\lib\site-packages\flask\app.py", line 865, in dispatch_request
    return self.ensure_sync(self.view_functions[rule.endpoint])(**view_args)  # type: ignore[no-any-return]
  File "D:\PythonProjects\FaceRecognizerServer\.venv\lib\site-packages\flask_restful\__init__.py", line 489, in wrapper
    resp = resource(*args, **kwargs)
  File "D:\PythonProjects\FaceRecognizerServer\.venv\lib\site-packages\flask\views.py", line 107, in view
    self = view.view_class(  # type: ignore[attr-defined]
  File "src/dependency_injector/_cwiring.pyx", line 26, in dependency_injector._cwiring._get_sync_patched._patched
  File "src/dependency_injector/providers.pyx", line 225, in dependency_injector.providers.Provider.__call__
  File "src/dependency_injector/providers.pyx", line 3049, in dependency_injector.providers.Singleton._provide
  File "src/dependency_injector/providers.pxd", line 650, in dependency_injector.providers.__factory_call
  File "src/dependency_injector/providers.pxd", line 577, in dependency_injector.providers.__call
  File "src/dependency_injector/providers.pxd", line 445, in dependency_injector.providers.__provide_keyword_args
  File "src/dependency_injector/providers.pxd", line 365, in dependency_injector.providers.__get_value
  File "src/dependency_injector/providers.pyx", line 225, in dependency_injector.providers.Provider.__call__
  File "src/dependency_injector/providers.pyx", line 3049, in dependency_injector.providers.Singleton._provide
  File "src/dependency_injector/providers.pxd", line 650, in dependency_injector.providers.__factory_call
  File "src/dependency_injector/providers.pxd", line 608, in dependency_injector.providers.__call
  File "D:\PythonProjects\FaceRecognizerServer\source_code\db_connection\db_class.py", line 25, in __init__
    self.engine = create_engine("postgresql+psycopg2://postgres:Chronos386@localhost/face_recognition_db")
  File "<string>", line 2, in create_engine
  File "D:\PythonProjects\FaceRecognizerServer\.venv\lib\site-packages\sqlalchemy\util\deprecations.py", line 281, in warned
    return fn(*args, **kwargs)  # type: ignore[no-any-return]
  File "D:\PythonProjects\FaceRecognizerServer\.venv\lib\site-packages\sqlalchemy\engine\create.py", line 599, in create_engine
    dbapi = dbapi_meth(**dbapi_args)
  File "D:\PythonProjects\FaceRecognizerServer\.venv\lib\site-packages\sqlalchemy\dialects\postgresql\psycopg2.py", line 690, in import_dbapi
    import psycopg2
  File "D:\PythonProjects\FaceRecognizerServer\.venv\lib\site-packages\psycopg2\__init__.py", line 51, in <module>
    from psycopg2._psycopg import (                     # noqa
ImportError: DLL load failed while importing _psycopg: Не найден указанный модуль.


2024-11-01 04:10:39 - ERROR - Необработанная ошибка: DLL load failed while importing _psycopg: Не найден указанный модуль.
Traceback (most recent call last):
  File "D:\PythonProjects\FaceRecognizerServer\.venv\lib\site-packages\flask\app.py", line 880, in full_dispatch_request
    rv = self.dispatch_request()
  File "D:\PythonProjects\FaceRecognizerServer\.venv\lib\site-packages\flask\app.py", line 865, in dispatch_request
    return self.ensure_sync(self.view_functions[rule.endpoint])(**view_args)  # type: ignore[no-any-return]
  File "D:\PythonProjects\FaceRecognizerServer\.venv\lib\site-packages\flask_restful\__init__.py", line 489, in wrapper
    resp = resource(*args, **kwargs)
  File "D:\PythonProjects\FaceRecognizerServer\.venv\lib\site-packages\flask\views.py", line 107, in view
    self = view.view_class(  # type: ignore[attr-defined]
  File "src/dependency_injector/_cwiring.pyx", line 26, in dependency_injector._cwiring._get_sync_patched._patched
  File "src/dependency_injector/providers.pyx", line 225, in dependency_injector.providers.Provider.__call__
  File "src/dependency_injector/providers.pyx", line 3049, in dependency_injector.providers.Singleton._provide
  File "src/dependency_injector/providers.pxd", line 650, in dependency_injector.providers.__factory_call
  File "src/dependency_injector/providers.pxd", line 577, in dependency_injector.providers.__call
  File "src/dependency_injector/providers.pxd", line 445, in dependency_injector.providers.__provide_keyword_args
  File "src/dependency_injector/providers.pxd", line 365, in dependency_injector.providers.__get_value
  File "src/dependency_injector/providers.pyx", line 225, in dependency_injector.providers.Provider.__call__
  File "src/dependency_injector/providers.pyx", line 3049, in dependency_injector.providers.Singleton._provide
  File "src/dependency_injector/providers.pxd", line 650, in dependency_injector.providers.__factory_call
  File "src/dependency_injector/providers.pxd", line 608, in dependency_injector.providers.__call
  File "D:\PythonProjects\FaceRecognizerServer\source_code\db_connection\db_class.py", line 25, in __init__
    self.engine = create_engine("postgresql+psycopg2://postgres:Chronos386@localhost/face_recognition_db")
  File "<string>", line 2, in create_engine
  File "D:\PythonProjects\FaceRecognizerServer\.venv\lib\site-packages\sqlalchemy\util\deprecations.py", line 281, in warned
    return fn(*args, **kwargs)  # type: ignore[no-any-return]
  File "D:\PythonProjects\FaceRecognizerServer\.venv\lib\site-packages\sqlalchemy\engine\create.py", line 599, in create_engine
    dbapi = dbapi_meth(**dbapi_args)
  File "D:\PythonProjects\FaceRecognizerServer\.venv\lib\site-packages\sqlalchemy\dialects\postgresql\psycopg2.py", line 690, in import_dbapi
    import psycopg2
  File "D:\PythonProjects\FaceRecognizerServer\.venv\lib\site-packages\psycopg2\__init__.py", line 51, in <module>
    from psycopg2._psycopg import (                     # noqa
ImportError: DLL load failed while importing _psycopg: Не найден указанный модуль.


2024-11-01 04:12:47 - ERROR - Необработанная ошибка: DLL load failed while importing _psycopg: Не найден указанный модуль.
Traceback (most recent call last):
  File "D:\PythonProjects\FaceRecognizerServer\.venv\lib\site-packages\flask\app.py", line 880, in full_dispatch_request
    rv = self.dispatch_request()
  File "D:\PythonProjects\FaceRecognizerServer\.venv\lib\site-packages\flask\app.py", line 865, in dispatch_request
    return self.ensure_sync(self.view_functions[rule.endpoint])(**view_args)  # type: ignore[no-any-return]
  File "D:\PythonProjects\FaceRecognizerServer\.venv\lib\site-packages\flask_restful\__init__.py", line 489, in wrapper
    resp = resource(*args, **kwargs)
  File "D:\PythonProjects\FaceRecognizerServer\.venv\lib\site-packages\flask\views.py", line 107, in view
    self = view.view_class(  # type: ignore[attr-defined]
  File "src/dependency_injector/_cwiring.pyx", line 26, in dependency_injector._cwiring._get_sync_patched._patched
  File "src/dependency_injector/providers.pyx", line 225, in dependency_injector.providers.Provider.__call__
  File "src/dependency_injector/providers.pyx", line 3049, in dependency_injector.providers.Singleton._provide
  File "src/dependency_injector/providers.pxd", line 650, in dependency_injector.providers.__factory_call
  File "src/dependency_injector/providers.pxd", line 577, in dependency_injector.providers.__call
  File "src/dependency_injector/providers.pxd", line 445, in dependency_injector.providers.__provide_keyword_args
  File "src/dependency_injector/providers.pxd", line 365, in dependency_injector.providers.__get_value
  File "src/dependency_injector/providers.pyx", line 225, in dependency_injector.providers.Provider.__call__
  File "src/dependency_injector/providers.pyx", line 3049, in dependency_injector.providers.Singleton._provide
  File "src/dependency_injector/providers.pxd", line 650, in dependency_injector.providers.__factory_call
  File "src/dependency_injector/providers.pxd", line 608, in dependency_injector.providers.__call
  File "D:\PythonProjects\FaceRecognizerServer\source_code\db_connection\db_class.py", line 25, in __init__
    self.engine = create_engine("postgresql+psycopg2://postgres:Chronos386@localhost/face_recognition_db")
  File "<string>", line 2, in create_engine
  File "D:\PythonProjects\FaceRecognizerServer\.venv\lib\site-packages\sqlalchemy\util\deprecations.py", line 281, in warned
    return fn(*args, **kwargs)  # type: ignore[no-any-return]
  File "D:\PythonProjects\FaceRecognizerServer\.venv\lib\site-packages\sqlalchemy\engine\create.py", line 599, in create_engine
    dbapi = dbapi_meth(**dbapi_args)
  File "D:\PythonProjects\FaceRecognizerServer\.venv\lib\site-packages\sqlalchemy\dialects\postgresql\psycopg2.py", line 690, in import_dbapi
    import psycopg2
  File "D:\PythonProjects\FaceRecognizerServer\.venv\lib\site-packages\psycopg2\__init__.py", line 51, in <module>
    from psycopg2._psycopg import (                     # noqa
ImportError: DLL load failed while importing _psycopg: Не найден указанный модуль.


2024-11-01 04:22:06 - ERROR - Необработанная ошибка: DLL load failed while importing _psycopg: Не найден указанный модуль.
Traceback (most recent call last):
  File "D:\PythonProjects\FaceRecognizerServer\.venv\lib\site-packages\flask\app.py", line 880, in full_dispatch_request
    rv = self.dispatch_request()
  File "D:\PythonProjects\FaceRecognizerServer\.venv\lib\site-packages\flask\app.py", line 865, in dispatch_request
    return self.ensure_sync(self.view_functions[rule.endpoint])(**view_args)  # type: ignore[no-any-return]
  File "D:\PythonProjects\FaceRecognizerServer\.venv\lib\site-packages\flask_restful\__init__.py", line 489, in wrapper
    resp = resource(*args, **kwargs)
  File "D:\PythonProjects\FaceRecognizerServer\.venv\lib\site-packages\flask\views.py", line 107, in view
    self = view.view_class(  # type: ignore[attr-defined]
  File "src/dependency_injector/_cwiring.pyx", line 26, in dependency_injector._cwiring._get_sync_patched._patched
  File "src/dependency_injector/providers.pyx", line 225, in dependency_injector.providers.Provider.__call__
  File "src/dependency_injector/providers.pyx", line 3049, in dependency_injector.providers.Singleton._provide
  File "src/dependency_injector/providers.pxd", line 650, in dependency_injector.providers.__factory_call
  File "src/dependency_injector/providers.pxd", line 577, in dependency_injector.providers.__call
  File "src/dependency_injector/providers.pxd", line 445, in dependency_injector.providers.__provide_keyword_args
  File "src/dependency_injector/providers.pxd", line 365, in dependency_injector.providers.__get_value
  File "src/dependency_injector/providers.pyx", line 225, in dependency_injector.providers.Provider.__call__
  File "src/dependency_injector/providers.pyx", line 3049, in dependency_injector.providers.Singleton._provide
  File "src/dependency_injector/providers.pxd", line 650, in dependency_injector.providers.__factory_call
  File "src/dependency_injector/providers.pxd", line 608, in dependency_injector.providers.__call
  File "D:\PythonProjects\FaceRecognizerServer\source_code\db_connection\db_class.py", line 25, in __init__
    self.engine = create_engine("postgresql+psycopg2://postgres:Chronos386@localhost/face_recognition_db")
  File "<string>", line 2, in create_engine
  File "D:\PythonProjects\FaceRecognizerServer\.venv\lib\site-packages\sqlalchemy\util\deprecations.py", line 281, in warned
    return fn(*args, **kwargs)  # type: ignore[no-any-return]
  File "D:\PythonProjects\FaceRecognizerServer\.venv\lib\site-packages\sqlalchemy\engine\create.py", line 599, in create_engine
    dbapi = dbapi_meth(**dbapi_args)
  File "D:\PythonProjects\FaceRecognizerServer\.venv\lib\site-packages\sqlalchemy\dialects\postgresql\psycopg2.py", line 690, in import_dbapi
    import psycopg2
  File "D:\PythonProjects\FaceRecognizerServer\.venv\lib\site-packages\psycopg2\__init__.py", line 51, in <module>
    from psycopg2._psycopg import (                     # noqa
ImportError: DLL load failed while importing _psycopg: Не найден указанный модуль.


2024-11-01 04:38:43 - ERROR - Ошибка при сохранении фотографии: OpenCV(4.10.0) D:\a\opencv-python\opencv-python\opencv\modules\imgcodecs\src\loadsave.cpp:813: error: (-215:Assertion failed) !buf.empty() in function 'cv::imdecode_'



2024-11-01 04:38:44 - ERROR - Ошибка при сохранении фотографии: OpenCV(4.10.0) D:\a\opencv-python\opencv-python\opencv\modules\imgcodecs\src\loadsave.cpp:813: error: (-215:Assertion failed) !buf.empty() in function 'cv::imdecode_'



2024-11-01 04:38:44 - ERROR - Ошибка при сохранении фотографии: OpenCV(4.10.0) D:\a\opencv-python\opencv-python\opencv\modules\imgcodecs\src\loadsave.cpp:813: error: (-215:Assertion failed) !buf.empty() in function 'cv::imdecode_'



2024-11-01 04:38:44 - ERROR - Ошибка при сохранении фотографии: OpenCV(4.10.0) D:\a\opencv-python\opencv-python\opencv\modules\imgcodecs\src\loadsave.cpp:813: error: (-215:Assertion failed) !buf.empty() in function 'cv::imdecode_'



2024-11-01 04:41:47 - ERROR - Ошибка при сохранении фотографии: OpenCV(4.10.0) D:\a\opencv-python\opencv-python\opencv\modules\imgcodecs\src\loadsave.cpp:813: error: (-215:Assertion failed) !buf.empty() in function 'cv::imdecode_'



2024-11-01 04:41:47 - ERROR - Ошибка при сохранении фотографии: OpenCV(4.10.0) D:\a\opencv-python\opencv-python\opencv\modules\imgcodecs\src\loadsave.cpp:813: error: (-215:Assertion failed) !buf.empty() in function 'cv::imdecode_'



2024-11-01 04:41:47 - ERROR - Ошибка при сохранении фотографии: OpenCV(4.10.0) D:\a\opencv-python\opencv-python\opencv\modules\imgcodecs\src\loadsave.cpp:813: error: (-215:Assertion failed) !buf.empty() in function 'cv::imdecode_'



2024-11-01 04:41:47 - ERROR - Ошибка при сохранении фотографии: OpenCV(4.10.0) D:\a\opencv-python\opencv-python\opencv\modules\imgcodecs\src\loadsave.cpp:813: error: (-215:Assertion failed) !buf.empty() in function 'cv::imdecode_'



2024-11-01 04:51:21 - ERROR - Ошибка в getEmbedding: OpenCV(4.10.0) D:\a\opencv-python\opencv-python\opencv\modules\imgcodecs\src\loadsave.cpp:813: error: (-215:Assertion failed) !buf.empty() in function 'cv::imdecode_'
Traceback (most recent call last):
  File "D:\PythonProjects\FaceRecognizerServer\source_code\face_recognition\face_recognizer.py", line 66, in getEmbedding
    img = cv2.imdecode(np_arr, cv2.IMREAD_COLOR)
cv2.error: OpenCV(4.10.0) D:\a\opencv-python\opencv-python\opencv\modules\imgcodecs\src\loadsave.cpp:813: error: (-215:Assertion failed) !buf.empty() in function 'cv::imdecode_'



2024-11-01 04:51:21 - ERROR - Ошибка в getEmbedding: OpenCV(4.10.0) D:\a\opencv-python\opencv-python\opencv\modules\imgcodecs\src\loadsave.cpp:813: error: (-215:Assertion failed) !buf.empty() in function 'cv::imdecode_'
Traceback (most recent call last):
  File "D:\PythonProjects\FaceRecognizerServer\source_code\face_recognition\face_recognizer.py", line 66, in getEmbedding
    img = cv2.imdecode(np_arr, cv2.IMREAD_COLOR)
cv2.error: OpenCV(4.10.0) D:\a\opencv-python\opencv-python\opencv\modules\imgcodecs\src\loadsave.cpp:813: error: (-215:Assertion failed) !buf.empty() in function 'cv::imdecode_'



2024-11-01 04:51:21 - ERROR - Ошибка в getEmbedding: OpenCV(4.10.0) D:\a\opencv-python\opencv-python\opencv\modules\imgcodecs\src\loadsave.cpp:813: error: (-215:Assertion failed) !buf.empty() in function 'cv::imdecode_'
Traceback (most recent call last):
  File "D:\PythonProjects\FaceRecognizerServer\source_code\face_recognition\face_recognizer.py", line 66, in getEmbedding
    img = cv2.imdecode(np_arr, cv2.IMREAD_COLOR)
cv2.error: OpenCV(4.10.0) D:\a\opencv-python\opencv-python\opencv\modules\imgcodecs\src\loadsave.cpp:813: error: (-215:Assertion failed) !buf.empty() in function 'cv::imdecode_'



2024-11-01 04:51:21 - ERROR - Ошибка в getEmbedding: OpenCV(4.10.0) D:\a\opencv-python\opencv-python\opencv\modules\imgcodecs\src\loadsave.cpp:813: error: (-215:Assertion failed) !buf.empty() in function 'cv::imdecode_'
Traceback (most recent call last):
  File "D:\PythonProjects\FaceRecognizerServer\source_code\face_recognition\face_recognizer.py", line 66, in getEmbedding
    img = cv2.imdecode(np_arr, cv2.IMREAD_COLOR)
cv2.error: OpenCV(4.10.0) D:\a\opencv-python\opencv-python\opencv\modules\imgcodecs\src\loadsave.cpp:813: error: (-215:Assertion failed) !buf.empty() in function 'cv::imdecode_'



2024-11-01 04:53:38 - ERROR - Ошибка в getEmbedding: OpenCV(4.10.0) :-1: error: (-5:Bad argument) in function 'cvtColor'
> Overload resolution failed:
>  - src is not a numpy array, neither a scalar
>  - Expected Ptr<cv::UMat> for argument 'src'
Traceback (most recent call last):
  File "D:\PythonProjects\FaceRecognizerServer\source_code\face_recognition\face_recognizer.py", line 64, in getEmbedding
    emb, code = self.__getFaceEmbedding(img)
  File "D:\PythonProjects\FaceRecognizerServer\source_code\face_recognition\face_recognizer.py", line 20, in __getFaceEmbedding
    img = cv2.cvtColor(img, cv2.COLOR_BGR2RGB)
cv2.error: OpenCV(4.10.0) :-1: error: (-5:Bad argument) in function 'cvtColor'
> Overload resolution failed:
>  - src is not a numpy array, neither a scalar
>  - Expected Ptr<cv::UMat> for argument 'src'



2024-11-01 04:53:38 - ERROR - Ошибка в getEmbedding: OpenCV(4.10.0) :-1: error: (-5:Bad argument) in function 'cvtColor'
> Overload resolution failed:
>  - src is not a numpy array, neither a scalar
>  - Expected Ptr<cv::UMat> for argument 'src'
Traceback (most recent call last):
  File "D:\PythonProjects\FaceRecognizerServer\source_code\face_recognition\face_recognizer.py", line 64, in getEmbedding
    emb, code = self.__getFaceEmbedding(img)
  File "D:\PythonProjects\FaceRecognizerServer\source_code\face_recognition\face_recognizer.py", line 20, in __getFaceEmbedding
    img = cv2.cvtColor(img, cv2.COLOR_BGR2RGB)
cv2.error: OpenCV(4.10.0) :-1: error: (-5:Bad argument) in function 'cvtColor'
> Overload resolution failed:
>  - src is not a numpy array, neither a scalar
>  - Expected Ptr<cv::UMat> for argument 'src'



2024-11-01 04:53:39 - ERROR - Ошибка в getEmbedding: OpenCV(4.10.0) :-1: error: (-5:Bad argument) in function 'cvtColor'
> Overload resolution failed:
>  - src is not a numpy array, neither a scalar
>  - Expected Ptr<cv::UMat> for argument 'src'
Traceback (most recent call last):
  File "D:\PythonProjects\FaceRecognizerServer\source_code\face_recognition\face_recognizer.py", line 64, in getEmbedding
    emb, code = self.__getFaceEmbedding(img)
  File "D:\PythonProjects\FaceRecognizerServer\source_code\face_recognition\face_recognizer.py", line 20, in __getFaceEmbedding
    img = cv2.cvtColor(img, cv2.COLOR_BGR2RGB)
cv2.error: OpenCV(4.10.0) :-1: error: (-5:Bad argument) in function 'cvtColor'
> Overload resolution failed:
>  - src is not a numpy array, neither a scalar
>  - Expected Ptr<cv::UMat> for argument 'src'



2024-11-01 04:53:39 - ERROR - Ошибка в getEmbedding: OpenCV(4.10.0) :-1: error: (-5:Bad argument) in function 'cvtColor'
> Overload resolution failed:
>  - src is not a numpy array, neither a scalar
>  - Expected Ptr<cv::UMat> for argument 'src'
Traceback (most recent call last):
  File "D:\PythonProjects\FaceRecognizerServer\source_code\face_recognition\face_recognizer.py", line 64, in getEmbedding
    emb, code = self.__getFaceEmbedding(img)
  File "D:\PythonProjects\FaceRecognizerServer\source_code\face_recognition\face_recognizer.py", line 20, in __getFaceEmbedding
    img = cv2.cvtColor(img, cv2.COLOR_BGR2RGB)
cv2.error: OpenCV(4.10.0) :-1: error: (-5:Bad argument) in function 'cvtColor'
> Overload resolution failed:
>  - src is not a numpy array, neither a scalar
>  - Expected Ptr<cv::UMat> for argument 'src'



2024-11-01 05:06:00 - ERROR - Ошибка при сохранении фотографии: OpenCV(4.10.0) D:\a\opencv-python\opencv-python\opencv\modules\highgui\src\window.cpp:1301: error: (-2:Unspecified error) The function is not implemented. Rebuild the library with Windows, GTK+ 2.x or Cocoa support. If you are on Ubuntu or Debian, install libgtk2.0-dev and pkg-config, then re-run cmake or configure script in function 'cvShowImage'



2024-11-01 05:06:00 - ERROR - Ошибка при сохранении фотографии: OpenCV(4.10.0) D:\a\opencv-python\opencv-python\opencv\modules\highgui\src\window.cpp:1301: error: (-2:Unspecified error) The function is not implemented. Rebuild the library with Windows, GTK+ 2.x or Cocoa support. If you are on Ubuntu or Debian, install libgtk2.0-dev and pkg-config, then re-run cmake or configure script in function 'cvShowImage'



2024-11-01 05:06:00 - ERROR - Ошибка при сохранении фотографии: OpenCV(4.10.0) D:\a\opencv-python\opencv-python\opencv\modules\highgui\src\window.cpp:1301: error: (-2:Unspecified error) The function is not implemented. Rebuild the library with Windows, GTK+ 2.x or Cocoa support. If you are on Ubuntu or Debian, install libgtk2.0-dev and pkg-config, then re-run cmake or configure script in function 'cvShowImage'



2024-11-01 05:06:01 - ERROR - Ошибка при сохранении фотографии: OpenCV(4.10.0) D:\a\opencv-python\opencv-python\opencv\modules\highgui\src\window.cpp:1301: error: (-2:Unspecified error) The function is not implemented. Rebuild the library with Windows, GTK+ 2.x or Cocoa support. If you are on Ubuntu or Debian, install libgtk2.0-dev and pkg-config, then re-run cmake or configure script in function 'cvShowImage'



2024-11-01 05:22:39 - ERROR - Лицо не обнаружено на изображении
NoneType: None


2024-11-01 05:23:26 - ERROR - Ошибка в recognizeFace: not enough values to unpack (expected 2, got 1)
Traceback (most recent call last):
  File "D:\PythonProjects\FaceRecognizerServer\source_code\face_recognition\face_recognizer.py", line 44, in recognizeFace
    distances, indices = index.search(emb, 3)
  File "D:\PythonProjects\FaceRecognizerServer\.venv\lib\site-packages\faiss\class_wrappers.py", line 327, in replacement_search
    n, d = x.shape
ValueError: not enough values to unpack (expected 2, got 1)


