2024-10-09 01:01:33 - ERROR - Необработанная ошибка: 500 Internal Server Error: The server encountered an internal error and was unable to complete your request. Either the server is overloaded or there is an error in the application.
Traceback (most recent call last):
  File "D:\anaconda3\Lib\site-packages\flask\app.py", line 1820, in full_dispatch_request
    rv = self.dispatch_request()
         ^^^^^^^^^^^^^^^^^^^^^^^
  File "D:\anaconda3\Lib\site-packages\flask\app.py", line 1785, in dispatch_request
    self.raise_routing_exception(req)
  File "D:\anaconda3\Lib\site-packages\flask\app.py", line 1767, in raise_routing_exception
    raise request.routing_exception  # type: ignore
    ^^^^^^^^^^^^^^^^^^^^^^^^^^^^^^^
  File "D:\anaconda3\Lib\site-packages\flask\ctx.py", line 351, in match_request
    result = self.url_adapter.match(return_rule=True)  # type: ignore
             ^^^^^^^^^^^^^^^^^^^^^^^^^^^^^^^^^^^^^^^^
  File "D:\anaconda3\Lib\site-packages\werkzeug\routing\map.py", line 624, in match
    raise NotFound() from None
werkzeug.exceptions.NotFound: 404 Not Found: The requested URL was not found on the server. If you entered the URL manually please check your spelling and try again.

During handling of the above exception, another exception occurred:

Traceback (most recent call last):
  File "D:\anaconda3\Lib\site-packages\flask\app.py", line 2525, in wsgi_app
    response = self.full_dispatch_request()
               ^^^^^^^^^^^^^^^^^^^^^^^^^^^^
  File "D:\anaconda3\Lib\site-packages\flask\app.py", line 1822, in full_dispatch_request
    rv = self.handle_user_exception(e)
         ^^^^^^^^^^^^^^^^^^^^^^^^^^^^^
  File "D:\anaconda3\Lib\site-packages\flask_restful\__init__.py", line 298, in error_router
    return original_handler(e)
           ^^^^^^^^^^^^^^^^^^^
  File "D:\anaconda3\Lib\site-packages\flask_cors\extension.py", line 176, in wrapped_function
    return cors_after_request(app.make_response(f(*args, **kwargs)))
                                                ^^^^^^^^^^^^^^^^^^
  File "D:\anaconda3\Lib\site-packages\flask\app.py", line 1666, in handle_user_exception
    return self.handle_http_exception(e)
           ^^^^^^^^^^^^^^^^^^^^^^^^^^^^^
  File "D:\anaconda3\Lib\site-packages\flask\app.py", line 1606, in handle_http_exception
    return self.ensure_sync(handler)(e)
           ^^^^^^^^^^^^^^^^^^^^^^^^^^^^
TypeError: page_not_found() takes 0 positional arguments but 1 was given


