2025-04-11 00:38:57 - ERROR - Необработанная ошибка: 404 Not Found: The requested URL was not found on the server. If you entered the URL manually please check your spelling and try again.
Traceback (most recent call last):
  File "/Users/chronos_386/PycharmProjects/FaceRecognizerServer/.venv/lib/python3.8/site-packages/flask/app.py", line 880, in full_dispatch_request
    rv = self.dispatch_request()
  File "/Users/chronos_386/PycharmProjects/FaceRecognizerServer/.venv/lib/python3.8/site-packages/flask/app.py", line 854, in dispatch_request
    self.raise_routing_exception(req)
  File "/Users/chronos_386/PycharmProjects/FaceRecognizerServer/.venv/lib/python3.8/site-packages/flask/app.py", line 463, in raise_routing_exception
    raise request.routing_exception  # type: ignore[misc]
  File "/Users/chronos_386/PycharmProjects/FaceRecognizerServer/.venv/lib/python3.8/site-packages/flask/ctx.py", line 362, in match_request
    result = self.url_adapter.match(return_rule=True)  # type: ignore
  File "/Users/chronos_386/PycharmProjects/FaceRecognizerServer/.venv/lib/python3.8/site-packages/werkzeug/routing/map.py", line 629, in match
    raise NotFound() from None
werkzeug.exceptions.NotFound: 404 Not Found: The requested URL was not found on the server. If you entered the URL manually please check your spelling and try again.


2025-04-11 00:43:44 - ERROR - Необработанная ошибка: 404 Not Found: The requested URL was not found on the server. If you entered the URL manually please check your spelling and try again.
Traceback (most recent call last):
  File "/Users/chronos_386/PycharmProjects/FaceRecognizerServer/.venv/lib/python3.8/site-packages/flask/app.py", line 880, in full_dispatch_request
    rv = self.dispatch_request()
  File "/Users/chronos_386/PycharmProjects/FaceRecognizerServer/.venv/lib/python3.8/site-packages/flask/app.py", line 854, in dispatch_request
    self.raise_routing_exception(req)
  File "/Users/chronos_386/PycharmProjects/FaceRecognizerServer/.venv/lib/python3.8/site-packages/flask/app.py", line 463, in raise_routing_exception
    raise request.routing_exception  # type: ignore[misc]
  File "/Users/chronos_386/PycharmProjects/FaceRecognizerServer/.venv/lib/python3.8/site-packages/flask/ctx.py", line 362, in match_request
    result = self.url_adapter.match(return_rule=True)  # type: ignore
  File "/Users/chronos_386/PycharmProjects/FaceRecognizerServer/.venv/lib/python3.8/site-packages/werkzeug/routing/map.py", line 629, in match
    raise NotFound() from None
werkzeug.exceptions.NotFound: 404 Not Found: The requested URL was not found on the server. If you entered the URL manually please check your spelling and try again.


2025-04-11 00:43:51 - ERROR - Необработанная ошибка: 404 Not Found: The requested URL was not found on the server. If you entered the URL manually please check your spelling and try again.
Traceback (most recent call last):
  File "/Users/chronos_386/PycharmProjects/FaceRecognizerServer/.venv/lib/python3.8/site-packages/flask/app.py", line 880, in full_dispatch_request
    rv = self.dispatch_request()
  File "/Users/chronos_386/PycharmProjects/FaceRecognizerServer/.venv/lib/python3.8/site-packages/flask/app.py", line 854, in dispatch_request
    self.raise_routing_exception(req)
  File "/Users/chronos_386/PycharmProjects/FaceRecognizerServer/.venv/lib/python3.8/site-packages/flask/app.py", line 463, in raise_routing_exception
    raise request.routing_exception  # type: ignore[misc]
  File "/Users/chronos_386/PycharmProjects/FaceRecognizerServer/.venv/lib/python3.8/site-packages/flask/ctx.py", line 362, in match_request
    result = self.url_adapter.match(return_rule=True)  # type: ignore
  File "/Users/chronos_386/PycharmProjects/FaceRecognizerServer/.venv/lib/python3.8/site-packages/werkzeug/routing/map.py", line 629, in match
    raise NotFound() from None
werkzeug.exceptions.NotFound: 404 Not Found: The requested URL was not found on the server. If you entered the URL manually please check your spelling and try again.


