2024-10-16 01:16:32 - ERROR - Необработанная ошибка: 404 Not Found: The requested URL was not found on the server. If you entered the URL manually please check your spelling and try again.
Traceback (most recent call last):
  File "D:\anaconda3\Lib\site-packages\flask\app.py", line 1820, in full_dispatch_request
    rv = self.dispatch_request()
         ^^^^^^^^^^^^^^^^^^^^^^^
  File "D:\anaconda3\Lib\site-packages\flask\app.py", line 1785, in dispatch_request
    self.raise_routing_exception(req)
  File "D:\anaconda3\Lib\site-packages\flask\app.py", line 1767, in raise_routing_exception
    raise request.routing_exception  # type: ignore
    ^^^^^^^^^^^^^^^^^^^^^^^^^^^^^^^
  File "D:\anaconda3\Lib\site-packages\flask\ctx.py", line 351, in match_request
    result = self.url_adapter.match(return_rule=True)  # type: ignore
             ^^^^^^^^^^^^^^^^^^^^^^^^^^^^^^^^^^^^^^^^
  File "D:\anaconda3\Lib\site-packages\werkzeug\routing\map.py", line 624, in match
    raise NotFound() from None
werkzeug.exceptions.NotFound: 404 Not Found: The requested URL was not found on the server. If you entered the URL manually please check your spelling and try again.


2024-10-16 02:15:28 - ERROR - Необработанная ошибка: int() argument must be a string, a bytes-like object or a real number, not 'NoneType'
Traceback (most recent call last):
  File "D:\anaconda3\Lib\site-packages\flask_restful\__init__.py", line 295, in error_router
    return self.handle_error(e)
           ^^^^^^^^^^^^^^^^^^^^
  File "D:\anaconda3\Lib\site-packages\flask_restful\__init__.py", line 310, in handle_error
    _handle_flask_propagate_exceptions_config(current_app, e)
  File "D:\anaconda3\Lib\site-packages\flask\app.py", line 1820, in full_dispatch_request
    rv = self.dispatch_request()
         ^^^^^^^^^^^^^^^^^^^^^^^
  File "D:\anaconda3\Lib\site-packages\flask\app.py", line 1796, in dispatch_request
    return self.ensure_sync(self.view_functions[rule.endpoint])(**view_args)
           ^^^^^^^^^^^^^^^^^^^^^^^^^^^^^^^^^^^^^^^^^^^^^^^^^^^^^^^^^^^^^^^^^
  File "D:\anaconda3\Lib\site-packages\flask_restful\__init__.py", line 489, in wrapper
    resp = resource(*args, **kwargs)
           ^^^^^^^^^^^^^^^^^^^^^^^^^
  File "D:\anaconda3\Lib\site-packages\flask\views.py", line 107, in view
    return current_app.ensure_sync(self.dispatch_request)(**kwargs)
           ^^^^^^^^^^^^^^^^^^^^^^^^^^^^^^^^^^^^^^^^^^^^^^^^^^^^^^^^
  File "D:\anaconda3\Lib\site-packages\flask_restful\__init__.py", line 604, in dispatch_request
    resp = meth(*args, **kwargs)
           ^^^^^^^^^^^^^^^^^^^^^
  File "D:\PythonProjects\FaceRecognizerServer\source_code\resources\admin_teachers_res.py", line 13, in post
    department_id: int = int(request.form.get('department_id'))
                         ^^^^^^^^^^^^^^^^^^^^^^^^^^^^^^^^^^^^^^
TypeError: int() argument must be a string, a bytes-like object or a real number, not 'NoneType'


2024-10-16 02:32:33 - ERROR - Необработанная ошибка: (psycopg2.errors.UniqueViolation) ОШИБКА:  повторяющееся значение ключа нарушает ограничение уникальности "accounts_pkey"
DETAIL:  Ключ "(id)=(7)" уже существует.

[SQL: INSERT INTO accounts (id, admin, email, password) VALUES (%(id)s, %(admin)s, %(email)s, %(password)s)]
[parameters: {'id': 7, 'admin': False, 'email': 'test@test.test', 'password': '123test456'}]
(Background on this error at: https://sqlalche.me/e/14/gkpj)
Traceback (most recent call last):
  File "D:\anaconda3\Lib\site-packages\sqlalchemy\engine\base.py", line 1819, in _execute_context
    self.dialect.do_execute(
  File "D:\anaconda3\Lib\site-packages\sqlalchemy\engine\default.py", line 732, in do_execute
    cursor.execute(statement, parameters)
psycopg2.errors.UniqueViolation: ОШИБКА:  повторяющееся значение ключа нарушает ограничение уникальности "accounts_pkey"
DETAIL:  Ключ "(id)=(7)" уже существует.


The above exception was the direct cause of the following exception:

Traceback (most recent call last):
  File "D:\anaconda3\Lib\site-packages\flask_restful\__init__.py", line 295, in error_router
    return self.handle_error(e)
           ^^^^^^^^^^^^^^^^^^^^
  File "D:\anaconda3\Lib\site-packages\flask_restful\__init__.py", line 310, in handle_error
    _handle_flask_propagate_exceptions_config(current_app, e)
  File "D:\anaconda3\Lib\site-packages\flask\app.py", line 1820, in full_dispatch_request
    rv = self.dispatch_request()
         ^^^^^^^^^^^^^^^^^^^^^^^
  File "D:\anaconda3\Lib\site-packages\flask\app.py", line 1796, in dispatch_request
    return self.ensure_sync(self.view_functions[rule.endpoint])(**view_args)
           ^^^^^^^^^^^^^^^^^^^^^^^^^^^^^^^^^^^^^^^^^^^^^^^^^^^^^^^^^^^^^^^^^
  File "D:\anaconda3\Lib\site-packages\flask_restful\__init__.py", line 489, in wrapper
    resp = resource(*args, **kwargs)
           ^^^^^^^^^^^^^^^^^^^^^^^^^
  File "D:\anaconda3\Lib\site-packages\flask\views.py", line 107, in view
    return current_app.ensure_sync(self.dispatch_request)(**kwargs)
           ^^^^^^^^^^^^^^^^^^^^^^^^^^^^^^^^^^^^^^^^^^^^^^^^^^^^^^^^
  File "D:\anaconda3\Lib\site-packages\flask_restful\__init__.py", line 604, in dispatch_request
    resp = meth(*args, **kwargs)
           ^^^^^^^^^^^^^^^^^^^^^
  File "D:\PythonProjects\FaceRecognizerServer\source_code\resources\admin_teachers_actions_res.py", line 18, in post
    json_model = self.api_connector.createTeacher(name, email, password, department_id)
                 ^^^^^^^^^^^^^^^^^^^^^^^^^^^^^^^^^^^^^^^^^^^^^^^^^^^^^^^^^^^^^^^^^^^^^^
  File "D:\PythonProjects\FaceRecognizerServer\source_code\api_connection\api_connector.py", line 394, in createTeacher
    new_acc = self.db_class.createAccount(email=email, password=password)
              ^^^^^^^^^^^^^^^^^^^^^^^^^^^^^^^^^^^^^^^^^^^^^^^^^^^^^^^^^^^
  File "D:\PythonProjects\FaceRecognizerServer\source_code\db_connection\db_class.py", line 59, in createAccount
    self.session.commit()
  File "D:\anaconda3\Lib\site-packages\sqlalchemy\orm\session.py", line 1451, in commit
    self._transaction.commit(_to_root=self.future)
  File "D:\anaconda3\Lib\site-packages\sqlalchemy\orm\session.py", line 829, in commit
    self._prepare_impl()
  File "D:\anaconda3\Lib\site-packages\sqlalchemy\orm\session.py", line 808, in _prepare_impl
    self.session.flush()
  File "D:\anaconda3\Lib\site-packages\sqlalchemy\orm\session.py", line 3383, in flush
    self._flush(objects)
  File "D:\anaconda3\Lib\site-packages\sqlalchemy\orm\session.py", line 3522, in _flush
    with util.safe_reraise():
  File "D:\anaconda3\Lib\site-packages\sqlalchemy\util\langhelpers.py", line 70, in __exit__
    compat.raise_(
  File "D:\anaconda3\Lib\site-packages\sqlalchemy\util\compat.py", line 208, in raise_
    raise exception
  File "D:\anaconda3\Lib\site-packages\sqlalchemy\orm\session.py", line 3483, in _flush
    flush_context.execute()
  File "D:\anaconda3\Lib\site-packages\sqlalchemy\orm\unitofwork.py", line 456, in execute
    rec.execute(self)
  File "D:\anaconda3\Lib\site-packages\sqlalchemy\orm\unitofwork.py", line 630, in execute
    util.preloaded.orm_persistence.save_obj(
  File "D:\anaconda3\Lib\site-packages\sqlalchemy\orm\persistence.py", line 245, in save_obj
    _emit_insert_statements(
  File "D:\anaconda3\Lib\site-packages\sqlalchemy\orm\persistence.py", line 1097, in _emit_insert_statements
    c = connection._execute_20(
        ^^^^^^^^^^^^^^^^^^^^^^^
  File "D:\anaconda3\Lib\site-packages\sqlalchemy\engine\base.py", line 1631, in _execute_20
    return meth(self, args_10style, kwargs_10style, execution_options)
           ^^^^^^^^^^^^^^^^^^^^^^^^^^^^^^^^^^^^^^^^^^^^^^^^^^^^^^^^^^^
  File "D:\anaconda3\Lib\site-packages\sqlalchemy\sql\elements.py", line 332, in _execute_on_connection
    return connection._execute_clauseelement(
           ^^^^^^^^^^^^^^^^^^^^^^^^^^^^^^^^^^
  File "D:\anaconda3\Lib\site-packages\sqlalchemy\engine\base.py", line 1498, in _execute_clauseelement
    ret = self._execute_context(
          ^^^^^^^^^^^^^^^^^^^^^^
  File "D:\anaconda3\Lib\site-packages\sqlalchemy\engine\base.py", line 1862, in _execute_context
    self._handle_dbapi_exception(
  File "D:\anaconda3\Lib\site-packages\sqlalchemy\engine\base.py", line 2043, in _handle_dbapi_exception
    util.raise_(
  File "D:\anaconda3\Lib\site-packages\sqlalchemy\util\compat.py", line 208, in raise_
    raise exception
  File "D:\anaconda3\Lib\site-packages\sqlalchemy\engine\base.py", line 1819, in _execute_context
    self.dialect.do_execute(
  File "D:\anaconda3\Lib\site-packages\sqlalchemy\engine\default.py", line 732, in do_execute
    cursor.execute(statement, parameters)
sqlalchemy.exc.IntegrityError: (psycopg2.errors.UniqueViolation) ОШИБКА:  повторяющееся значение ключа нарушает ограничение уникальности "accounts_pkey"
DETAIL:  Ключ "(id)=(7)" уже существует.

[SQL: INSERT INTO accounts (id, admin, email, password) VALUES (%(id)s, %(admin)s, %(email)s, %(password)s)]
[parameters: {'id': 7, 'admin': False, 'email': 'test@test.test', 'password': '123test456'}]
(Background on this error at: https://sqlalche.me/e/14/gkpj)


2024-10-16 03:26:45 - ERROR - Необработанная ошибка: int() argument must be a string, a bytes-like object or a real number, not 'NoneType'
Traceback (most recent call last):
  File "D:\anaconda3\Lib\site-packages\flask_restful\__init__.py", line 295, in error_router
    return self.handle_error(e)
           ^^^^^^^^^^^^^^^^^^^^
  File "D:\anaconda3\Lib\site-packages\flask_restful\__init__.py", line 310, in handle_error
    _handle_flask_propagate_exceptions_config(current_app, e)
  File "D:\anaconda3\Lib\site-packages\flask\app.py", line 1820, in full_dispatch_request
    rv = self.dispatch_request()
         ^^^^^^^^^^^^^^^^^^^^^^^
  File "D:\anaconda3\Lib\site-packages\flask\app.py", line 1796, in dispatch_request
    return self.ensure_sync(self.view_functions[rule.endpoint])(**view_args)
           ^^^^^^^^^^^^^^^^^^^^^^^^^^^^^^^^^^^^^^^^^^^^^^^^^^^^^^^^^^^^^^^^^
  File "D:\anaconda3\Lib\site-packages\flask_restful\__init__.py", line 489, in wrapper
    resp = resource(*args, **kwargs)
           ^^^^^^^^^^^^^^^^^^^^^^^^^
  File "D:\anaconda3\Lib\site-packages\flask\views.py", line 107, in view
    return current_app.ensure_sync(self.dispatch_request)(**kwargs)
           ^^^^^^^^^^^^^^^^^^^^^^^^^^^^^^^^^^^^^^^^^^^^^^^^^^^^^^^^
  File "D:\anaconda3\Lib\site-packages\flask_restful\__init__.py", line 604, in dispatch_request
    resp = meth(*args, **kwargs)
           ^^^^^^^^^^^^^^^^^^^^^
  File "D:\PythonProjects\FaceRecognizerServer\source_code\resources\admin_groups_actions_res.py", line 36, in put
    institute_id: int = int(request.form.get('institute_id'))
                        ^^^^^^^^^^^^^^^^^^^^^^^^^^^^^^^^^^^^^
TypeError: int() argument must be a string, a bytes-like object or a real number, not 'NoneType'


